Workbook
Name \A: #REF!
Name \A: #REF!
Name \A: #REF!
Name \A: #REF!
Name \A: #REF!
Name \B: #REF!
Name \B: #REF!
Name \B: #REF!
Name \B: #REF!
Name \B: #REF!
Name \C: #REF!
Name \D: #REF!
Name \E: #REF!
Name \F: #REF!
Name \G: #REF!
Name \H: #REF!
Name \I: #REF!
Name \J: #REF!
Name \P: #REF!
Name \Q: #REF!
Name \R: #REF!
Name \S: #REF!
Name \X: #REF!
Name \Z: #REF!
Name _1___0Yazdırma_Al: #REF!
Name _1_0Yazdırma_Al: #REF!
Name _108CROMO: #REF!
Name _15___0Yazdırma_Al: #REF!
Name _16___0Yazdırma_Al: #REF!
Name _2____Yazdırma_Al: #REF!
Name _2Yazdırma_Al: #REF!
Name _4_0Yazdırma_Al: #REF!
Name _5_0Yazdırma_Al: #REF!
Name _6Yazdırma_Al: #REF!
Name _9._Analysis_of_net_debt: #REF!
Name _ANG1: #REF!
Name _ANG2: #REF!
Name _ANG3: #REF!
Name _ANG4: #REF!
Name _c: #REF!
Name _DAT1: #REF!
Name _DAT11: #REF!
Name _DAT3: #REF!
Name _DAT4: #REF!
Name _DAT5: #REF!
Name _DAT9: #REF!
Name _pan1: #REF!
Name _par1: #REF!
Name _PY1: #REF!
Name _PY2: #REF!
Name _tab3: #REF!
Name _tab3: #REF!
Name _tab3: #REF!
Name _tab3: #REF!
Name _Typ7: "Cost Centre"
Name _Typ8: "Expense/Income"
Name a: {"Werkdp_excl",#N/A,FALSE,"WERKdp"}
Name a: {"Werkdp_excl",#N/A,FALSE,"WERKdp"}
Name a: {"Werkdp_excl",#N/A,FALSE,"WERKdp"}
Name a: {"Werkdp_excl",#N/A,FALSE,"WERKdp"}

Sheet _com.sap.ip.bi.xl.hiddensheet

Sheet Finansal Raporlama AY
C3: AYLIK
C4: bin Avro | D4: Ciro | G4: Brüt Kar | J4: EBITDA | M4: Net Kar
D5: Gerçekleşme | E5: Bütçe - Gerçekleşme Fark | F5: % Değişim | G5: Gerçekleşme | H5: Bütçe - Gerçekleşme Fark | I5: % Değişim | J5: Gerçekleşme | K5: Bütçe - Gerçekleşme Fark | L5: % Değişim | M5: Gerçekleşme | N5: Bütçe - Gerçekleşme Fark | O5: % Değişim
C6: Toplam | D6: =SUM(D7:D14) -> 62184.729 | E6: =SUM(E7:E14) -> -15618.408 | F6: =(D6/(D6-E6))-1 -> -0.20074265 | G6: =SUM(G7:G14) -> 14284.821 | H6: =SUM(H7:H14) -> -3350.4084 | I6: =(G6/(G6-H6))-1 -> -0.18998383 | J6: =SUM(J7:J14) -> 11032.073 | K6: =SUM(K7:K14) -> -2538.0733 | L6: =(J6/(J6-K6))-1 -> -0.1870336 | M6: =SUM(M7:M14) -> 5977.8703 | N6: =SUM(N7:N14) -> -2551.2414 | O6: =(M6/(M6-N6))-1 -> -0.29912158
C7: İnci Holding | D7: ='A -Döviz'!AA9/1000 -> 789.95617 | E7: =('A -Döviz'!AA9-'A -Döviz'!Z9)/1000 -> -86.002945 | F7: =(D7/(D7-E7))-1 -> -0.09818146 | G7: =('A -Döviz'!AA36)/1000 -> 789.95617 | H7: =('A -Döviz'!AA36-'A -Döviz'!Z36)/1000 -> -86.002945 | I7: =(G7/(G7-H7))-1 -> -0.09818146 | J7: ='A -Döviz'!AA139/1000 -> 482.56644 | K7: =('A -Döviz'!AA139-'A -Döviz'!Z139)/1000 -> -4.00163 | L7: =(J7/(J7-K7))-1 -> -0.0082241935 | M7: ='A -Döviz'!AA215/1000 -> 379.22638 | N7: =('A -Döviz'!AA215-'A -Döviz'!Z215)/1000 -> 48.662371 | O7: =(M7/(M7-N7))-1 -> 0.14721013
C8: ISM | D8: ='A -Döviz'!AA10/1000 -> 453.451 | E8: =('A -Döviz'!AA10-'A -Döviz'!Z10)/1000 -> -177.1531 | F8: =(D8/(D8-E8))-1 -> -0.28092603 | G8: =('A -Döviz'!AA37)/1000 -> 103.70261 | H8: =('A -Döviz'!AA37-'A -Döviz'!Z37)/1000 -> -98.326642 | I8: =(G8/(G8-H8))-1 -> -0.48669507 | J8: ='A -Döviz'!AA140/1000 -> -23.409095 | K8: =('A -Döviz'!AA140-'A -Döviz'!Z140)/1000 -> -106.64183 | L8: =((J8/(J8-K8))-1) -> -1.2812487 | M8: ='A -Döviz'!AA216/1000 -> -204.95991 | N8: =('A -Döviz'!AA216-'A -Döviz'!Z216)/1000 -> -251.23212 | O8: =((M8/(M8-N8))-1) -> -5.429438
C9: İncitaş | D9: ='A -Döviz'!AA11/1000 -> 890.67476 | E9: =('A -Döviz'!AA11-'A -Döviz'!Z11)/1000 -> -524.10649 | F9: =(D9/(D9-E9))-1 -> -0.37045055 | G9: =('A -Döviz'!AA38)/1000 -> 170.33583 | H9: =('A -Döviz'!AA38-'A -Döviz'!Z38)/1000 -> -117.78465 | I9: =(G9/(G9-H9))-1 -> -0.40880347 | J9: ='A -Döviz'!AA141/1000 -> 55.231727 | K9: =('A -Döviz'!AA141-'A -Döviz'!Z141)/1000 -> -20.731473 | L9: =((J9/(J9-K9))-1) -> -0.27291469 | M9: ='A -Döviz'!AA217/1000 -> 27.18271 | N9: =('A -Döviz'!AA217-'A -Döviz'!Z217)/1000 -> 2.6174754 | O9: =((M9/(M9-N9))-1) -> 0.10655202
C10: İnci GS Yuasa | D10: ='A -Döviz'!AA12/1000 -> 10760.31 | E10: =('A -Döviz'!AA12-'A -Döviz'!Z12)/1000 -> -11782.675 | F10: =(D10/(D10-E10))-1 -> -0.5226759 | G10: =('A -Döviz'!AA39)/1000 -> 1647.421 | H10: =('A -Döviz'!AA39-'A -Döviz'!Z39)/1000 -> -3233.7434 | I10: =(G10/(G10-H10))-1 -> -0.66249426 | J10: ='A -Döviz'!AA142/1000 -> 274.34946 | K10: =('A -Döviz'!AA142-'A -Döviz'!Z142)/1000 -> -2626.7896 | L10: =(J10/(J10-K10))-1 -> -0.90543388 | M10: ='A -Döviz'!AA218/1000 -> -2472.8123 | N10: =('A -Döviz'!AA218-'A -Döviz'!Z218)/1000 -> -2878.9134 | O10: =((M10/(M10-N10))-1) -> -7.0891548
C11: Yusen İnci Loj. | D11: ='A -Döviz'!AA13/1000 -> 5403.6456 | E11: =('A -Döviz'!AA13-'A -Döviz'!Z13)/1000 -> -554.58101 | F11: =(D11/(D11-E11))-1 -> -0.0930782 | G11: =('A -Döviz'!AA40)/1000 -> 1183.0214 | H11: =('A -Döviz'!AA40-'A -Döviz'!Z40)/1000 -> -53.767077 | I11: =(G11/(G11-H11))-1 -> -0.04347314 | J11: ='A -Döviz'!AA143/1000 -> 606.40071 | K11: =('A -Döviz'!AA143-'A -Döviz'!Z143)/1000 -> 153.79958 | L11: =(J11/(J11-K11))-1 -> 0.33981263 | M11: ='A -Döviz'!AA219/1000 -> 266.91508 | N11: =('A -Döviz'!AA219-'A -Döviz'!Z219)/1000 -> 187.34422 | O11: =(M11/(M11-N11))-1 -> 2.3544324
C12: Jantaş | D12: ='A -Döviz'!AA14/1000 -> 11814.679 | E12: =('A -Döviz'!AA14-'A -Döviz'!Z14)/1000 -> -2041.1323 | F12: =(D12/(D12-E12))-1 -> -0.14731237 | G12: =('A -Döviz'!AA41)/1000 -> 3027.0706 | H12: =('A -Döviz'!AA41-'A -Döviz'!Z41)/1000 -> -195.4839 | I12: =(G12/(G12-H12))-1 -> -0.060661164 | J12: ='A -Döviz'!AA144/1000 -> 2866.0326 | K12: =('A -Döviz'!AA144-'A -Döviz'!Z144)/1000 -> -556.12204 | L12: =(J12/(J12-K12))-1 -> -0.1625064 | M12: ='A -Döviz'!AA220/1000 -> 2095.4481 | N12: =('A -Döviz'!AA220-'A -Döviz'!Z220)/1000 -> 31.085566 | O12: =(M12/(M12-N12))-1 -> 0.015058192
C13: Çelik | D13: ='A -Döviz'!AA15/1000 -> 9589.3663 | E13: =('A -Döviz'!AA15-'A -Döviz'!Z15)/1000 -> 1295.4971 | F13: =(D13/(D13-E13))-1 -> 0.15619936 | G13: =('A -Döviz'!AA42)/1000 -> 3399.9394 | H13: =('A -Döviz'!AA42-'A -Döviz'!Z42)/1000 -> 988.71206 | I13: =(G13/(G13-H13))-1 -> 0.41004514 | J13: ='A -Döviz'!AA145/1000 -> 3117.0046 | K13: =('A -Döviz'!AA145-'A -Döviz'!Z145)/1000 -> 875.91267 | L13: =(J13/(J13-K13))-1 -> 0.39084193 | M13: ='A -Döviz'!AA221/1000 -> 2585.9406 | N13: =('A -Döviz'!AA221-'A -Döviz'!Z221)/1000 -> 861.26263 | O13: =(M13/(M13-N13))-1 -> 0.49937592
C14: Alüminyum | D14: ='A -Döviz'!AA16/1000 -> 22482.647 | E14: =('A -Döviz'!AA16-'A -Döviz'!Z16)/1000 -> -1748.2533 | F14: =(D14/(D14-E14))-1 -> -0.072149746 | G14: =('A -Döviz'!AA43)/1000 -> 3963.3737 | H14: =('A -Döviz'!AA43-'A -Döviz'!Z43)/1000 -> -554.01183 | I14: =(G14/(G14-H14))-1 -> -0.12263993 | J14: ='A -Döviz'!AA146/1000 -> 3653.8965 | K14: =('A -Döviz'!AA146-'A -Döviz'!Z146)/1000 -> -253.49901 | L14: =(J14/(J14-K14))-1 -> -0.064876722 | M14: ='A -Döviz'!AA222/1000 -> 3300.9298 | N14: =('A -Döviz'!AA222-'A -Döviz'!Z222)/1000 -> -552.06812 | O14: =(M14/(M14-N14))-1 -> -0.14328275
C17: bin Avro | D17: Vergi | G17: Operasyonel Nakit | J17: Serbest Nakit | M17: Net Nakit
D18: Gerçekleşme | E18: Bütçe - Gerçekleşme Fark | F18: % Değişim | G18: Gerçekleşme | H18: Bütçe - Gerçekleşme Fark | I18: % Değişim | J18: Gerçekleşme | K18: Bütçe - Gerçekleşme Fark | L18: % Değişim | M18: Gerçekleşme | N18: Bütçe - Gerçekleşme Fark | O18: % Değişim
C19: Toplam | D19: =SUM(D20:D27) -> -341.55929 | E19: =SUM(E20:E27) -> -43.845778 | F19: =(D19/(D19-E19)) -> 1.1472751 | G19: =SUM(G20:G27) -> 10311.75 | H19: =SUM(H20:H27) -> -5682.1969 | I19: =((G19/(G19-H19))-1) -> -0.35527171 | J19: =SUM(J20:J27) -> 9191.7263 | K19: =SUM(K20:K27) -> -5141.0351 | L19: =((J19/(J19-K19))-1) -> -0.35869118 | M19: =SUM(M20:M27) -> -4534.3694 | N19: =SUM(N20:N27) -> -27509.965 | O19: =(M19/(M19-N19))-1 -> -1.1973559
C20: İnci Holding | D20: ='A -Döviz'!AA202/1000 -> -126.40879 | E20: =('A -Döviz'!AA202-'A -Döviz'!Z202)/1000 -> -16.22079 | F20: =-((D20/(D20-E20))-1) -> -0.14721013 | G20: ='A -Döviz'!AA291/1000 -> -322.34966 | H20: =('A -Döviz'!AA291-'A -Döviz'!Z291)/1000 -> -477.1543 | I20: =((G20/(G20-H20))-1) -> -3.0822998 | J20: ='A -Döviz'!AA304/1000 -> -322.34966 | K20: =('A -Döviz'!AA304-'A -Döviz'!Z304)/1000 -> -475.18934 | L20: =((J20/(J20-K20))-1) -> -3.1090706 | M20: ='A -Döviz'!AA265/1000 -> 17091.704 | N20: =('A -Döviz'!AA265-'A -Döviz'!Z265)/1000 -> 7291.21 | O20: =(M20/(M20-N20))-1 -> 0.74396352
C21: ISM | D21: ='A -Döviz'!AA203/1000 -> -20.740769 | E21: =('A -Döviz'!AA203-'A -Döviz'!Z203)/1000 -> -9.1727155 | F21: =-((D21/(D21-E21))-1) -> -0.79293507 | G21: ='A -Döviz'!AA292/1000 -> 182.56356 | H21: =('A -Döviz'!AA292-'A -Döviz'!Z292)/1000 -> -44.509057 | I21: =((G21/(G21-H21))-1) -> -0.19601243 | J21: ='A -Döviz'!AA305/1000 -> 131.81758 | K21: =('A -Döviz'!AA305-'A -Döviz'!Z305)/1000 -> -40.698409 | L21: =((J21/(J21-K21))-1) -> -0.23591095 | M21: ='A -Döviz'!AA266/1000 -> -6388.4993 | N21: =('A -Döviz'!AA266-'A -Döviz'!Z266)/1000 -> -5562.7719 | O21: =-((M21/(M21-N21))-1) -> -6.736814
C22: İncitaş | D22: ='A -Döviz'!AA204/1000 -> 0 | E22: =('A -Döviz'!AA204-'A -Döviz'!Z204)/1000 -> 8.1884116 | F22: =-IFERROR((D22/(D22-E22))-1,0) -> 1 | G22: ='A -Döviz'!AA293/1000 -> 58.366544 | H22: =('A -Döviz'!AA293-'A -Döviz'!Z293)/1000 -> -117.71158 | I22: =((G22/(G22-H22))-1) -> -0.66851905 | J22: ='A -Döviz'!AA306/1000 -> 58.366544 | K22: =('A -Döviz'!AA306-'A -Döviz'!Z306)/1000 -> -117.71158 | L22: =((J22/(J22-K22))-1) -> -0.66851905 | M22: ='A -Döviz'!AA267/1000 -> -178.30217 | N22: =('A -Döviz'!AA267-'A -Döviz'!Z267)/1000 -> 97.4135 | O22: =-((M22/(M22-N22))-1) -> 0.35331144
C23: İnci GS Yuasa | D23: ='A -Döviz'!AA205/1000 -> 0 | E23: =('A -Döviz'!AA205-'A -Döviz'!Z205)/1000 -> 0 | F23: 0 | G23: ='A -Döviz'!AA294/1000 -> 3176.5112 | H23: =('A -Döviz'!AA294-'A -Döviz'!Z294)/1000 -> 2905.8865 | I23: =((G23/(G23-H23))-1) -> 10.737697 | J23: ='A -Döviz'!AA307/1000 -> 2909.0553 | K23: =('A -Döviz'!AA307-'A -Döviz'!Z307)/1000 -> 3254.8766 | L23: =-((J23/(J23-K23))) -> 8.4120194 | M23: ='A -Döviz'!AA268/1000 -> -51044.529 | N23: =('A -Döviz'!AA268-'A -Döviz'!Z268)/1000 -> -9860.7636 | O23: =-((M23/(M23-N23))-1) -> -0.23943327
C24: Yusen İnci Loj. | D24: ='A -Döviz'!AA206/1000 -> 12.510289 | E24: =('A -Döviz'!AA206-'A -Döviz'!Z206)/1000 -> 48.142949 | F24: =-((D24/(D24-E24))-1) -> 1.3510905 | G24: ='A -Döviz'!AA295/1000 -> -182.64657 | H24: =('A -Döviz'!AA295-'A -Döviz'!Z295)/1000 -> -695.67728 | I24: =(G24/(G24-H24))-1 -> -1.3560149 | J24: ='A -Döviz'!AA308/1000 -> -243.77891 | K24: =('A -Döviz'!AA308-'A -Döviz'!Z308)/1000 -> -687.45797 | L24: =(J24/(J24-K24))-1 -> -1.5494488 | M24: ='A -Döviz'!AA269/1000 -> 1603.0792 | N24: =('A -Döviz'!AA269-'A -Döviz'!Z269)/1000 -> -18.032012 | O24: =(M24/(M24-N24))-1 -> -0.011123242
C25: Jantaş | D25: ='A -Döviz'!AA207/1000 -> -373.98408 | E25: =('A -Döviz'!AA207-'A -Döviz'!Z207)/1000 -> 19.208393 | F25: =-((D25/(D25-E25))-1) -> 0.048852392 | G25: ='A -Döviz'!AA296/1000 -> -970.02151 | H25: =('A -Döviz'!AA296-'A -Döviz'!Z296)/1000 -> -4221.8801 | I25: =((G25/(G25-H25))-1) -> -1.2982976 | J25: ='A -Döviz'!AA309/1000 -> -1265.4283 | K25: =('A -Döviz'!AA309-'A -Döviz'!Z309)/1000 -> -4283.0064 | L25: =((J25/(J25-K25))-1) -> -1.4193523 | M25: ='A -Döviz'!AA270/1000 -> 8134.848 | N25: =('A -Döviz'!AA270-'A -Döviz'!Z270)/1000 -> -5129.6927 | O25: =(M25/(M25-N25))-1 -> -0.38672222
C26: Çelik | D26: ='A -Döviz'!AA208/1000 -> -13.92815 | E26: =('A -Döviz'!AA208-'A -Döviz'!Z208)/1000 -> 218.09443 | F26: =-((D26/(D26-E26))-1) -> 0.93997071 | G26: ='A -Döviz'!AA297/1000 -> 4336.1464 | H26: =('A -Döviz'!AA297-'A -Döviz'!Z297)/1000 -> 782.60169 | I26: =((G26/(G26-H26))-1) -> 0.22023127 | J26: ='A -Döviz'!AA310/1000 -> 4086.1464 | K26: =('A -Döviz'!AA310-'A -Döviz'!Z310)/1000 -> 883.60169 | L26: =((J26/(J26-K26))-1) -> 0.27590612 | M26: ='A -Döviz'!AA271/1000 -> 14279.442 | N26: =('A -Döviz'!AA271-'A -Döviz'!Z271)/1000 -> -12626.154 | O26: =(M26/(M26-N26))-1 -> -0.46927614
C27: Alüminyum | D27: ='A -Döviz'!AA209/1000 -> 180.99221 | E27: =('A -Döviz'!AA209-'A -Döviz'!Z209)/1000 -> -312.08646 | F27: =-((D27/(D27-E27))-1) -> 0.63293441 | G27: ='A -Döviz'!AA298/1000 -> 4033.1801 | H27: =('A -Döviz'!AA298-'A -Döviz'!Z298)/1000 -> -3813.7527 | I27: =((G27/(G27-H27))-1) -> -0.48601827 | J27: ='A -Döviz'!AA311/1000 -> 3837.8974 | K27: =('A -Döviz'!AA311-'A -Döviz'!Z311)/1000 -> -3675.4497 | L27: =((J27/(J27-K27))-1) -> -0.4891894 | M27: ='A -Döviz'!AA272/1000 -> 11967.888 | N27: =('A -Döviz'!AA272-'A -Döviz'!Z272)/1000 -> -1701.1734 | O27: =(M27/(M27-N27))-1 -> -0.1244543
D30: Faaliyet Giderleri Marjı | F30: Brüt Kar Marjı | H30: EBITDA Marjı | J30: Net Kar Marjı | L30: Operasyonel Nakit Marjı | N30: Serbest Nakit Marjı
D31: Gerçekleşme | E31: Bütçe - Gerçekleşme Fark | F31: Gerçekleşme | G31: Bütçe - Gerçekleşme Fark | H31: Gerçekleşme | I31: Bütçe - Gerçekleşme Fark | J31: Gerçekleşme | K31: Bütçe - Gerçekleşme Fark | L31: Gerçekleşme | M31: Bütçe - Gerçekleşme Fark | N31: Gerçekleşme | O31: Bütçe - Gerçekleşme Fark
C33: İnci Holding | D33: ='A -Döviz'!AA102 -> 0.3941863 | E33: =-('A -Döviz'!AA102-'A -Döviz'!Z102) -> 0.055169941 | F33: ='A -Döviz'!AA79 -> 1 | G33: ='A -Döviz'!AA79-'A -Döviz'!Z79 -> 0 | H33: ='A -Döviz'!AA150 -> 0.61087749 | I33: ='A -Döviz'!AA150-'A -Döviz'!Z150 -> 0.05540856 | J33: ='A -Döviz'!AA226 -> 0.48006002 | K33: ='A -Döviz'!AA226-'A -Döviz'!Z226 -> 0.10268624 | L33: ='A -Döviz'!AA291/'A -Döviz'!AA9 -> -0.40806019 | M33: =L33-('A -Döviz'!Z291/'A -Döviz'!Z9) -> -0.58478606 | N33: ='A -Döviz'!AA304/'A -Döviz'!AA9 -> -0.40806019 | O33: =N33-'A -Döviz'!Z304/'A -Döviz'!Z9 -> -0.58254285
C34: ISM | D34: ='A -Döviz'!AA103 -> 0.30586298 | E34: =-('A -Döviz'!AA103-'A -Döviz'!Z103) -> -0.085906702 | F34: ='A -Döviz'!AA80 -> 0.22869641 | G34: ='A -Döviz'!AA80-'A -Döviz'!Z80 -> -0.091677749 | H34: ='A -Döviz'!AA151 -> -0.05162431 | I34: ='A -Döviz'!AA151-'A -Döviz'!Z151 -> -0.1836132 | J34: ='A -Döviz'!AA227 -> -0.45200013 | K34: ='A -Döviz'!AA227-'A -Döviz'!Z227 -> -0.52537773 | L34: ='A -Döviz'!AA292/'A -Döviz'!AA10 -> 0.40260924 | M34: =L34-('A -Döviz'!Z292/'A -Döviz'!Z10) -> 0.042521798 | N34: ='A -Döviz'!AA305/'A -Döviz'!AA10 -> 0.29069861 | O34: =N34-'A -Döviz'!Z305/'A -Döviz'!Z10 -> 0.017126042
C35: İncitaş | D35: ='A -Döviz'!AA104 -> 0.12970398 | E35: =-('A -Döviz'!AA104-'A -Döviz'!Z104) -> 0.021042144 | F35: ='A -Döviz'!AA81 -> 0.19124358 | G35: ='A -Döviz'!AA81-'A -Döviz'!Z81 -> -0.012406619 | H35: ='A -Döviz'!AA152 -> 0.062011106 | I35: ='A -Döviz'!AA152-'A -Döviz'!Z152 -> 0.0083185653 | J35: ='A -Döviz'!AA228 -> 0.030519232 | K35: ='A -Döviz'!AA228-'A -Döviz'!Z228 -> 0.013155958 | L35: ='A -Döviz'!AA293/'A -Döviz'!AA11 -> 0.065530704 | M35: =L35-('A -Döviz'!Z293/'A -Döviz'!Z11) -> -0.058925373 | N35: ='A -Döviz'!AA306/'A -Döviz'!AA11 -> 0.065530704 | O35: =N35-'A -Döviz'!Z306/'A -Döviz'!Z11 -> -0.058925373
C36: İnci GS Yuasa | D36: ='A -Döviz'!AA105 -> 0.14794068 | E36: =-('A -Döviz'!AA105-'A -Döviz'!Z105) -> -0.050734338 | F36: ='A -Döviz'!AA82 -> 0.15310162 | G36: ='A -Döviz'!AA82-'A -Döviz'!Z82 -> -0.063425344 | H36: ='A -Döviz'!AA153 -> 0.025496426 | I36: ='A -Döviz'!AA153-'A -Döviz'!Z153 -> -0.10319722 | J36: ='A -Döviz'!AA229 -> -0.22980865 | K36: ='A -Döviz'!AA229-'A -Döviz'!Z229 -> -0.24782317 | L36: ='A -Döviz'!AA294/'A -Döviz'!AA12 -> 0.29520629 | M36: =L36-('A -Döviz'!Z294/'A -Döviz'!Z12) -> 0.28320146 | N36: ='A -Döviz'!AA307/'A -Döviz'!AA12 -> 0.27035051 | O36: =N36-'A -Döviz'!Z307/'A -Döviz'!Z12 -> 0.28569103
C37: Yusen İnci Loj. | D37: ='A -Döviz'!AA106 -> 0.14551814 | E37: =-('A -Döviz'!AA106-'A -Döviz'!Z106) -> 0.01623303 | F37: ='A -Döviz'!AA83 -> 0.21893023 | G37: ='A -Döviz'!AA83-'A -Döviz'!Z83 -> 0.011353625 | H37: ='A -Döviz'!AA154 -> 0.11222067 | I37: ='A -Döviz'!AA154-'A -Döviz'!Z154 -> 0.036258277 | J37: ='A -Döviz'!AA230 -> 0.049395372 | K37: ='A -Döviz'!AA230-'A -Döviz'!Z230 -> 0.036040582 | L37: ='A -Döviz'!AA295/'A -Döviz'!AA13 -> -0.03380062 | M37: =L37-('A -Döviz'!Z295/'A -Döviz'!Z13) -> -0.11990522 | N37: ='A -Döviz'!AA308/'A -Döviz'!AA13 -> -0.045113787 | O37: =N37-'A -Döviz'!Z308/'A -Döviz'!Z13 -> -0.11957874
C38: Jantaş | D38: ='A -Döviz'!AA107 -> 0.050360267 | E38: =-('A -Döviz'!AA107-'A -Döviz'!Z107) -> 0.0050527569 | F38: ='A -Döviz'!AA84 -> 0.25621269 | G38: ='A -Döviz'!AA84-'A -Döviz'!Z84 -> 0.023634856 | H38: ='A -Döviz'!AA155 -> 0.24258236 | I38: ='A -Döviz'!AA155-'A -Döviz'!Z155 -> -0.0044009941 | J38: ='A -Döviz'!AA231 -> 0.17735972 | K38: ='A -Döviz'!AA231-'A -Döviz'!Z231 -> 0.028370784 | L38: ='A -Döviz'!AA296/'A -Döviz'!AA14 -> -0.082103081 | M38: =L38-('A -Döviz'!Z296/'A -Döviz'!Z14) -> -0.31679585 | N38: ='A -Döviz'!AA309/'A -Döviz'!AA14 -> -0.10710645 | O38: =N38-'A -Döviz'!Z309/'A -Döviz'!Z14 -> -0.32489075
C39: Çelik | D39: ='A -Döviz'!AA108 -> 0.054425459 | E39: =-('A -Döviz'!AA108-'A -Döviz'!Z108) -> -0.0021091709 | F39: ='A -Döviz'!AA85 -> 0.35455308 | G39: ='A -Döviz'!AA85-'A -Döviz'!Z85 -> 0.063829023 | H39: ='A -Döviz'!AA156 -> 0.32504802 | I39: ='A -Döviz'!AA156-'A -Döviz'!Z156 -> 0.054837362 | J39: ='A -Döviz'!AA232 -> 0.26966751 | K39: ='A -Döviz'!AA232-'A -Döviz'!Z232 -> 0.061721393 | L39: ='A -Döviz'!AA297/'A -Döviz'!AA15 -> 0.45218279 | M39: =L39-('A -Döviz'!Z297/'A -Döviz'!Z15) -> 0.023728395 | N39: ='A -Döviz'!AA310/'A -Döviz'!AA15 -> 0.42611225 | O39: =N39-'A -Döviz'!Z310/'A -Döviz'!Z15 -> 0.039978267
C40: Alüminyum | D40: ='A -Döviz'!AA109 -> 0.044010085 | E40: =-('A -Döviz'!AA109-'A -Döviz'!Z109) -> 0.0018922525 | F40: ='A -Döviz'!AA86 -> 0.1762859 | G40: ='A -Döviz'!AA86-'A -Döviz'!Z86 -> -0.010144874 | H40: ='A -Döviz'!AA157 -> 0.16252075 | I40: ='A -Döviz'!AA157-'A -Döviz'!Z157 -> 0.001264023 | J40: ='A -Döviz'!AA233 -> 0.14682123 | K40: ='A -Döviz'!AA233-'A -Döviz'!Z233 -> -0.012190526 | L40: ='A -Döviz'!AA298/'A -Döviz'!AA16 -> 0.17939081 | M40: =L40-('A -Döviz'!Z298/'A -Döviz'!Z16) -> -0.14444912 | N40: ='A -Döviz'!AA311/'A -Döviz'!AA16 -> 0.17070487 | O40: =N40-'A -Döviz'!Z311/'A -Döviz'!Z16 -> -0.1393681
D64: Ciro | G64: EBITDA | K64: Net Kar
D65: Gerçekleşme | E65: % | G65: Gerçekleşme | I65: % | K65: Gerçekleşme | M65: %
C66: Ciro | D66: 55 | G66: 55 | K66: 55
C67: Adet | D67: 12 | E67: =D67/$D$66 -> 0.21818182 | G67: 12 | H67: =G67/$D$66 -> 0.21818182 | K67: 12 | M67: =K67/$K$66 -> 0.21818182
C68: Fiyat | D68: 9 | E68: =D68/$D$66 -> 0.16363636 | G68: 9 | H68: =G68/$D$66 -> 0.16363636 | K68: 9 | M68: =K68/$K$66 -> 0.16363636
C69: Miks | D69: 8 | E69: =D69/$D$66 -> 0.14545455 | G69: 8 | H69: =G69/$D$66 -> 0.14545455 | K69: 8 | M69: =K69/$K$66 -> 0.14545455
C70: Ham Madde | D70: 5 | E70: =D70/$D$66 -> 0.090909091 | G70: 5 | H70: =G70/$D$66 -> 0.090909091 | K70: 5 | M70: =K70/$K$66 -> 0.090909091
...

Sheet Finansal Raporlama KÜM
C3: KÜMÜLATİF
C4: bin Avro | D4: Ciro | G4: Brüt Kar | J4: EBITDA | M4: Net Kar
D5: Gerçekleşme | E5: Bütçe - Gerçekleşme Fark | F5: % Değişim | G5: Gerçekleşme | H5: Bütçe - Gerçekleşme Fark | I5: % Değişim | J5: Gerçekleşme | K5: Bütçe - Gerçekleşme Fark | L5: % Değişim | M5: Gerçekleşme | N5: Bütçe - Gerçekleşme Fark | O5: % Değişim
C6: Toplam | D6: =SUM(D7:D14) -> 565671.74 | E6: =SUM(E7:E14) -> -53626.511 | F6: =(D6/(D6-E6))-1 -> -0.086592383 | G6: =SUM(G7:G14) -> 100550.71 | H6: =SUM(H7:H14) -> -16410.107 | I6: =(G6/(G6-H6))-1 -> -0.14030431 | J6: =SUM(J7:J14) -> 66115.062 | K6: =SUM(K7:K14) -> -12763.622 | L6: =(J6/(J6-K6))-1 -> -0.16181332 | M6: =SUM(M7:M14) -> 10077.388 | N6: =SUM(N7:N14) -> -26302.144 | O6: =(M6/(M6-N6))-1 -> -0.72299292
C7: İnci Holding | D7: ='C-Döviz'!AJ9/1000 -> 6530.3115 | E7: =('C-Döviz'!AJ9-'C-Döviz'!Z9)/1000 -> -307.09639 | F7: =(D7/(D7-E7))-1 -> -0.044914154 | G7: =('C-Döviz'!AJ36)/1000 -> 6530.3115 | H7: =('C-Döviz'!AJ36-'C-Döviz'!Z36)/1000 -> -307.09639 | I7: =(G7/(G7-H7))-1 -> -0.044914154 | J7: ='C-Döviz'!AJ139/1000 -> 3039.0888 | K7: =('C-Döviz'!AJ139-'C-Döviz'!Z139)/1000 -> -280.50444 | L7: =(J7/(J7-K7))-1 -> -0.084499641 | M7: ='C-Döviz'!AJ215/1000 -> 2668.6618 | N7: =('C-Döviz'!AJ215-'C-Döviz'!Z215)/1000 -> 534.82385 | O7: =(M7/(M7-N7))-1 -> 0.2506394
C8: ISM | D8: ='C-Döviz'!AJ10/1000 -> 5967.9349 | E8: =('C-Döviz'!AJ10-'C-Döviz'!Z10)/1000 -> -1976.3017 | F8: =(D8/(D8-E8))-1 -> -0.24877176 | G8: =('C-Döviz'!AJ37)/1000 -> 1401.8845 | H8: =('C-Döviz'!AJ37-'C-Döviz'!Z37)/1000 -> -991.12984 | I8: =(G8/(G8-H8))-1 -> -0.41417631 | J8: ='C-Döviz'!AJ140/1000 -> 221.6865 | K8: =('C-Döviz'!AJ140-'C-Döviz'!Z140)/1000 -> -912.01891 | L8: =(J8/(J8-K8))-1 -> -0.80445846 | M8: ='C-Döviz'!AJ216/1000 -> -1015.0345 | N8: =('C-Döviz'!AJ216-'C-Döviz'!Z216)/1000 -> -1756.8359 | O8: =(M8/(M8-N8))-1 -> -2.3683372
C9: İncitaş | D9: ='C-Döviz'!AJ11/1000 -> 9087.7867 | E9: =('C-Döviz'!AJ11-'C-Döviz'!Z11)/1000 -> -3066.7795 | F9: =(D9/(D9-E9))-1 -> -0.25231501 | G9: =('C-Döviz'!AJ38)/1000 -> 1427.8488 | H9: =('C-Döviz'!AJ38-'C-Döviz'!Z38)/1000 -> -893.61152 | I9: =(G9/(G9-H9))-1 -> -0.38493509 | J9: ='C-Döviz'!AJ141/1000 -> 255.55944 | K9: =('C-Döviz'!AJ141-'C-Döviz'!Z141)/1000 -> -319.03575 | L9: =((J9/(J9-K9))-1) -> -0.55523567 | M9: ='C-Döviz'!AJ217/1000 -> -98.697156 | N9: =('C-Döviz'!AJ217-'C-Döviz'!Z217)/1000 -> -159.90088 | O9: =-((M9/(M9-N9))-1) -> 2.6126006
C10: İnci GS Yuasa | D10: ='C-Döviz'!AJ12/1000 -> 126030.1 | E10: =('C-Döviz'!AJ12-'C-Döviz'!Z12)/1000 -> -55175.93 | F10: =(D10/(D10-E10))-1 -> -0.30449279 | G10: =('C-Döviz'!AJ39)/1000 -> 17075.643 | H10: =('C-Döviz'!AJ39-'C-Döviz'!Z39)/1000 -> -17409.143 | I10: =(G10/(G10-H10))-1 -> -0.50483547 | J10: ='C-Döviz'!AJ142/1000 -> 1489.7818 | K10: =('C-Döviz'!AJ142-'C-Döviz'!Z142)/1000 -> -15242.45 | L10: =(J10/(J10-K10))-1 -> -0.91096335 | M10: ='C-Döviz'!AJ218/1000 -> -26215.785 | N10: =('C-Döviz'!AJ218-'C-Döviz'!Z218)/1000 -> -21897.37 | O10: =-((M10/(M10-N10))-1) -> -5.0706956
C11: Yusen İnci Loj. | D11: ='C-Döviz'!AJ13/1000 -> 48487.948 | E11: =('C-Döviz'!AJ13-'C-Döviz'!Z13)/1000 -> -9889.4305 | F11: =(D11/(D11-E11))-1 -> -0.16940518 | G11: =('C-Döviz'!AJ40)/1000 -> 10273.605 | H11: =('C-Döviz'!AJ40-'C-Döviz'!Z40)/1000 -> -896.69385 | I11: =(G11/(G11-H11))-1 -> -0.080274827 | J11: ='C-Döviz'!AJ143/1000 -> 3826.3729 | K11: =('C-Döviz'!AJ143-'C-Döviz'!Z143)/1000 -> 17.779218 | L11: =(J11/(J11-K11))-1 -> 0.0046681845 | M11: ='C-Döviz'!AJ219/1000 -> 1259.3685 | N11: =('C-Döviz'!AJ219-'C-Döviz'!Z219)/1000 -> 557.4965 | O11: =(M11/(M11-N11))-1 -> 0.79429938
C12: Jantaş | D12: ='C-Döviz'!AJ14/1000 -> 104950.21 | E12: =('C-Döviz'!AJ14-'C-Döviz'!Z14)/1000 -> 4362.6068 | F12: =(D12/(D12-E12))-1 -> 0.043371218 | G12: =('C-Döviz'!AJ41)/1000 -> 19353.674 | H12: =('C-Döviz'!AJ41-'C-Döviz'!Z41)/1000 -> 3068.7376 | I12: =(G12/(G12-H12))-1 -> 0.18844025 | J12: ='C-Döviz'!AJ144/1000 -> 17008.492 | K12: =('C-Döviz'!AJ144-'C-Döviz'!Z144)/1000 -> 1717.3841 | L12: =(J12/(J12-K12))-1 -> 0.1123126 | M12: ='C-Döviz'!AJ220/1000 -> 9649.5204 | N12: =('C-Döviz'!AJ220-'C-Döviz'!Z220)/1000 -> 2143.7248 | O12: =(M12/(M12-N12))-1 -> 0.28560927
C13: Çelik | D13: ='C-Döviz'!AJ15/1000 -> 73735.729 | E13: =('C-Döviz'!AJ15-'C-Döviz'!Z15)/1000 -> 8549.5681 | F13: =(D13/(D13-E13))-1 -> 0.13115618 | G13: =('C-Döviz'!AJ42)/1000 -> 21124.56 | H13: =('C-Döviz'!AJ42-'C-Döviz'!Z42)/1000 -> 4880.7707 | I13: =(G13/(G13-H13))-1 -> 0.30046996 | J13: ='C-Döviz'!AJ145/1000 -> 19272.518 | K13: =('C-Döviz'!AJ145-'C-Döviz'!Z145)/1000 -> 4320.8874 | L13: =(J13/(J13-K13))-1 -> 0.28899106 | M13: ='C-Döviz'!AJ221/1000 -> 11051.709 | N13: =('C-Döviz'!AJ221-'C-Döviz'!Z221)/1000 -> 134.63149 | O13: =(M13/(M13-N13))-1 -> 0.012332191
C14: Alüminyum | D14: ='C-Döviz'!AJ16/1000 -> 190881.72 | E14: =('C-Döviz'!AJ16-'C-Döviz'!Z16)/1000 -> 3876.8525 | F14: =(D14/(D14-E14))-1 -> 0.020731292 | G14: =('C-Döviz'!AJ43)/1000 -> 23363.186 | H14: =('C-Döviz'!AJ43-'C-Döviz'!Z43)/1000 -> -3861.941 | I14: =(G14/(G14-H14))-1 -> -0.14185208 | J14: ='C-Döviz'!AJ146/1000 -> 21001.563 | K14: =('C-Döviz'!AJ146-'C-Döviz'!Z146)/1000 -> -2065.6638 | L14: =(J14/(J14-K14))-1 -> -0.089549723 | M14: ='C-Döviz'!AJ222/1000 -> 12777.644 | N14: =('C-Döviz'!AJ222-'C-Döviz'!Z222)/1000 -> -5858.7137 | O14: =(M14/(M14-N14))-1 -> -0.3143701
C17: bin Avro | D17: Vergi | G17: Operasyonel Nakit | J17: Serbest Nakit | M17: Net Nakit
D18: Gerçekleşme | E18: Bütçe - Gerçekleşme Fark | F18: % Değişim | G18: Gerçekleşme | H18: Bütçe - Gerçekleşme Fark | I18: % Değişim | J18: Gerçekleşme | K18: Bütçe - Gerçekleşme Fark | L18: % Değişim | M18: Gerçekleşme | N18: Bütçe - Gerçekleşme Fark | O18: % Değişim
C19: Toplam | D19: =SUM(D20:D27) -> -5919.2195 | E19: =SUM(E20:E27) -> -1944.4595 | F19: =(D19/(D19-E19))-1 -> 0.48920175 | G19: =SUM(G20:G27) -> 47522.539 | H19: =SUM(H20:H27) -> -14203.586 | I19: =((G19/(G19-H19))-1) -> -0.23010656 | J19: =SUM(J20:J27) -> 29480.781 | K19: =SUM(K20:K27) -> -19942.768 | L19: =((J19/(J19-K19))-1) -> -0.4035074 | M19: =SUM(M20:M27) -> -4534.3694 | N19: =SUM(N20:N27) -> -27509.965 | O19: =(M19/(M19-N19))-1 -> -1.1973559
C20: İnci Holding | D20: ='C-Döviz'!AJ202/1000 -> -889.55392 | E20: =('C-Döviz'!AJ202-'C-Döviz'!Z202)/1000 -> -178.27462 | F20: =-((D20/(D20-E20))-1) -> -0.2506394 | G20: ='C-Döviz'!AJ291/1000 -> 2331.0995 | H20: =('C-Döviz'!AA291-'C-Döviz'!Z291)/1000 -> -832.21314 | I20: =(G20/(G20-H20))-1 -> -0.2630828 | J20: ='C-Döviz'!AJ304/1000 -> 2323.5545 | K20: =('C-Döviz'!AA304-'C-Döviz'!Z304)/1000 -> -827.10136 | L20: =(J20/(J20-K20))-1 -> -0.26251721 | M20: ='C-Döviz'!AA265/1000 -> 17091.704 | N20: =M20-'C-Döviz'!Z265/1000 -> 7291.21 | O20: =(M20/(M20-N20))-1 -> 0.74396352
C21: ISM | D21: ='C-Döviz'!AJ203/1000 -> -34.619311 | E21: =('C-Döviz'!AJ203-'C-Döviz'!Z203)/1000 -> 150.83105 | F21: =-((D21/(D21-E21))-1) -> 0.81332304 | G21: ='C-Döviz'!AJ292/1000 -> 94.449464 | H21: =('C-Döviz'!AA292-'C-Döviz'!Z292)/1000 -> -989.0497 | I21: =((G21/(G21-H21))-1) -> -0.91282922 | J21: ='C-Döviz'!AJ305/1000 -> -435.0404 | K21: =('C-Döviz'!AA305-'C-Döviz'!Z305)/1000 -> -939.99587 | L21: =((J21/(J21-K21))-1) -> -1.8615421 | M21: ='C-Döviz'!AA266/1000 -> -6388.4993 | N21: =M21-'C-Döviz'!Z266/1000 -> -5562.7719 | O21: =-((M21/(M21-N21))-1) -> -6.736814
C22: İncitaş | D22: ='C-Döviz'!AJ204/1000 -> -0.0082083884 | E22: =('C-Döviz'!AJ204-'C-Döviz'!Z204)/1000 -> 70.301711 | F22: =-((D22/(D22-E22))-1) -> 0.99988325 | G22: ='C-Döviz'!AJ293/1000 -> 123.07484 | H22: =('C-Döviz'!AA293-'C-Döviz'!Z293)/1000 -> 342.95738 | I22: =-((G22/(G22-H22))-1) -> 1.5597299 | J22: ='C-Döviz'!AJ306/1000 -> 123.07484 | K22: =('C-Döviz'!AA306-'C-Döviz'!Z306)/1000 -> 342.95738 | L22: =-((J22/(J22-K22))-1) -> 1.5597299 | M22: ='C-Döviz'!AA267/1000 -> -178.30217 | N22: =M22-'C-Döviz'!Z267/1000 -> 97.4135 | O22: =-((M22/(M22-N22))-1) -> 0.35331144
C23: İnci GS Yuasa | D23: ='C-Döviz'!AJ205/1000 -> 0 | E23: =('C-Döviz'!AJ205-'C-Döviz'!Z205)/1000 -> 0 | F23: 0 | G23: ='C-Döviz'!AJ294/1000 -> 2616.4004 | H23: =('C-Döviz'!AA294-'C-Döviz'!Z294)/1000 -> -6284.2839 | I23: =((G23/(G23-H23))-1) -> -0.70604503 | J23: ='C-Döviz'!AJ307/1000 -> 1189.1052 | K23: =('C-Döviz'!AA307-'C-Döviz'!Z307)/1000 -> -3766.2794 | L23: =((J23/(J23-K23))-1) -> -0.76003776 | M23: ='C-Döviz'!AA268/1000 -> -51044.529 | N23: =M23-'C-Döviz'!Z268/1000 -> -9860.7636 | O23: =-(M23/(M23-N23))-1 -> -2.2394333
C24: Yusen İnci Loj. | D24: ='C-Döviz'!AJ206/1000 -> -208.38717 | E24: =('C-Döviz'!AJ206-'C-Döviz'!Z206)/1000 -> 141.40323 | F24: =-((D24/(D24-E24))-1) -> 0.40425132 | G24: ='C-Döviz'!AJ295/1000 -> 5080.0747 | H24: =('C-Döviz'!AA295-'C-Döviz'!Z295)/1000 -> 1055.3634 | I24: =((G24/(G24-H24))-1) -> 0.2622209 | J24: ='C-Döviz'!AJ308/1000 -> 3913.7512 | K24: =('C-Döviz'!AA308-'C-Döviz'!Z308)/1000 -> 580.96511 | L24: =(J24/(J24-K24))-1 -> 0.17431815 | M24: ='C-Döviz'!AA269/1000 -> 1603.0792 | N24: =M24-'C-Döviz'!Z269/1000 -> -18.032012 | O24: =(M24/(M24-N24))-1 -> -0.011123242
C25: Jantaş | D25: ='C-Döviz'!AJ207/1000 -> -3042.0139 | E25: =('C-Döviz'!AJ207-'C-Döviz'!Z207)/1000 -> -940.15931 | F25: =-((D25/(D25-E25))-1) -> -0.44729989 | G25: ='C-Döviz'!AJ296/1000 -> 8127.2592 | H25: =('C-Döviz'!AA296-'C-Döviz'!Z296)/1000 -> 557.90043 | I25: =((G25/(G25-H25))-1) -> 0.073705111 | J25: ='C-Döviz'!AJ309/1000 -> 5514.5208 | K25: =('C-Döviz'!AA309-'C-Döviz'!Z309)/1000 -> 71.783698 | L25: =((J25/(J25-K25))-1) -> 0.013188897 | M25: ='C-Döviz'!AA270/1000 -> 8134.848 | N25: =M25-'C-Döviz'!Z270/1000 -> -5129.6927 | O25: =(M25/(M25-N25))-1 -> -0.38672222
C26: Çelik | D26: ='C-Döviz'!AJ208/1000 -> -682.53347 | E26: =('C-Döviz'!AJ208-'C-Döviz'!Z208)/1000 -> 744.45732 | F26: =-((D26/(D26-E26))-1) -> 0.52169735 | G26: ='C-Döviz'!AJ297/1000 -> 15566.602 | H26: =('C-Döviz'!AA297-'C-Döviz'!Z297)/1000 -> -5315.8855 | I26: =((G26/(G26-H26))-1) -> -0.25456189 | J26: ='C-Döviz'!AJ310/1000 -> 5389.8133 | K26: =('C-Döviz'!AA310-'C-Döviz'!Z310)/1000 -> -12664.674 | L26: =(J26/(J26-K26))-1 -> -0.7014696 | M26: ='C-Döviz'!AA271/1000 -> 14279.442 | N26: =M26-'C-Döviz'!Z271/1000 -> -12626.154 | O26: =(M26/(M26-N26))-1 -> -0.46927614
C27: Alüminyum | D27: ='C-Döviz'!AJ209/1000 -> -1062.1036 | E27: =('C-Döviz'!AJ209-'C-Döviz'!Z209)/1000 -> -1933.0189 | F27: =((D27/(D27-E27))-1) -> -2.2195256 | G27: ='C-Döviz'!AJ298/1000 -> 13583.578 | H27: =('C-Döviz'!AA298-'C-Döviz'!Z298)/1000 -> -2738.3749 | I27: =((G27/(G27-H27))-1) -> -0.1677725 | J27: ='C-Döviz'!AJ311/1000 -> 11462.002 | K27: =('C-Döviz'!AA311-'C-Döviz'!Z311)/1000 -> -2740.423 | L27: =((J27/(J27-K27))-1) -> -0.19295458 | M27: ='C-Döviz'!AA272/1000 -> 11967.888 | N27: =M27-'C-Döviz'!Z272/1000 -> -1701.1734 | O27: =(M27/(M27-N27))-1 -> -0.1244543
D30: Faaliyet Giderleri Marjı | F30: Brüt Kar Marjı | H30: EBITDA Marjı | J30: Net Kar Marjı | L30: Operasyonel Nakit Marjı | N30: Serbest Nakit Marjı
D31: Gerçekleşme | E31: Bütçe - Gerçekleşme Fark | F31: Gerçekleşme | G31: Bütçe - Gerçekleşme Fark | H31: Gerçekleşme | I31: Bütçe - Gerçekleşme Fark | J31: Gerçekleşme | K31: Bütçe - Gerçekleşme Fark | L31: Gerçekleşme | M31: Bütçe - Gerçekleşme Fark | N31: Gerçekleşme | O31: Bütçe - Gerçekleşme Fark
C33: İnci Holding | D33: ='C-Döviz'!AJ102 -> 0.54096706 | E33: =-('C-Döviz'!AA102-'C-Döviz'!Z102) -> -0.020469784 | F33: ='C-Döviz'!AJ79 -> 1 | G33: ='C-Döviz'!AA79-'C-Döviz'!Z79 -> 0 | H33: ='C-Döviz'!AJ150 -> 0.46538191 | I33: ='C-Döviz'!AA150-'C-Döviz'!Z150 -> -0.020122734 | J33: ='C-Döviz'!AJ226 -> 0.40865765 | K33: ='C-Döviz'!AA226-'C-Döviz'!Z226 -> 0.096574776 | L33: ='C-Döviz'!AJ291/'C-Döviz'!AJ9 -> 0.35696605 | M33: =L33-('C-Döviz'!Z291/'C-Döviz'!Z9) -> -0.10568188 | N33: ='C-Döviz'!AJ304/'C-Döviz'!AJ9 -> 0.35581066 | O33: =N33-('C-Döviz'!Z304/'C-Döviz'!Z9) -> -0.10498616
C34: ISM | D34: ='C-Döviz'!AJ103 -> 0.21691081 | E34: =-('C-Döviz'!AA103-'C-Döviz'!Z103) -> -0.03860526 | F34: ='C-Döviz'!AJ80 -> 0.23490277 | G34: ='C-Döviz'!AA80-'C-Döviz'!Z80 -> -0.066323691 | H34: ='C-Döviz'!AJ151 -> 0.037146267 | I34: ='C-Döviz'!AA151-'C-Döviz'!Z151 -> -0.10556164 | J34: ='C-Döviz'!AJ227 -> -0.17008136 | K34: ='C-Döviz'!AA227-'C-Döviz'!Z227 -> -0.26345741 | L34: ='C-Döviz'!AJ292/'C-Döviz'!AJ10 -> 0.015826155 | M34: =L34-('C-Döviz'!Z292/'C-Döviz'!Z10) -> -0.12056192 | N34: ='C-Döviz'!AJ305/'C-Döviz'!AJ10 -> -0.072896305 | O34: =N34-('C-Döviz'!Z305/'C-Döviz'!Z10) -> -0.1364588
C35: İncitaş | D35: ='C-Döviz'!AJ104 -> 0.12959812 | E35: =-('C-Döviz'!AA104-'C-Döviz'!Z104) -> 0.015013858 | F35: ='C-Döviz'!AJ81 -> 0.15711733 | G35: ='C-Döviz'!AA81-'C-Döviz'!Z81 -> -0.033877582 | H35: ='C-Döviz'!AJ152 -> 0.028121197 | I35: ='C-Döviz'!AA152-'C-Döviz'!Z152 -> -0.019152821 | J35: ='C-Döviz'!AJ228 -> -0.010860417 | K35: ='C-Döviz'!AA228-'C-Döviz'!Z228 -> -0.015895868 | L35: ='C-Döviz'!AJ293/'C-Döviz'!AJ11 -> 0.013542884 | M35: =L35-('C-Döviz'!Z293/'C-Döviz'!Z11) -> 0.031633413 | N35: ='C-Döviz'!AJ306/'C-Döviz'!AJ11 -> 0.013542884 | O35: =N35-('C-Döviz'!Z306/'C-Döviz'!Z11) -> 0.031633413
C36: İnci GS Yuasa | D36: ='C-Döviz'!AJ105 -> 0.13792311 | E36: =-('C-Döviz'!AA105-'C-Döviz'!Z105) -> -0.028646533 | F36: ='C-Döviz'!AJ82 -> 0.13548861 | G36: ='C-Döviz'!AA82-'C-Döviz'!Z82 -> -0.054818446 | H36: ='C-Döviz'!AJ153 -> 0.011820841 | I36: ='C-Döviz'!AA153-'C-Döviz'!Z153 -> -0.080517319 | J36: ='C-Döviz'!AJ229 -> -0.20801209 | K36: ='C-Döviz'!AA229-'C-Döviz'!Z229 -> -0.18418057 | L36: ='C-Döviz'!AJ294/'C-Döviz'!AJ12 -> 0.020760123 | M36: =L36-('C-Döviz'!Z294/'C-Döviz'!Z12) -> -0.028359016 | N36: ='C-Döviz'!AJ307/'C-Döviz'!AJ12 -> 0.0094350887 | O36: =N36-('C-Döviz'!Z307/'C-Döviz'!Z12) -> -0.017911598
C37: Yusen İnci Loj. | D37: ='C-Döviz'!AJ106 -> 0.16812818 | E37: =-('C-Döviz'!AA106-'C-Döviz'!Z106) -> -0.018282497 | F37: ='C-Döviz'!AJ83 -> 0.21187957 | G37: ='C-Döviz'!AA83-'C-Döviz'!Z83 -> 0.0205332 | H37: ='C-Döviz'!AJ154 -> 0.078913895 | I37: ='C-Döviz'!AA154-'C-Döviz'!Z154 -> 0.013672979 | J37: ='C-Döviz'!AJ230 -> 0.025972815 | K37: ='C-Döviz'!AA230-'C-Döviz'!Z230 -> 0.013949802 | L37: ='C-Döviz'!AJ295/'C-Döviz'!AJ13 -> 0.10476984 | M37: =L37-('C-Döviz'!Z295/'C-Döviz'!Z13) -> 0.035826848 | N37: ='C-Döviz'!AJ308/'C-Döviz'!AJ13 -> 0.080715957 | O37: =N37-('C-Döviz'!Z308/'C-Döviz'!Z13) -> 0.023625589
C38: Jantaş | D38: ='C-Döviz'!AJ107 -> 0.05982241 | E38: =-('C-Döviz'!AA107-'C-Döviz'!Z107) -> 0.0047564489 | F38: ='C-Döviz'!AJ84 -> 0.18440815 | G38: ='C-Döviz'!AA84-'C-Döviz'!Z84 -> 0.022510104 | H38: ='C-Döviz'!AJ155 -> 0.16206249 | I38: ='C-Döviz'!AA155-'C-Döviz'!Z155 -> 0.01004467 | J38: ='C-Döviz'!AJ231 -> 0.091943795 | K38: ='C-Döviz'!AA231-'C-Döviz'!Z231 -> 0.017324304 | L38: ='C-Döviz'!AJ296/'C-Döviz'!AJ14 -> 0.077439191 | M38: =L38-('C-Döviz'!Z296/'C-Döviz'!Z14) -> 0.0021877815 | N38: ='C-Döviz'!AJ309/'C-Döviz'!AJ14 -> 0.052544162 | O38: =N38-('C-Döviz'!Z309/'C-Döviz'!Z14) -> -0.0015652607
C39: Çelik | D39: ='C-Döviz'!AJ108 -> 0.055100064 | E39: =-('C-Döviz'!AA108-'C-Döviz'!Z108) -> 0.00078124024 | F39: ='C-Döviz'!AJ85 -> 0.28649015 | G39: ='C-Döviz'!AA85-'C-Döviz'!Z85 -> 0.037299385 | H39: ='C-Döviz'!AJ156 -> 0.26137285 | I39: ='C-Döviz'!AA156-'C-Döviz'!Z156 -> 0.032004684 | J39: ='C-Döviz'!AJ232 -> 0.14988269 | K39: ='C-Döviz'!AA232-'C-Döviz'!Z232 -> -0.017592703 | L39: ='C-Döviz'!AJ297/'C-Döviz'!AJ15 -> 0.21111342 | M39: =L39-('C-Döviz'!Z297/'C-Döviz'!Z15) -> -0.10923813 | N39: ='C-Döviz'!AJ310/'C-Döviz'!AJ15 -> 0.073096359 | O39: =N39-('C-Döviz'!Z310/'C-Döviz'!Z15) -> -0.20387175
C40: Alüminyum | D40: ='C-Döviz'!AJ109 -> 0.04641657 | E40: =-('C-Döviz'!AA109-'C-Döviz'!Z109) -> 0.0019927702 | F40: ='C-Döviz'!AJ86 -> 0.12239614 | G40: ='C-Döviz'!AA86-'C-Döviz'!Z86 -> -0.023188984 | H40: ='C-Döviz'!AJ157 -> 0.11002396 | I40: ='C-Döviz'!AA157-'C-Döviz'!Z157 -> -0.013326982 | J40: ='C-Döviz'!AJ233 -> 0.066940115 | K40: ='C-Döviz'!AA233-'C-Döviz'!Z233 -> -0.03271696 | L40: ='C-Döviz'!AJ298/'C-Döviz'!AJ16 -> 0.071162282 | M40: =L40-('C-Döviz'!Z298/'C-Döviz'!Z16) -> -0.016118621 | N40: ='C-Döviz'!AJ311/'C-Döviz'!AJ16 -> 0.060047668 | O40: =N40-('C-Döviz'!Z311/'C-Döviz'!Z16) -> -0.015899153
D64: Ciro | G64: EBITDA | K64: Net Kar
D65: Gerçekleşme | E65: % | G65: Gerçekleşme | I65: % | K65: Gerçekleşme | M65: %
C66: Ciro | D66: 55 | G66: 55 | K66: 55
C67: Adet | D67: 12 | E67: =D67/$D$66 -> 0.21818182 | G67: 12 | H67: =G67/$D$66 -> 0.21818182 | K67: 12 | M67: =K67/$K$66 -> 0.21818182
C68: Fiyat | D68: 9 | E68: =D68/$D$66 -> 0.16363636 | G68: 9 | H68: =G68/$D$66 -> 0.16363636 | K68: 9 | M68: =K68/$K$66 -> 0.16363636
C69: Miks | D69: 8 | E69: =D69/$D$66 -> 0.14545455 | G69: 8 | H69: =G69/$D$66 -> 0.14545455 | K69: 8 | M69: =K69/$K$66 -> 0.14545455
C70: Ham Madde | D70: 5 | E70: =D70/$D$66 -> 0.090909091 | G70: 5 | H70: =G70/$D$66 -> 0.090909091 | K70: 5 | M70: =K70/$K$66 -> 0.090909091
...

Sheet Finansal Raporlama Tahmin
C3: KÜMÜLATİF | D3: Ciro | I3: Brüt Kar | N3: EBITDA | S3: Net Kar
C4: bin Avro
D5: Temmuz Tahmin | E5: Ağustos Tahmin | F5: Eylül Tahmin | G5: Bütçe - Tahmin Fark | H5: % Değişim | I5: Temmuz Tahmin | J5: Ağustos Tahmin | K5: Eylül Tahmin | L5: Bütçe - Tahmin Fark | M5: % Değişim | N5: Temmuz Tahmin | O5: Ağustos Tahmin | P5: Eylül Tahmin | Q5: Bütçe - Tahmin Fark | R5: % Değişim | S5: Temmuz Tahmin | T5: Ağustos Tahmin | U5: Eylül Tahmin | V5: Bütçe - Tahmin Fark | W5: % Değişim
C6: Toplam | D6: =SUM(D7:D14) -> 776064.95 | E6: =SUM(E7:E14) -> 757192.3 | F6: =SUM(F7:F14) -> 754778.04 | G6: =SUM(G7:G14) -> -85366.678 | H6: =(F6/(F6-G6))-1 -> -0.10160949 | I6: =SUM(I7:I14) -> 151507.62 | J6: =SUM(J7:J14) -> 145586.15 | K6: =SUM(K7:K14) -> 142940.28 | L6: =SUM(L7:L14) -> -20993.178 | M6: =(K6/(K6-L6))-1 -> -0.12805914 | N6: =SUM(N7:N14) -> 106038.39 | O6: =SUM(O7:O14) -> 100861.3 | P6: =SUM(P7:P14) -> 98351.624 | Q6: =SUM(Q7:Q14) -> -14514.79 | R6: =(P6/(P6-Q6))-1 -> -0.12860149 | S6: =SUM(S7:S14) -> 30465.031 | T6: =SUM(T7:T14) -> 22244.032 | U6: =SUM(U7:U14) -> 19292.456 | V6: =SUM(V7:V14) -> -33324.727 | W6: =(U6/(U6-V6))-1 -> -0.63334304
C7: İnci Holding | D7: ='Tahmin Data'!O4/1000 -> 8537.105 | E7: ='Tahmin Data'!Q4/1000 -> 8329.6736 | F7: ='Tahmin Data'!S4/1000 -> 8347.1112 | G7: =F7-'C-Döviz'!AI9/1000 -> -886.13971 | H7: =(F7/(F7-G7))-1 -> -0.095972666 | I7: ='Tahmin Data'!O20/1000 -> 8537.105 | J7: ='Tahmin Data'!Q20/1000 -> 8329.6736 | K7: ='Tahmin Data'!S20/1000 -> 8347.1112 | L7: =K7-'C-Döviz'!AI36/1000 -> -886.13971 | M7: =(K7/(K7-L7))-1 -> -0.095972666 | N7: ='Tahmin Data'!M60/1000 -> 3415.0849 | O7: ='Tahmin Data'!Q60/1000 -> 3225.6411 | P7: ='Tahmin Data'!S60/1000 -> 3247.08 | Q7: =P7-'C-Döviz'!AI139/1000 -> -692.67236 | R7: =(P7/(P7-Q7))-1 -> -0.17581622 | S7: ='Tahmin Data'!O100/1000 -> 3519.337 | T7: ='Tahmin Data'!Q100/1000 -> 3099.383 | U7: ='Tahmin Data'!S100/1000 -> 2980.6565 | V7: =U7-'C-Döviz'!AI215/1000 -> 434.52102 | W7: =(U7/(U7-V7))-1 -> 0.17065903
C8: ISM | D8: ='Tahmin Data'!O6/1000 -> 8341.0386 | E8: ='Tahmin Data'!Q6/1000 -> 7796.0768 | F8: ='Tahmin Data'!S6/1000 -> 7507.5363 | G8: =F8-'C-Döviz'!AI10/1000 -> -1892.1519 | H8: =(F8/(F8-G8))-1 -> -0.20129944 | I8: ='Tahmin Data'!O22/1000 -> 2061.7774 | J8: ='Tahmin Data'!Q22/1000 -> 1933.6858 | K8: ='Tahmin Data'!S22/1000 -> 1728.7069 | L8: =K8-'C-Döviz'!AI37/1000 -> -1010.888 | M8: =(K8/(K8-L8))-1 -> -0.36899178 | N8: ='Tahmin Data'!O62/1000 -> 596.76644 | O8: ='Tahmin Data'!Q62/1000 -> 490.55285 | P8: ='Tahmin Data'!S62/1000 -> 263.00679 | Q8: =P8-'C-Döviz'!AI140/1000 -> -888.05446 | R8: =(P8/(P8-Q8))-1 -> -0.7715093 | S8: ='Tahmin Data'!O102/1000 -> -1203.5408 | T8: ='Tahmin Data'!Q102/1000 -> -1440.0033 | U8: ='Tahmin Data'!S102/1000 -> -1708.7459 | V8: =U8-'C-Döviz'!AI216/1000 -> -2413.2673 | W8: =(U8/(U8-V8))-1 -> -3.4253995
C9: İncitaş | D9: ='Tahmin Data'!O5/1000 -> 13327.053 | E9: ='Tahmin Data'!Q5/1000 -> 12990.151 | F9: ='Tahmin Data'!S5/1000 -> 12844.341 | G9: =F9-'C-Döviz'!AI11/1000 -> -3977.701 | H9: =(F9/(F9-G9))-1 -> -0.23645767 | I9: ='Tahmin Data'!O21/1000 -> 2151.0436 | J9: ='Tahmin Data'!Q21/1000 -> 2081.2902 | K9: ='Tahmin Data'!S21/1000 -> 2050.8149 | L9: =K9-'C-Döviz'!AI38/1000 -> -1120.6245 | M9: =(K9/(K9-L9))-1 -> -0.35334886 | N9: ='Tahmin Data'!O61/1000 -> 455.3784 | O9: ='Tahmin Data'!Q61/1000 -> 488.72535 | P9: ='Tahmin Data'!S61/1000 -> 473.82975 | Q9: =P9-'C-Döviz'!AI141/1000 -> -358.03084 | R9: =(P9/(P9-Q9))-1 -> -0.43039764 | S9: ='Tahmin Data'!O101/1000 -> -2.7123575 | T9: ='Tahmin Data'!Q101/1000 -> 10.980641 | U9: ='Tahmin Data'!S101/1000 -> 10.583732 | V9: =U9-'C-Döviz'!AI217/1000 -> -146.65484 | W9: =(U9/(U9-V9))-1 -> -0.93268997
C10: İnci GS Yuasa | D10: ='Tahmin Data'!O3/1000 -> 188623.17 | E10: ='Tahmin Data'!Q3/1000 -> 179530.45 | F10: ='Tahmin Data'!S3/1000 -> 175031.2 | G10: =F10-'C-Döviz'!AI12/1000 -> -83460.79 | H10: =(F10/(F10-G10))-1 -> -0.32287573 | I10: ='Tahmin Data'!O19/1000 -> 30932.748 | J10: ='Tahmin Data'!Q19/1000 -> 29215.74 | K10: ='Tahmin Data'!S19/1000 -> 26026.066 | L10: =K10-'C-Döviz'!AI39/1000 -> -26247.099 | M10: =(K10/(K10-L10))-1 -> -0.50211422 | N10: ='Tahmin Data'!O59/1000 -> 10575.876 | O10: ='Tahmin Data'!Q59/1000 -> 9274.5209 | P10: ='Tahmin Data'!S59/1000 -> 6204.1748 | Q10: =P10-'C-Döviz'!AI142/1000 -> -22169.826 | R10: =(P10/(P10-Q10))-1 -> -0.78134297 | S10: ='Tahmin Data'!O99/1000 -> -26431.22 | T10: ='Tahmin Data'!Q99/1000 -> -26769.172 | U10: ='Tahmin Data'!S99/1000 -> -29355.248 | V10: =U10-'C-Döviz'!AI218/1000 -> -29801.069 | W10: =(U10/(U10-V10))-1 -> -66.845311
C11: Yusen İnci Loj. | D11: ='Tahmin Data'!O10/1000 -> 67920.753 | E11: ='Tahmin Data'!Q10/1000 -> 65560.404 | F11: ='Tahmin Data'!S10/1000 -> 66014.098 | G11: =F11-'C-Döviz'!AI13/1000 -> -12653.07 | H11: =(F11/(F11-G11))-1 -> -0.16084309 | I11: ='Tahmin Data'!O26/1000 -> 13230.517 | J11: ='Tahmin Data'!Q26/1000 -> 13039.542 | K11: ='Tahmin Data'!S26/1000 -> 13326.952 | L11: =K11-'C-Döviz'!AI40/1000 -> -1743.4885 | M11: =(K11/(K11-L11))-1 -> -0.11568929 | N11: ='Tahmin Data'!O66/1000 -> 4252.5572 | O11: ='Tahmin Data'!Q66/1000 -> 4416.1308 | P11: ='Tahmin Data'!S66/1000 -> 4791.8744 | Q11: =P11-'C-Döviz'!AI143/1000 -> -545.24383 | R11: =(P11/(P11-Q11))-1 -> -0.10216072 | S11: ='Tahmin Data'!O106/1000 -> 1452.906 | T11: ='Tahmin Data'!Q106/1000 -> 1414.3521 | U11: ='Tahmin Data'!S106/1000 -> 1612.4862 | V11: =U11-'C-Döviz'!AI219/1000 -> 499.63512 | W11: =(U11/(U11-V11))-1 -> 0.44896852
C12: Jantaş | D12: ='Tahmin Data'!O9/1000 -> 138028.08 | E12: ='Tahmin Data'!Q9/1000 -> 134805.53 | F12: ='Tahmin Data'!S9/1000 -> 135924.73 | G12: =F12-'C-Döviz'!AI14/1000 -> 1924.9902 | H12: =(F12/(F12-G12))-1 -> 0.014365627 | I12: ='Tahmin Data'!O25/1000 -> 28313.429 | J12: ='Tahmin Data'!Q25/1000 -> 26203.409 | K12: ='Tahmin Data'!S25/1000 -> 26856.8 | L12: =K12-'C-Döviz'!AI41/1000 -> 4618.3394 | M12: =(K12/(K12-L12))-1 -> 0.20767352 | N12: ='Tahmin Data'!O65/1000 -> 25617.404 | O12: ='Tahmin Data'!Q65/1000 -> 23465.103 | P12: ='Tahmin Data'!S65/1000 -> 24141.524 | Q12: =P12-'C-Döviz'!AI144/1000 -> 2979.1056 | R12: =(P12/(P12-Q12))-1 -> 0.1407734 | S12: ='Tahmin Data'!O105/1000 -> 15040.335 | T12: ='Tahmin Data'!Q105/1000 -> 13183.786 | U12: ='Tahmin Data'!S105/1000 -> 13840.253 | V12: =U12-'C-Döviz'!AI220/1000 -> 3233.2945 | W12: =(U12/(U12-V12))-1 -> 0.30482767
C13: Çelik | D13: ='Tahmin Data'!O8/1000 -> 94646.153 | E13: ='Tahmin Data'!Q8/1000 -> 94582.019 | F13: ='Tahmin Data'!S8/1000 -> 95763.679 | G13: =F13-'C-Döviz'!AI15/1000 -> 9915.8181 | H13: =(F13/(F13-G13))-1 -> 0.11550454 | I13: ='Tahmin Data'!O24/1000 -> 27497.364 | J13: ='Tahmin Data'!Q24/1000 -> 27357.649 | K13: ='Tahmin Data'!S24/1000 -> 27754.871 | L13: =K13-'C-Döviz'!AI42/1000 -> 5992.4757 | M13: =(K13/(K13-L13))-1 -> 0.2753592 | N13: ='Tahmin Data'!O64/1000 -> 25607.473 | O13: ='Tahmin Data'!Q64/1000 -> 25493.943 | P13: ='Tahmin Data'!S64/1000 -> 25763.872 | Q13: =P13-'C-Döviz'!AI145/1000 -> 5623.6209 | R13: =(P13/(P13-Q13))-1 -> 0.27922297 | S13: ='Tahmin Data'!O104/1000 -> 13178.548 | T13: ='Tahmin Data'!Q104/1000 -> 8851.3945 | U13: ='Tahmin Data'!S104/1000 -> 8923.2265 | V13: =U13-'C-Döviz'!AI221/1000 -> -2412.3442 | W13: =(U13/(U13-V13))-1 -> -0.21281189
C14: Alüminyum | D14: ='Tahmin Data'!O7/1000 -> 256641.59 | E14: ='Tahmin Data'!Q7/1000 -> 253598 | F14: ='Tahmin Data'!S7/1000 -> 253345.34 | G14: =F14-'C-Döviz'!AI16/1000 -> 5662.3673 | H14: =(F14/(F14-G14))-1 -> 0.02286135 | I14: ='Tahmin Data'!O23/1000 -> 38783.637 | J14: ='Tahmin Data'!Q23/1000 -> 37425.16 | K14: ='Tahmin Data'!S23/1000 -> 36848.954 | L14: =K14-'C-Döviz'!AI43/1000 -> -595.75293 | M14: =(K14/(K14-L14))-1 -> -0.015910204 | N14: ='Tahmin Data'!O63/1000 -> 35517.853 | O14: ='Tahmin Data'!Q63/1000 -> 34006.684 | P14: ='Tahmin Data'!S63/1000 -> 33466.263 | Q14: =P14-'C-Döviz'!AI146/1000 -> 1536.3116 | R14: =(P14/(P14-Q14))-1 -> 0.048115061 | S14: ='Tahmin Data'!O103/1000 -> 24911.379 | T14: ='Tahmin Data'!Q103/1000 -> 23893.31 | U14: ='Tahmin Data'!S103/1000 -> 22989.244 | V14: =U14-'C-Döviz'!AI222/1000 -> -2718.8422 | W14: =(U14/(U14-V14))-1 -> -0.10575825
D16: Vergi | I16: Operasyonel Nakit | N16: Serbest Nakit
C17: bin Avro
D18: Temmuz Tahmin | E18: Ağustos Tahmin | F18: Eylül Tahmin | G18: Bütçe - Tahmin Fark | H18: % Değişim | I18: Temmuz Tahmin | J18: Ağustos Tahmin | K18: Eylül Tahmin | L18: Bütçe - Tahmin Fark | M18: % Değişim | N18: Temmuz Tahmin | O18: Ağustos Tahmin | P18: Eylül Tahmin | Q18: Bütçe - Tahmin Fark | R18: % Değişim
C19: Toplam | D19: =SUM(D20:D27) -> 11368.66 | E19: =SUM(E20:E27) -> 14457.745 | F19: =SUM(F20:F27) -> 15244.087 | G19: =SUM(G20:G27) -> 6001.7736 | H19: =(F19/(F19-G19))-1 -> 0.64938001 | I19: =SUM(I20:I27) -> 108461.56 | J19: =SUM(J20:J27) -> 96880.475 | K19: =SUM(K20:K27) -> 88358.719 | L19: =SUM(L20:L27) -> -7782.0648 | M19: =(K19/(K19-L19))-1 -> -0.080944469 | N19: =SUM(N20:N27) -> 90736.944 | O19: =SUM(O20:O27) -> 79885.44 | P19: =SUM(P20:P27) -> 70451.485 | Q19: =SUM(Q20:Q27) -> -9408.9875 | R19: =(P19/(P19-Q19))-1 -> -0.11781783
C20: İnci Holding | D20: ='Tahmin Data'!O92/1000 -> 410.74147 | E20: ='Tahmin Data'!Q92/1000 -> 590.843 | F20: ='Tahmin Data'!S92/1000 -> 827.15497 | G20: =F20-('C-Döviz'!AI202/-1000) -> -21.556876 | H20: =(F20/(F20-G20))-1 -> -0.025399524 | I20: ='Tahmin Data'!O140/1000 -> 3252.9798 | J20: ='Tahmin Data'!Q140/1000 -> 2990.0396 | K20: ='Tahmin Data'!S140/1000 -> 2775.1665 | L20: =K20-('C-Döviz'!AI291/1000) -> -454.21833 | M20: =(K20/(K20-L20))-1 -> -0.14065166 | N20: ='Tahmin Data'!O148/1000 -> 3239.5279 | O20: ='Tahmin Data'!Q148/1000 -> 2976.9009 | P20: ='Tahmin Data'!S148/1000 -> 2762.1044 | Q20: =P20-('C-Döviz'!AI304/1000) -> -452.35212 | R20: =(P20/(P20-Q20))-1 -> -0.14072429
C21: ISM | D21: ='Tahmin Data'!O94/1000 -> 3.3571263 | E21: ='Tahmin Data'!Q94/1000 -> 1.1061965 | F21: ='Tahmin Data'!S94/1000 -> 0.48283212 | G21: =F21-('C-Döviz'!AI203/-1000) -> -175.64752 | H21: =(F21/(F21-G21))-1 -> -0.99725867 | I21: ='Tahmin Data'!O142/1000 -> 771.42032 | J21: ='Tahmin Data'!Q142/1000 -> 634.70742 | K21: ='Tahmin Data'!S142/1000 -> 513.20468 | L21: =K21-('C-Döviz'!AI292/1000) -> -690.11326 | M21: =(K21/(K21-L21))-1 -> -0.57350866 | N21: ='Tahmin Data'!O150/1000 -> 186.51448 | O21: ='Tahmin Data'!Q150/1000 -> 54.325379 | P21: ='Tahmin Data'!S150/1000 -> -69.172497 | Q21: =P21-('C-Döviz'!AI305/1000) -> -645.37776 | R21: =(P21/(P21-Q21))-1 -> -1.1200484
C22: İncitaş | D22: ='Tahmin Data'!O93/1000 -> 0.0019830577 | E22: ='Tahmin Data'!Q93/1000 -> 0.002313139 | F22: ='Tahmin Data'!S93/1000 -> 8.4467769 | G22: =F22-('C-Döviz'!AI204/-1000) -> -93.874758 | H22: =(F22/(F22-G22))-1 -> -0.91744869 | I22: ='Tahmin Data'!O141/1000 -> 855.04792 | J22: ='Tahmin Data'!Q141/1000 -> 843.21919 | K22: ='Tahmin Data'!S141/1000 -> 967.11505 | L22: =K22-('C-Döviz'!AI293/1000) -> 1282.0655 | M22: =-(K22/(K22-L22)) -> 3.0706893 | N22: ='Tahmin Data'!O149/1000 -> 855.04792 | O22: ='Tahmin Data'!Q149/1000 -> 843.21919 | P22: ='Tahmin Data'!S149/1000 -> 967.11505 | Q22: =P22-('C-Döviz'!AI306/1000) -> 1282.0655 | R22: =-(P22/(P22-Q22)) -> 3.0706893
C23: İnci GS Yuasa | D23: ='Tahmin Data'!O91/1000 -> 0 | E23: ='Tahmin Data'!Q91/1000 -> 0 | F23: ='Tahmin Data'!S91/1000 -> 0 | G23: =F23-('C-Döviz'!AI205/-1000) -> 0 | H23: 0 | I23: ='Tahmin Data'!O139/1000 -> 15056.206 | J23: ='Tahmin Data'!Q139/1000 -> 13354.778 | K23: ='Tahmin Data'!S139/1000 -> 8648.9199 | L23: =K23-('C-Döviz'!AI294/1000) -> -12656.813 | M23: =(K23/(K23-L23))-1 -> -0.59405669 | N23: ='Tahmin Data'!O147/1000 -> 9583.6562 | O23: ='Tahmin Data'!Q147/1000 -> 8095.7402 | P23: ='Tahmin Data'!S147/1000 -> 3428.1354 | Q23: =P23-('C-Döviz'!AI307/1000) -> -11707.11 | R23: =-(P23/(P23-Q23)) -> -0.22650015
C24: Yusen İnci Loj. | D24: ='Tahmin Data'!O98/1000 -> 360.08078 | E24: ='Tahmin Data'!Q98/1000 -> 389.20972 | F24: ='Tahmin Data'!S98/1000 -> 349.57753 | G24: =F24-('C-Döviz'!AI206/-1000) -> -164.33969 | H24: =(F24/(F24-G24))-1 -> -0.31977853 | I24: ='Tahmin Data'!O146/1000 -> 5383.0295 | J24: ='Tahmin Data'!Q146/1000 -> 5017.2294 | K24: ='Tahmin Data'!S146/1000 -> 5842.0166 | L24: =K24-('C-Döviz'!AI295/1000) -> 366.90172 | M24: =(K24/(K24-L24))-1 -> 0.067012606 | N24: ='Tahmin Data'!O154/1000 -> 4147.0189 | O24: ='Tahmin Data'!Q154/1000 -> 3768.7039 | P24: ='Tahmin Data'!S154/1000 -> 3840.7679 | Q24: =P24-('C-Döviz'!AI308/1000) -> -741.44074 | R24: =(P24/(P24-Q24))-1 -> -0.1618086
C25: Jantaş | D25: ='Tahmin Data'!O97/1000 -> 4700.8966 | E25: ='Tahmin Data'!Q97/1000 -> 4211.0715 | F25: ='Tahmin Data'!S97/1000 -> 4273.66 | G25: =F25-('C-Döviz'!AI207/-1000) -> 1280.7592 | H25: =(F25/(F25-G25))-1 -> 0.42793238 | I25: ='Tahmin Data'!O145/1000 -> 20934.517 | J25: ='Tahmin Data'!Q145/1000 -> 18760.219 | K25: ='Tahmin Data'!S145/1000 -> 16915.992 | L25: =K25-('C-Döviz'!AI296/1000) -> 1325.0498 | M25: =(K25/(K25-L25))-1 -> 0.084988437 | N25: ='Tahmin Data'!O153/1000 -> 17535.581 | O25: ='Tahmin Data'!Q153/1000 -> 15333.093 | P25: ='Tahmin Data'!S153/1000 -> 13489.001 | Q25: =P25-('C-Döviz'!AI309/1000) -> 768.07446 | R25: =(P25/(P25-Q25))-1 -> 0.060378815
C26: Çelik | D26: ='Tahmin Data'!O96/1000 -> 4677.6054 | E26: ='Tahmin Data'!Q96/1000 -> 8383.4498 | F26: ='Tahmin Data'!S96/1000 -> 8408.4782 | G26: =F26-('C-Döviz'!AI208/-1000) -> 3070.5852 | H26: =(F26/(F26-G26))-1 -> 0.57524292 | I26: ='Tahmin Data'!O144/1000 -> 28253.003 | J26: ='Tahmin Data'!Q144/1000 -> 24170.708 | K26: ='Tahmin Data'!S144/1000 -> 24930.27 | L26: =K26-('C-Döviz'!AI297/1000) -> 3374.7711 | M26: =(K26/(K26-L26))-1 -> 0.15656196 | N26: ='Tahmin Data'!O152/1000 -> 25117.016 | O26: ='Tahmin Data'!Q152/1000 -> 21586.653 | P26: ='Tahmin Data'!S152/1000 -> 21850.27 | Q26: =P26-('C-Döviz'!AI310/1000) -> 3381.7711 | R26: =(P26/(P26-Q26))-1 -> 0.18311023
C27: Alüminyum | D27: ='Tahmin Data'!O95/1000 -> 1215.9765 | E27: ='Tahmin Data'!Q95/1000 -> 882.0623 | F27: ='Tahmin Data'!S95/1000 -> 1376.2866 | G27: =F27-('C-Döviz'!AI209/-1000) -> 2105.8481 | H27: =(F27/(F27-G27))-1 -> -2.8864576 | I27: ='Tahmin Data'!O143/1000 -> 33955.352 | J27: ='Tahmin Data'!Q143/1000 -> 31109.575 | K27: ='Tahmin Data'!S143/1000 -> 27766.035 | L27: =K27-('C-Döviz'!AI298/1000) -> -329.70785 | M27: =(K27/(K27-L27))-1 -> -0.011735154 | N27: ='Tahmin Data'!O151/1000 -> 30072.581 | O27: ='Tahmin Data'!Q151/1000 -> 27226.805 | P27: ='Tahmin Data'!S151/1000 -> 24183.265 | Q27: =P27-('C-Döviz'!AI311/1000) -> -1294.6178 | R27: =(P27/(P27-Q27))-1 -> -0.050813399
D30: Faaliyet Giderleri Marjı | H30: Brüt Kar Marjı | L30: EBITDA Marjı
C31: bin Avro
D32: Temmuz Tahmin | E32: Ağustos Tahmin | F32: Eylül Tahmin | G32: Bütçe - Tahmin Fark | H32: Temmuz Tahmin | I32: Ağustos Tahmin | J32: Eylül Tahmin | K32: Bütçe - Tahmin Fark | L32: Temmuz Tahmin | M32: Ağustos Tahmin | N32: Eylül Tahmin | O32: Bütçe - Tahmin Fark
C34: İnci Holding | D34: ='Tahmin Data'!O28/1000/D7*-1 -> 0.60682418 | E34: ='Tahmin Data'!Q28/1000/E7*-1 -> 0.61866796 | F34: ='Tahmin Data'!S28/1000/F7*-1 -> 0.61690877 | G34: =-(F34-'C-Döviz'!AI102) -> -0.037829428 | H34: =I7/D7 -> 1 | I34: =J7/E7 -> 1 | J34: =K7/F7 -> 1 | K34: =J34-'C-Döviz'!AI79 -> 0 | L34: =N7/D7 -> 0.40002846 | M34: =O7/E7 -> 0.387247 | N34: =P7/F7 -> 0.38900644 | O34: =N34-'C-Döviz'!AI150 -> -0.037685351
C35: ISM | D35: ='Tahmin Data'!O30/1000/D8*-1 -> 0.19565259 | E35: ='Tahmin Data'!Q30/1000/E8*-1 -> 0.20575323 | F35: ='Tahmin Data'!S30/1000/F8*-1 -> 0.21588734 | G35: =-(F35-'C-Döviz'!AI103) -> -0.025050889 | H35: =I8/D8 -> 0.24718473 | I35: =J8/E8 -> 0.24803319 | J35: =K8/F8 -> 0.23026287 | K35: =J35-'C-Döviz'!AI80 -> -0.061193054 | L35: =N8/D8 -> 0.071545819 | M35: =O8/E8 -> 0.06292304 | N35: =P8/F8 -> 0.03503237 | O35: =N35-'C-Döviz'!AI151 -> -0.087425016
C36: İncitaş | D36: ='Tahmin Data'!O29/1000/D9*-1 -> 0.12764512 | E36: ='Tahmin Data'!Q29/1000/E9*-1 -> 0.12310905 | F36: ='Tahmin Data'!S29/1000/F9*-1 -> 0.12329411 | G36: =-(F36-'C-Döviz'!AI104) -> 0.016620069 | H36: =I9/D9 -> 0.1614043 | I36: =J9/E9 -> 0.16022063 | J36: =K9/F9 -> 0.1596668 | K36: =J36-'C-Döviz'!AI81 -> -0.028861993 | L36: =N9/D9 -> 0.034169475 | M36: =O9/E9 -> 0.037622762 | N36: =P9/F9 -> 0.036890156 | O36: =N36-'C-Döviz'!AI152 -> -0.012560474
C37: İnci GS Yuasa | D37: ='Tahmin Data'!O27/1000/D10*-1 -> 0.1217235 | E37: ='Tahmin Data'!Q27/1000/E10*-1 -> 0.12482421 | F37: ='Tahmin Data'!S27/1000/F10*-1 -> 0.12744526 | G37: =-(F37-'C-Döviz'!AI105) -> -0.024454444 | H37: =I10/D10 -> 0.16399231 | I37: =J10/E10 -> 0.16273418 | J37: =K10/F10 -> 0.14869387 | K37: =J37-'C-Döviz'!AI82 -> -0.053529673 | L37: =N10/D10 -> 0.056068805 | M37: =O10/E10 -> 0.051659877 | N37: =P10/F10 -> 0.035446108 | O37: =N37-'C-Döviz'!AI153 -> -0.07432132
C38: Yusen İnci Loj. | D38: ='Tahmin Data'!O34/1000/D11*-1 -> 0.16245588 | E38: ='Tahmin Data'!Q34/1000/E11*-1 -> 0.16333987 | F38: ='Tahmin Data'!S34/1000/F11*-1 -> 0.16193424 | G38: =-(F38-'C-Döviz'!AI106) -> -0.013974318 | H38: =I11/D11 -> 0.19479344 | I38: =J11/E11 -> 0.19889355 | J38: =K11/F11 -> 0.20188039 | K38: =J38-'C-Döviz'!AI83 -> 0.010308217 | L38: =N11/D11 -> 0.062610571 | M38: =O11/E11 -> 0.067359724 | N38: =P11/F11 -> 0.072588652 | O38: =N38-'C-Döviz'!AI154 -> 0.0047443616
C39: Jantaş | D39: ='Tahmin Data'!O33/1000/D12*-1 -> 0.05763275 | E39: ='Tahmin Data'!Q33/1000/E12*-1 -> 0.059032185 | F39: ='Tahmin Data'!S33/1000/F12*-1 -> 0.058640818 | G39: =-(F39-'C-Döviz'!AI107) -> 0.0044809718 | H39: =I12/D12 -> 0.20512803 | I39: =J12/E12 -> 0.19437934 | J39: =K12/F12 -> 0.19758583 | K39: =J39-'C-Döviz'!AI84 -> 0.031626843 | L39: =N12/D12 -> 0.18559559 | M39: =O12/E12 -> 0.17406633 | N39: =P12/F12 -> 0.17760951 | O39: =N39-'C-Döviz'!AI155 -> 0.019680703
C40: Çelik | D40: ='Tahmin Data'!O32/1000/D13*-1 -> 0.052245571 | E40: ='Tahmin Data'!Q32/1000/E13*-1 -> 0.051818682 | F40: ='Tahmin Data'!S32/1000/F13*-1 -> 0.052249482 | G40: =-(F40-'C-Döviz'!AI108) -> 0.0033660611 | H40: =I13/D13 -> 0.29052807 | I40: =J13/E13 -> 0.28924789 | J40: =K13/F13 -> 0.2898267 | K40: =J40-'C-Döviz'!AI85 -> 0.036327135 | L40: =N13/D13 -> 0.27056011 | M40: =O13/E13 -> 0.26954323 | N40: =P13/F13 -> 0.26903595 | O40: =N40-'C-Döviz'!AI156 -> 0.034431951
C41: Alüminyum | D41: ='Tahmin Data'!O31/1000/D14*-1 -> 0.04436207 | E41: ='Tahmin Data'!Q31/1000/E14*-1 -> 0.045930348 | F41: ='Tahmin Data'!S31/1000/F14*-1 -> 0.046085893 | G41: =-(F41-'C-Döviz'!AI109) -> -0.0049364307 | H41: =I14/D14 -> 0.15111984 | I41: =J14/E14 -> 0.14757671 | J41: =K14/F14 -> 0.1454495 | K41: =J41-'C-Döviz'!AI86 -> -0.0057304764 | L41: =N14/D14 -> 0.13839476 | M41: =O14/E14 -> 0.13409682 | N41: =P14/F14 -> 0.13209741 | O41: =N41-'C-Döviz'!AI157 -> 0.0031828087
D43: Net Kar Marjı | H43: Operasyonel Nakit Marjı | L43: Serbest Nakit Marjı
C44: bin Avro
D45: Temmuz Tahmin | E45: Ağustos Tahmin | F45: Eylül Tahmin | G45: Bütçe - Tahmin Fark | H45: Temmuz Tahmin | I45: Ağustos Tahmin | J45: Eylül Tahmin | K45: Bütçe - Tahmin Fark | L45: Temmuz Tahmin | M45: Ağustos Tahmin | N45: Eylül Tahmin | O45: Bütçe - Tahmin Fark
C47: İnci Holding | D47: =S7/D7 -> 0.4122401 | E47: =T7/E7 -> 0.37208938 | F47: =U7/F7 -> 0.3570884 | G47: =F47-'C-Döviz'!AI226 -> 0.081331184 | H47: =I20/D7 -> 0.38104015 | I47: =J20/E7 -> 0.35896239 | J47: =K20/F7 -> 0.3324703 | K47: =J47-('C-Döviz'!AI291/'C-Döviz'!AI9) -> -0.0172857 | L47: =N20/D7 -> 0.37946445 | M47: =O20/E7 -> 0.35738506 | N47: =P20/F7 -> 0.33090543 | O47: =N47-'C-Döviz'!AI304/'C-Döviz'!AI9 -> -0.017233765
C48: ISM | D48: =S8/D8 -> -0.14429149 | E48: =T8/E8 -> -0.18470871 | F48: =U8/F8 -> -0.22760408 | G48: =F48-'C-Döviz'!AI227 -> -0.30255565 | H48: =I21/D8 -> 0.092484924 | I48: =J21/E8 -> 0.081413696 | J48: =K21/F8 -> 0.068358601 | K48: =J48-('C-Döviz'!AI292/'C-Döviz'!AI10) -> -0.059658191 | L48: =N21/D8 -> 0.022361062 | M48: =O21/E8 -> 0.0069682972 | N48: =P21/F8 -> -0.0092137413 | O48: =N48-'C-Döviz'!AI305/'C-Döviz'!AI10 -> -0.070514207
...

Sheet A -Döviz
A1: ='A-TRY'!A1 -> EYLÜL | B1: OCAK | E1: ŞUBAT | H1: MART | K1: NİSAN | N1: MAYIS | Q1: HAZİRAN | T1: TEMMUZ | W1: AĞUSTOS | Z1: EYLÜL | AC1: EKİM | AF1: KASIM | AI1: ARALIK
B2: Budget | C2: Actual | E2: Budget | F2: Actual | H2: Budget | I2: Actual | K2: Budget | L2: Actual | N2: Budget | O2: Actual | Q2: Budget | R2: Actual | T2: Budget | U2: Actual | W2: Budget | X2: Actual | Z2: Budget | AA2: Actual | AC2: Budget | AD2: Actual | AF2: Budget | AG2: Actual | AI2: Budget | AJ2: Actual | AL2: Difference | AM2: Variance % | AO2: Budget | AP2: Actual
A3: Eur Kapanış | B3: ='Bütçe aylık-TL'!$B$2 -> 37.515625 | C3: ='gerç aylık-tl'!$B$2 -> 37.1844 | E3: ='Bütçe aylık-TL'!$C$2 -> 38.28125 | F3: ='gerç aylık-tl'!$C$2 -> 38.104 | H3: ='Bütçe aylık-TL'!$D$2 -> 39.046875 | I3: ='gerç aylık-tl'!$D$2 -> 40.7019 | K3: ='Bütçe aylık-TL'!$E$2 -> 39.8125 | L3: ='gerç aylık-tl'!$E$2 -> 43.6858 | N3: ='Bütçe aylık-TL'!$F$2 -> 40.578125 | O3: ='gerç aylık-tl'!$F$2 -> 44.2706 | Q3: ='Bütçe aylık-TL'!$G$2 -> 41.34375 | R3: ='gerç aylık-tl'!$G$2 -> 46.5526 | T3: ='Bütçe aylık-TL'!$H$2 -> 42.109375 | U3: ='gerç aylık-tl'!$H$2 -> 46.7684 | W3: ='Bütçe aylık-TL'!$I$2 -> 42.875 | X3: ='gerç aylık-tl'!$I$2 -> 47.7841 | Z3: ='Bütçe aylık-TL'!$J$2 -> 43.640625 | AA3: ='gerç aylık-tl'!$J$2 -> 48.6479 | AC3: ='Bütçe aylık-TL'!$K$2 -> 44.40625 | AD3: ='gerç aylık-tl'!$K$2 -> #DIV/0! | AF3: ='Bütçe aylık-TL'!$L$2 -> 45.171875 | AG3: ='gerç aylık-tl'!$L$2 -> #DIV/0! | AI3: ='Bütçe aylık-TL'!$M$2 -> 45.9375 | AJ3: ='gerç aylık-tl'!$M$2 -> #DIV/0! | AL3: =AP3-AO3 -> 5.007275 | AM3: =AP3/AO3-1 -> 0.11473885 | AO3: =IF($A$1=$B$1,B3,IF($A$1=$E$1,E3,IF($A$1=$H$1,H3,IF($A$1=$K$1,K3,IF($A$1=$N$1,N3,IF($A$1=$Q$1,Q3,IF($A$1=$T$1,T3,IF($A$1=$W$1,W3,IF($A$1=$Z$1,Z3,IF($A$1=$AC$1,AC3,IF($A$1=$AF$1,AF3,IF($A$1=$AI$1,AI3)))))))))))) -> 43.640625 | AP3: =IF($A$1=$B$1,C3,IF($A$1=$E$1,F3,IF($A$1=$H$1,I3,IF($A$1=$K$1,L3,IF($A$1=$N$1,O3,IF($A$1=$Q$1,R3,IF($A$1=$T$1,U3,IF($A$1=$W$1,X3,IF($A$1=$Z$1,AA3,IF($A$1=$AC$1,AD3,IF($A$1=$AF$1,AG3,IF($A$1=$AI$1,AJ3)))))))))))) -> 48.6479 | AR3: =250000000/L3 -> 5722683.3
A4: Eur Ortalama | B4: ='Bütçe aylık-TL'!$B$3 -> 37.132812 | C4: ='gerç aylık-tl'!$B$3 -> 36.689261 | E4: ='Bütçe aylık-TL'!$C$3 -> 37.898438 | F4: ='gerç aylık-tl'!$C$3 -> 37.577707 | H4: ='Bütçe aylık-TL'!$D$3 -> 38.664062 | I4: ='gerç aylık-tl'!$D$3 -> 39.849871 | K4: ='Bütçe aylık-TL'!$E$3 -> 39.429688 | L4: ='gerç aylık-tl'!$E$3 -> 42.673177 | N4: ='Bütçe aylık-TL'!$F$3 -> 40.195312 | O4: ='gerç aylık-tl'!$F$3 -> 43.629358 | Q4: ='Bütçe aylık-TL'!$G$3 -> 40.960938 | R4: ='gerç aylık-tl'!$G$3 -> 45.22721 | T4: ='Bütçe aylık-TL'!$H$3 -> 41.726562 | U4: ='gerç aylık-tl'!$H$3 -> 46.914206 | W4: ='Bütçe aylık-TL'!$I$3 -> 42.492188 | X4: ='gerç aylık-tl'!$I$3 -> 47.302506 | Z4: ='Bütçe aylık-TL'!$J$3 -> 43.257812 | AA4: ='gerç aylık-tl'!$J$3 -> 48.33795 | AC4: ='Bütçe aylık-TL'!$K$3 -> 44.023438 | AD4: ='gerç aylık-tl'!$K$3 -> #DIV/0! | AF4: ='Bütçe aylık-TL'!$L$3 -> 44.789062 | AG4: ='gerç aylık-tl'!$L$3 -> #DIV/0! | AI4: ='Bütçe aylık-TL'!$M$3 -> 45.554688 | AJ4: ='gerç aylık-tl'!$M$3 -> #DIV/0! | AL4: =AP4-AO4 -> 5.0801375 | AM4: =AP4/AO4-1 -> 0.11743861 | AO4: =IF($A$1=$B$1,B4,IF($A$1=$E$1,E4,IF($A$1=$H$1,H4,IF($A$1=$K$1,K4,IF($A$1=$N$1,N4,IF($A$1=$Q$1,Q4,IF($A$1=$T$1,T4,IF($A$1=$W$1,W4,IF($A$1=$Z$1,Z4,IF($A$1=$AC$1,AC4,IF($A$1=$AF$1,AF4,IF($A$1=$AI$1,AI4)))))))))))) -> 43.257812 | AP4: =IF($A$1=$B$1,C4,IF($A$1=$E$1,F4,IF($A$1=$H$1,I4,IF($A$1=$K$1,L4,IF($A$1=$N$1,O4,IF($A$1=$Q$1,R4,IF($A$1=$T$1,U4,IF($A$1=$W$1,X4,IF($A$1=$Z$1,AA4,IF($A$1=$AC$1,AD4,IF($A$1=$AF$1,AG4,IF($A$1=$AI$1,AJ4)))))))))))) -> 48.33795
