Workbook
Name \A: #REF!
Name \B: #REF!
Name \C: #REF!
Name \D: #REF!
Name \E: #REF!
Name \F: #REF!
Name \G: #REF!
Name \H: #REF!
Name \I: #REF!
Name \J: #REF!
Name \P: #REF!
Name \Q: #REF!
Name \R: #REF!
Name \S: #REF!
Name \X: #REF!
Name \Z: #REF!
Name _1___0Yazdırma_Al: #REF!
Name _1_0Yazdırma_Al: #REF!
Name _108CROMO: #REF!
Name _15___0Yazdırma_Al: #REF!
Name _16___0Yazdırma_Al: #REF!
Name _2____Yazdırma_Al: #REF!
Name _2Yazdırma_Al: #REF!
Name _4_0Yazdırma_Al: #REF!
Name _5_0Yazdırma_Al: #REF!
Name _6Yazdırma_Al: #REF!
Name _9._Analysis_of_net_debt: #REF!
Name _ANG1: #REF!
Name _ANG2: #REF!
Name _ANG3: #REF!
Name _ANG4: #REF!
Name _c: #REF!
Name _DAT1: #REF!
Name _DAT11: #REF!
Name _DAT3: #REF!
Name _DAT4: #REF!
Name _DAT5: #REF!
Name _DAT9: #REF!
Name _pan1: #REF!
Name _par1: #REF!
Name _PY1: #REF!
Name _PY2: #REF!
Name _tab3: #REF!
Name _Typ7: "Cost Centre"
Name _Typ8: "Expense/Income"
Name a: {"Werkdp_excl",#N/A,FALSE,"WERKdp"}
Name AAA: #REF!
Name aaaaaa: #REF!
Name Abweichung: #REF!
Name ACCCODE: #REF!
Name ACCCODE2: #REF!
Name actual: #REF!
Name ali: #REF!
Name ALUMINUM: #REF!
Name AMG: #REF!
Name ANGKEM1: #REF!
Name ANGKEM11: #REF!
Name ANGKEM12: #REF!
Name ANGKEM13: #REF!
Name ANGKEM14: #REF!

Sheet _com.sap.ip.bi.xl.hiddensheet

Sheet Finansal Raporlama AY
C3: AYLIK
C4: bin Avro | D4: Ciro | G4: Brüt Kar | J4: EBITDA | M4: Net Kar
D5: Gerçekleşme | E5: Bütçe - Gerçekleşme Fark | F5: % Değişim | G5: Gerçekleşme | H5: Bütçe - Gerçekleşme Fark | I5: % Değişim | J5: Gerçekleşme | K5: Bütçe - Gerçekleşme Fark | L5: % Değişim | M5: Gerçekleşme | N5: Bütçe - Gerçekleşme Fark | O5: % Değişim
C6: Toplam | D6: =SUM(D7:D14) | E6: =SUM(E7:E14) | F6: =(D6/(D6-E6))-1 | G6: =SUM(G7:G14) | H6: =SUM(H7:H14) | I6: =(G6/(G6-H6))-1 | J6: =SUM(J7:J14) | K6: =SUM(K7:K14) | L6: =(J6/(J6-K6))-1 | M6: =SUM(M7:M14) | N6: =SUM(N7:N14) | O6: =(M6/(M6-N6))-1
C7: İnci Holding | D7: ='A -Döviz'!AD9/1000 | E7: =('A -Döviz'!AD9-'A -Döviz'!AC9)/1000 | F7: =(D7/(D7-E7))-1 | G7: =('A -Döviz'!AD36)/1000 | H7: =('A -Döviz'!AD36-'A -Döviz'!AC36)/1000 | I7: =(G7/(G7-H7))-1 | J7: ='A -Döviz'!AD139/1000 | K7: =('A -Döviz'!AD139-'A -Döviz'!AC139)/1000 | L7: =(J7/(J7-K7))-1 | M7: ='A -Döviz'!AD215/1000 | N7: =('A -Döviz'!AD215-'A -Döviz'!AC215)/1000 | O7: =(M7/(M7-N7))-1
C8: ISM | D8: ='A -Döviz'!AD10/1000 | E8: =('A -Döviz'!AD10-'A -Döviz'!AC10)/1000 | F8: =(D8/(D8-E8))-1 | G8: =('A -Döviz'!AD37)/1000 | H8: =('A -Döviz'!AD37-'A -Döviz'!AC37)/1000 | I8: =(G8/(G8-H8))-1 | J8: ='A -Döviz'!AD140/1000 | K8: =('A -Döviz'!AD140-'A -Döviz'!AC140)/1000 | L8: =((J8/(J8-K8))-1) | M8: ='A -Döviz'!AD216/1000 | N8: =('A -Döviz'!AD216-'A -Döviz'!AC216)/1000 | O8: =((M8/(M8-N8))-1)
C9: İncitaş | D9: ='A -Döviz'!AD11/1000 | E9: =('A -Döviz'!AD11-'A -Döviz'!AC11)/1000 | F9: =(D9/(D9-E9))-1 | G9: =('A -Döviz'!AD38)/1000 | H9: =('A -Döviz'!AD38-'A -Döviz'!AC38)/1000 | I9: =(G9/(G9-H9))-1 | J9: ='A -Döviz'!AD141/1000 | K9: =('A -Döviz'!AD141-'A -Döviz'!AC141)/1000 | L9: =((J9/(J9-K9))-1) | M9: ='A -Döviz'!AD217/1000 | N9: =('A -Döviz'!AD217-'A -Döviz'!AC217)/1000 | O9: =((M9/(M9-N9))-1)
C10: İnci GS Yuasa | D10: ='A -Döviz'!AD12/1000 | E10: =('A -Döviz'!AD12-'A -Döviz'!AC12)/1000 | F10: =(D10/(D10-E10))-1 | G10: =('A -Döviz'!AD39)/1000 | H10: =('A -Döviz'!AD39-'A -Döviz'!AC39)/1000 | I10: =(G10/(G10-H10))-1 | J10: ='A -Döviz'!AD142/1000 | K10: =('A -Döviz'!AD142-'A -Döviz'!AC142)/1000 | L10: =(J10/(J10-K10))-1 | M10: ='A -Döviz'!AD218/1000 | N10: =('A -Döviz'!AD218-'A -Döviz'!AC218)/1000 | O10: =((M10/(M10-N10))-1)
C11: Yusen İnci Loj. | D11: ='A -Döviz'!AD13/1000 | E11: =('A -Döviz'!AD13-'A -Döviz'!AC13)/1000 | F11: =(D11/(D11-E11))-1 | G11: =('A -Döviz'!AD40)/1000 | H11: =('A -Döviz'!AD40-'A -Döviz'!AC40)/1000 | I11: =(G11/(G11-H11))-1 | J11: ='A -Döviz'!AD143/1000 | K11: =('A -Döviz'!AD143-'A -Döviz'!AC143)/1000 | L11: =(J11/(J11-K11))-1 | M11: ='A -Döviz'!AD219/1000 | N11: =('A -Döviz'!AD219-'A -Döviz'!AC219)/1000 | O11: =(M11/(M11-N11))-1
C12: Jantaş | D12: ='A -Döviz'!AD14/1000 | E12: =('A -Döviz'!AD14-'A -Döviz'!AC14)/1000 | F12: =(D12/(D12-E12))-1 | G12: =('A -Döviz'!AD41)/1000 | H12: =('A -Döviz'!AD41-'A -Döviz'!AC41)/1000 | I12: =(G12/(G12-H12))-1 | J12: ='A -Döviz'!AD144/1000 | K12: =('A -Döviz'!AD144-'A -Döviz'!AC144)/1000 | L12: =(J12/(J12-K12))-1 | M12: ='A -Döviz'!AD220/1000 | N12: =('A -Döviz'!AD220-'A -Döviz'!AC220)/1000 | O12: =(M12/(M12-N12))-1
C13: Çelik | D13: ='A -Döviz'!AD15/1000 | E13: =('A -Döviz'!AD15-'A -Döviz'!AC15)/1000 | F13: =(D13/(D13-E13))-1 | G13: =('A -Döviz'!AD42)/1000 | H13: =('A -Döviz'!AD42-'A -Döviz'!AC42)/1000 | I13: =(G13/(G13-H13))-1 | J13: ='A -Döviz'!AD145/1000 | K13: =('A -Döviz'!AD145-'A -Döviz'!AC145)/1000 | L13: =(J13/(J13-K13))-1 | M13: ='A -Döviz'!AD221/1000 | N13: =('A -Döviz'!AD221-'A -Döviz'!AC221)/1000 | O13: =(M13/(M13-N13))-1
C14: Alüminyum | D14: ='A -Döviz'!AD16/1000 | E14: =('A -Döviz'!AD16-'A -Döviz'!AC16)/1000 | F14: =(D14/(D14-E14))-1 | G14: =('A -Döviz'!AD43)/1000 | H14: =('A -Döviz'!AD43-'A -Döviz'!AC43)/1000 | I14: =(G14/(G14-H14))-1 | J14: ='A -Döviz'!AD146/1000 | K14: =('A -Döviz'!AD146-'A -Döviz'!AC146)/1000 | L14: =(J14/(J14-K14))-1 | M14: ='A -Döviz'!AD222/1000 | N14: =('A -Döviz'!AD222-'A -Döviz'!AC222)/1000 | O14: =(M14/(M14-N14))-1
C17: bin Avro | D17: Vergi | G17: Operasyonel Nakit | J17: Serbest Nakit | M17: Net Nakit
D18: Gerçekleşme | E18: Bütçe - Gerçekleşme Fark | F18: % Değişim | G18: Gerçekleşme | H18: Bütçe - Gerçekleşme Fark | I18: % Değişim | J18: Gerçekleşme | K18: Bütçe - Gerçekleşme Fark | L18: % Değişim | M18: Gerçekleşme | N18: Bütçe - Gerçekleşme Fark | O18: % Değişim
C19: Toplam | D19: =SUM(D20:D27) | E19: =SUM(E20:E27) | F19: =(D19/(D19-E19)) | G19: =SUM(G20:G27) | H19: =SUM(H20:H27) | I19: =((G19/(G19-H19))-1) | J19: =SUM(J20:J27) | K19: =SUM(K20:K27) | L19: =((J19/(J19-K19))-1) | M19: =SUM(M20:M27) | N19: =SUM(N20:N27) | O19: =(M19/(M19-N19))-1
C20: İnci Holding | D20: ='A -Döviz'!AA202/1000 | E20: =('A -Döviz'!AA202-'A -Döviz'!Z202)/1000 | F20: =-((D20/(D20-E20))-1) | G20: ='A -Döviz'!AA291/1000 | H20: =('A -Döviz'!AA291-'A -Döviz'!Z291)/1000 | I20: =((G20/(G20-H20))-1) | J20: ='A -Döviz'!AA304/1000 | K20: =('A -Döviz'!AA304-'A -Döviz'!Z304)/1000 | L20: =((J20/(J20-K20))-1) | M20: ='A -Döviz'!AA265/1000 | N20: =('A -Döviz'!AA265-'A -Döviz'!Z265)/1000 | O20: =(M20/(M20-N20))-1
C21: ISM | D21: ='A -Döviz'!AA203/1000 | E21: =('A -Döviz'!AA203-'A -Döviz'!Z203)/1000 | F21: =-((D21/(D21-E21))-1) | G21: ='A -Döviz'!AA292/1000 | H21: =('A -Döviz'!AA292-'A -Döviz'!Z292)/1000 | I21: =((G21/(G21-H21))-1) | J21: ='A -Döviz'!AA305/1000 | K21: =('A -Döviz'!AA305-'A -Döviz'!Z305)/1000 | L21: =((J21/(J21-K21))-1) | M21: ='A -Döviz'!AA266/1000 | N21: =('A -Döviz'!AA266-'A -Döviz'!Z266)/1000 | O21: =-((M21/(M21-N21))-1)
C22: İncitaş | D22: ='A -Döviz'!AA204/1000 | E22: =('A -Döviz'!AA204-'A -Döviz'!Z204)/1000 | F22: =-IFERROR((D22/(D22-E22))-1,0) | G22: ='A -Döviz'!AA293/1000 | H22: =('A -Döviz'!AA293-'A -Döviz'!Z293)/1000 | I22: =((G22/(G22-H22))-1) | J22: ='A -Döviz'!AA306/1000 | K22: =('A -Döviz'!AA306-'A -Döviz'!Z306)/1000 | L22: =((J22/(J22-K22))-1) | M22: ='A -Döviz'!AA267/1000 | N22: =('A -Döviz'!AA267-'A -Döviz'!Z267)/1000 | O22: =-((M22/(M22-N22))-1)
C23: İnci GS Yuasa | D23: ='A -Döviz'!AA205/1000 | E23: =('A -Döviz'!AA205-'A -Döviz'!Z205)/1000 | F23: 0 | G23: ='A -Döviz'!AA294/1000 | H23: =('A -Döviz'!AA294-'A -Döviz'!Z294)/1000 | I23: =((G23/(G23-H23))-1) | J23: ='A -Döviz'!AA307/1000 | K23: =('A -Döviz'!AA307-'A -Döviz'!Z307)/1000 | L23: =-((J23/(J23-K23))) | M23: ='A -Döviz'!AA268/1000 | N23: =('A -Döviz'!AA268-'A -Döviz'!Z268)/1000 | O23: =-((M23/(M23-N23))-1)
C24: Yusen İnci Loj. | D24: ='A -Döviz'!AA206/1000 | E24: =('A -Döviz'!AA206-'A -Döviz'!Z206)/1000 | F24: =-((D24/(D24-E24))-1) | G24: ='A -Döviz'!AA295/1000 | H24: =('A -Döviz'!AA295-'A -Döviz'!Z295)/1000 | I24: =(G24/(G24-H24))-1 | J24: ='A -Döviz'!AA308/1000 | K24: =('A -Döviz'!AA308-'A -Döviz'!Z308)/1000 | L24: =(J24/(J24-K24))-1 | M24: ='A -Döviz'!AA269/1000 | N24: =('A -Döviz'!AA269-'A -Döviz'!Z269)/1000 | O24: =(M24/(M24-N24))-1
C25: Jantaş | D25: ='A -Döviz'!AA207/1000 | E25: =('A -Döviz'!AA207-'A -Döviz'!Z207)/1000 | F25: =-((D25/(D25-E25))-1) | G25: ='A -Döviz'!AA296/1000 | H25: =('A -Döviz'!AA296-'A -Döviz'!Z296)/1000 | I25: =((G25/(G25-H25))-1) | J25: ='A -Döviz'!AA309/1000 | K25: =('A -Döviz'!AA309-'A -Döviz'!Z309)/1000 | L25: =((J25/(J25-K25))-1) | M25: ='A -Döviz'!AA270/1000 | N25: =('A -Döviz'!AA270-'A -Döviz'!Z270)/1000 | O25: =(M25/(M25-N25))-1
C26: Çelik | D26: ='A -Döviz'!AA208/1000 | E26: =('A -Döviz'!AA208-'A -Döviz'!Z208)/1000 | F26: =-((D26/(D26-E26))-1) | G26: ='A -Döviz'!AA297/1000 | H26: =('A -Döviz'!AA297-'A -Döviz'!Z297)/1000 | I26: =((G26/(G26-H26))-1) | J26: ='A -Döviz'!AA310/1000 | K26: =('A -Döviz'!AA310-'A -Döviz'!Z310)/1000 | L26: =((J26/(J26-K26))-1) | M26: ='A -Döviz'!AA271/1000 | N26: =('A -Döviz'!AA271-'A -Döviz'!Z271)/1000 | O26: =(M26/(M26-N26))-1
C27: Alüminyum | D27: ='A -Döviz'!AA209/1000 | E27: =('A -Döviz'!AA209-'A -Döviz'!Z209)/1000 | F27: =-((D27/(D27-E27))-1) | G27: ='A -Döviz'!AA298/1000 | H27: =('A -Döviz'!AA298-'A -Döviz'!Z298)/1000 | I27: =((G27/(G27-H27))-1) | J27: ='A -Döviz'!AA311/1000 | K27: =('A -Döviz'!AA311-'A -Döviz'!Z311)/1000 | L27: =((J27/(J27-K27))-1) | M27: ='A -Döviz'!AA272/1000 | N27: =('A -Döviz'!AA272-'A -Döviz'!Z272)/1000 | O27: =(M27/(M27-N27))-1
D30: Faaliyet Giderleri Marjı | F30: Brüt Kar Marjı | H30: EBITDA Marjı | J30: Net Kar Marjı | L30: Operasyonel Nakit Marjı | N30: Serbest Nakit Marjı
D31: Gerçekleşme | E31: Bütçe - Gerçekleşme Fark | F31: Gerçekleşme | G31: Bütçe - Gerçekleşme Fark | H31: Gerçekleşme | I31: Bütçe - Gerçekleşme Fark | J31: Gerçekleşme | K31: Bütçe - Gerçekleşme Fark | L31: Gerçekleşme | M31: Bütçe - Gerçekleşme Fark | N31: Gerçekleşme | O31: Bütçe - Gerçekleşme Fark
C33: İnci Holding | D33: ='A -Döviz'!AA102 | E33: =-('A -Döviz'!AA102-'A -Döviz'!Z102) | F33: ='A -Döviz'!AA79 | G33: ='A -Döviz'!AA79-'A -Döviz'!Z79 | H33: ='A -Döviz'!AA150 | I33: ='A -Döviz'!AA150-'A -Döviz'!Z150 | J33: ='A -Döviz'!AA226 | K33: ='A -Döviz'!AA226-'A -Döviz'!Z226 | L33: ='A -Döviz'!AA291/'A -Döviz'!AA9 | M33: =L33-('A -Döviz'!Z291/'A -Döviz'!Z9) | N33: ='A -Döviz'!AA304/'A -Döviz'!AA9 | O33: =N33-'A -Döviz'!Z304/'A -Döviz'!Z9
C34: ISM | D34: ='A -Döviz'!AA103 | E34: =-('A -Döviz'!AA103-'A -Döviz'!Z103) | F34: ='A -Döviz'!AA80 | G34: ='A -Döviz'!AA80-'A -Döviz'!Z80 | H34: ='A -Döviz'!AA151 | I34: ='A -Döviz'!AA151-'A -Döviz'!Z151 | J34: ='A -Döviz'!AA227 | K34: ='A -Döviz'!AA227-'A -Döviz'!Z227 | L34: ='A -Döviz'!AA292/'A -Döviz'!AA10 | M34: =L34-('A -Döviz'!Z292/'A -Döviz'!Z10) | N34: ='A -Döviz'!AA305/'A -Döviz'!AA10 | O34: =N34-'A -Döviz'!Z305/'A -Döviz'!Z10
C35: İncitaş | D35: ='A -Döviz'!AA104 | E35: =-('A -Döviz'!AA104-'A -Döviz'!Z104) | F35: ='A -Döviz'!AA81 | G35: ='A -Döviz'!AA81-'A -Döviz'!Z81 | H35: ='A -Döviz'!AA152 | I35: ='A -Döviz'!AA152-'A -Döviz'!Z152 | J35: ='A -Döviz'!AA228 | K35: ='A -Döviz'!AA228-'A -Döviz'!Z228 | L35: ='A -Döviz'!AA293/'A -Döviz'!AA11 | M35: =L35-('A -Döviz'!Z293/'A -Döviz'!Z11) | N35: ='A -Döviz'!AA306/'A -Döviz'!AA11 | O35: =N35-'A -Döviz'!Z306/'A -Döviz'!Z11
C36: İnci GS Yuasa | D36: ='A -Döviz'!AA105 | E36: =-('A -Döviz'!AA105-'A -Döviz'!Z105) | F36: ='A -Döviz'!AA82 | G36: ='A -Döviz'!AA82-'A -Döviz'!Z82 | H36: ='A -Döviz'!AA153 | I36: ='A -Döviz'!AA153-'A -Döviz'!Z153 | J36: ='A -Döviz'!AA229 | K36: ='A -Döviz'!AA229-'A -Döviz'!Z229 | L36: ='A -Döviz'!AA294/'A -Döviz'!AA12 | M36: =L36-('A -Döviz'!Z294/'A -Döviz'!Z12) | N36: ='A -Döviz'!AA307/'A -Döviz'!AA12 | O36: =N36-'A -Döviz'!Z307/'A -Döviz'!Z12
C37: Yusen İnci Loj. | D37: ='A -Döviz'!AA106 | E37: =-('A -Döviz'!AA106-'A -Döviz'!Z106) | F37: ='A -Döviz'!AA83 | G37: ='A -Döviz'!AA83-'A -Döviz'!Z83 | H37: ='A -Döviz'!AA154 | I37: ='A -Döviz'!AA154-'A -Döviz'!Z154 | J37: ='A -Döviz'!AA230 | K37: ='A -Döviz'!AA230-'A -Döviz'!Z230 | L37: ='A -Döviz'!AA295/'A -Döviz'!AA13 | M37: =L37-('A -Döviz'!Z295/'A -Döviz'!Z13) | N37: ='A -Döviz'!AA308/'A -Döviz'!AA13 | O37: =N37-'A -Döviz'!Z308/'A -Döviz'!Z13
C38: Jantaş | D38: ='A -Döviz'!AA107 | E38: =-('A -Döviz'!AA107-'A -Döviz'!Z107) | F38: ='A -Döviz'!AA84 | G38: ='A -Döviz'!AA84-'A -Döviz'!Z84 | H38: ='A -Döviz'!AA155 | I38: ='A -Döviz'!AA155-'A -Döviz'!Z155 | J38: ='A -Döviz'!AA231 | K38: ='A -Döviz'!AA231-'A -Döviz'!Z231 | L38: ='A -Döviz'!AA296/'A -Döviz'!AA14 | M38: =L38-('A -Döviz'!Z296/'A -Döviz'!Z14) | N38: ='A -Döviz'!AA309/'A -Döviz'!AA14 | O38: =N38-'A -Döviz'!Z309/'A -Döviz'!Z14
C39: Çelik | D39: ='A -Döviz'!AA108 | E39: =-('A -Döviz'!AA108-'A -Döviz'!Z108) | F39: ='A -Döviz'!AA85 | G39: ='A -Döviz'!AA85-'A -Döviz'!Z85 | H39: ='A -Döviz'!AA156 | I39: ='A -Döviz'!AA156-'A -Döviz'!Z156 | J39: ='A -Döviz'!AA232 | K39: ='A -Döviz'!AA232-'A -Döviz'!Z232 | L39: ='A -Döviz'!AA297/'A -Döviz'!AA15 | M39: =L39-('A -Döviz'!Z297/'A -Döviz'!Z15) | N39: ='A -Döviz'!AA310/'A -Döviz'!AA15 | O39: =N39-'A -Döviz'!Z310/'A -Döviz'!Z15
C40: Alüminyum | D40: ='A -Döviz'!AA109 | E40: =-('A -Döviz'!AA109-'A -Döviz'!Z109) | F40: ='A -Döviz'!AA86 | G40: ='A -Döviz'!AA86-'A -Döviz'!Z86 | H40: ='A -Döviz'!AA157 | I40: ='A -Döviz'!AA157-'A -Döviz'!Z157 | J40: ='A -Döviz'!AA233 | K40: ='A -Döviz'!AA233-'A -Döviz'!Z233 | L40: ='A -Döviz'!AA298/'A -Döviz'!AA16 | M40: =L40-('A -Döviz'!Z298/'A -Döviz'!Z16) | N40: ='A -Döviz'!AA311/'A -Döviz'!AA16 | O40: =N40-'A -Döviz'!Z311/'A -Döviz'!Z16
D64: Ciro | G64: EBITDA | K64: Net Kar
D65: Gerçekleşme | E65: % | G65: Gerçekleşme | I65: % | K65: Gerçekleşme | M65: %
C66: Ciro | D66: 55 | G66: 55 | K66: 55
C67: Adet | D67: 12 | E67: =D67/$D$66 | G67: 12 | H67: =G67/$D$66 | K67: 12 | M67: =K67/$K$66
C68: Fiyat | D68: 9 | E68: =D68/$D$66 | G68: 9 | H68: =G68/$D$66 | K68: 9 | M68: =K68/$K$66
C69: Miks | D69: 8 | E69: =D69/$D$66 | G69: 8 | H69: =G69/$D$66 | K69: 8 | M69: =K69/$K$66
C70: Ham Madde | D70: 5 | E70: =D70/$D$66 | G70: 5 | H70: =G70/$D$66 | K70: 5 | M70: =K70/$K$66
...

Sheet Finansal Raporlama KÜM
C3: KÜMÜLATİF
C4: bin Avro | D4: Ciro | G4: Brüt Kar | J4: EBITDA | M4: Net Kar
D5: Gerçekleşme | E5: Bütçe - Gerçekleşme Fark | F5: % Değişim | G5: Gerçekleşme | H5: Bütçe - Gerçekleşme Fark | I5: % Değişim | J5: Gerçekleşme | K5: Bütçe - Gerçekleşme Fark | L5: % Değişim | M5: Gerçekleşme | N5: Bütçe - Gerçekleşme Fark | O5: % Değişim
C6: Toplam | D6: =SUM(D7:D14) | E6: =SUM(E7:E14) | F6: =(D6/(D6-E6))-1 | G6: =SUM(G7:G14) | H6: =SUM(H7:H14) | I6: =(G6/(G6-H6))-1 | J6: =SUM(J7:J14) | K6: =SUM(K7:K14) | L6: =(J6/(J6-K6))-1 | M6: =SUM(M7:M14) | N6: =SUM(N7:N14) | O6: =(M6/(M6-N6))-1
C7: İnci Holding | D7: ='C-Döviz'!AJ9/1000 | E7: =('C-Döviz'!AJ9-'C-Döviz'!Z9)/1000 | F7: =(D7/(D7-E7))-1 | G7: =('C-Döviz'!AJ36)/1000 | H7: =('C-Döviz'!AJ36-'C-Döviz'!Z36)/1000 | I7: =(G7/(G7-H7))-1 | J7: ='C-Döviz'!AJ139/1000 | K7: =('C-Döviz'!AJ139-'C-Döviz'!Z139)/1000 | L7: =(J7/(J7-K7))-1 | M7: ='C-Döviz'!AJ215/1000 | N7: =('C-Döviz'!AJ215-'C-Döviz'!Z215)/1000 | O7: =(M7/(M7-N7))-1
C8: ISM | D8: ='C-Döviz'!AJ10/1000 | E8: =('C-Döviz'!AJ10-'C-Döviz'!Z10)/1000 | F8: =(D8/(D8-E8))-1 | G8: =('C-Döviz'!AJ37)/1000 | H8: =('C-Döviz'!AJ37-'C-Döviz'!Z37)/1000 | I8: =(G8/(G8-H8))-1 | J8: ='C-Döviz'!AJ140/1000 | K8: =('C-Döviz'!AJ140-'C-Döviz'!Z140)/1000 | L8: =(J8/(J8-K8))-1 | M8: ='C-Döviz'!AJ216/1000 | N8: =('C-Döviz'!AJ216-'C-Döviz'!Z216)/1000 | O8: =(M8/(M8-N8))-1
C9: İncitaş | D9: ='C-Döviz'!AJ11/1000 | E9: =('C-Döviz'!AJ11-'C-Döviz'!Z11)/1000 | F9: =(D9/(D9-E9))-1 | G9: =('C-Döviz'!AJ38)/1000 | H9: =('C-Döviz'!AJ38-'C-Döviz'!Z38)/1000 | I9: =(G9/(G9-H9))-1 | J9: ='C-Döviz'!AJ141/1000 | K9: =('C-Döviz'!AJ141-'C-Döviz'!Z141)/1000 | L9: =((J9/(J9-K9))-1) | M9: ='C-Döviz'!AJ217/1000 | N9: =('C-Döviz'!AJ217-'C-Döviz'!Z217)/1000 | O9: =-((M9/(M9-N9))-1)
C10: İnci GS Yuasa | D10: ='C-Döviz'!AJ12/1000 | E10: =('C-Döviz'!AJ12-'C-Döviz'!Z12)/1000 | F10: =(D10/(D10-E10))-1 | G10: =('C-Döviz'!AJ39)/1000 | H10: =('C-Döviz'!AJ39-'C-Döviz'!Z39)/1000 | I10: =(G10/(G10-H10))-1 | J10: ='C-Döviz'!AJ142/1000 | K10: =('C-Döviz'!AJ142-'C-Döviz'!Z142)/1000 | L10: =(J10/(J10-K10))-1 | M10: ='C-Döviz'!AJ218/1000 | N10: =('C-Döviz'!AJ218-'C-Döviz'!Z218)/1000 | O10: =-((M10/(M10-N10))-1)
C11: Yusen İnci Loj. | D11: ='C-Döviz'!AJ13/1000 | E11: =('C-Döviz'!AJ13-'C-Döviz'!Z13)/1000 | F11: =(D11/(D11-E11))-1 | G11: =('C-Döviz'!AJ40)/1000 | H11: =('C-Döviz'!AJ40-'C-Döviz'!Z40)/1000 | I11: =(G11/(G11-H11))-1 | J11: ='C-Döviz'!AJ143/1000 | K11: =('C-Döviz'!AJ143-'C-Döviz'!Z143)/1000 | L11: =(J11/(J11-K11))-1 | M11: ='C-Döviz'!AJ219/1000 | N11: =('C-Döviz'!AJ219-'C-Döviz'!Z219)/1000 | O11: =(M11/(M11-N11))-1
C12: Jantaş | D12: ='C-Döviz'!AJ14/1000 | E12: =('C-Döviz'!AJ14-'C-Döviz'!Z14)/1000 | F12: =(D12/(D12-E12))-1 | G12: =('C-Döviz'!AJ41)/1000 | H12: =('C-Döviz'!AJ41-'C-Döviz'!Z41)/1000 | I12: =(G12/(G12-H12))-1 | J12: ='C-Döviz'!AJ144/1000 | K12: =('C-Döviz'!AJ144-'C-Döviz'!Z144)/1000 | L12: =(J12/(J12-K12))-1 | M12: ='C-Döviz'!AJ220/1000 | N12: =('C-Döviz'!AJ220-'C-Döviz'!Z220)/1000 | O12: =(M12/(M12-N12))-1
C13: Çelik | D13: ='C-Döviz'!AJ15/1000 | E13: =('C-Döviz'!AJ15-'C-Döviz'!Z15)/1000 | F13: =(D13/(D13-E13))-1 | G13: =('C-Döviz'!AJ42)/1000 | H13: =('C-Döviz'!AJ42-'C-Döviz'!Z42)/1000 | I13: =(G13/(G13-H13))-1 | J13: ='C-Döviz'!AJ145/1000 | K13: =('C-Döviz'!AJ145-'C-Döviz'!Z145)/1000 | L13: =(J13/(J13-K13))-1 | M13: ='C-Döviz'!AJ221/1000 | N13: =('C-Döviz'!AJ221-'C-Döviz'!Z221)/1000 | O13: =(M13/(M13-N13))-1
C14: Alüminyum | D14: ='C-Döviz'!AJ16/1000 | E14: =('C-Döviz'!AJ16-'C-Döviz'!Z16)/1000 | F14: =(D14/(D14-E14))-1 | G14: =('C-Döviz'!AJ43)/1000 | H14: =('C-Döviz'!AJ43-'C-Döviz'!Z43)/1000 | I14: =(G14/(G14-H14))-1 | J14: ='C-Döviz'!AJ146/1000 | K14: =('C-Döviz'!AJ146-'C-Döviz'!Z146)/1000 | L14: =(J14/(J14-K14))-1 | M14: ='C-Döviz'!AJ222/1000 | N14: =('C-Döviz'!AJ222-'C-Döviz'!Z222)/1000 | O14: =(M14/(M14-N14))-1
C17: bin Avro | D17: Vergi | G17: Operasyonel Nakit | J17: Serbest Nakit | M17: Net Nakit
D18: Gerçekleşme | E18: Bütçe - Gerçekleşme Fark | F18: % Değişim | G18: Gerçekleşme | H18: Bütçe - Gerçekleşme Fark | I18: % Değişim | J18: Gerçekleşme | K18: Bütçe - Gerçekleşme Fark | L18: % Değişim | M18: Gerçekleşme | N18: Bütçe - Gerçekleşme Fark | O18: % Değişim
C19: Toplam | D19: =SUM(D20:D27) | E19: =SUM(E20:E27) | F19: =(D19/(D19-E19))-1 | G19: =SUM(G20:G27) | H19: =SUM(H20:H27) | I19: =((G19/(G19-H19))-1) | J19: =SUM(J20:J27) | K19: =SUM(K20:K27) | L19: =((J19/(J19-K19))-1) | M19: =SUM(M20:M27) | N19: =SUM(N20:N27) | O19: =(M19/(M19-N19))-1
C20: İnci Holding | D20: ='C-Döviz'!AJ202/1000 | E20: =('C-Döviz'!AJ202-'C-Döviz'!Z202)/1000 | F20: =-((D20/(D20-E20))-1) | G20: ='C-Döviz'!AJ291/1000 | H20: =('C-Döviz'!AA291-'C-Döviz'!Z291)/1000 | I20: =(G20/(G20-H20))-1 | J20: ='C-Döviz'!AJ304/1000 | K20: =('C-Döviz'!AA304-'C-Döviz'!Z304)/1000 | L20: =(J20/(J20-K20))-1 | M20: ='C-Döviz'!AA265/1000 | N20: =M20-'C-Döviz'!Z265/1000 | O20: =(M20/(M20-N20))-1
C21: ISM | D21: ='C-Döviz'!AJ203/1000 | E21: =('C-Döviz'!AJ203-'C-Döviz'!Z203)/1000 | F21: =-((D21/(D21-E21))-1) | G21: ='C-Döviz'!AJ292/1000 | H21: =('C-Döviz'!AA292-'C-Döviz'!Z292)/1000 | I21: =((G21/(G21-H21))-1) | J21: ='C-Döviz'!AJ305/1000 | K21: =('C-Döviz'!AA305-'C-Döviz'!Z305)/1000 | L21: =((J21/(J21-K21))-1) | M21: ='C-Döviz'!AA266/1000 | N21: =M21-'C-Döviz'!Z266/1000 | O21: =-((M21/(M21-N21))-1)
C22: İncitaş | D22: ='C-Döviz'!AJ204/1000 | E22: =('C-Döviz'!AJ204-'C-Döviz'!Z204)/1000 | F22: =-((D22/(D22-E22))-1) | G22: ='C-Döviz'!AJ293/1000 | H22: =('C-Döviz'!AA293-'C-Döviz'!Z293)/1000 | I22: =-((G22/(G22-H22))-1) | J22: ='C-Döviz'!AJ306/1000 | K22: =('C-Döviz'!AA306-'C-Döviz'!Z306)/1000 | L22: =-((J22/(J22-K22))-1) | M22: ='C-Döviz'!AA267/1000 | N22: =M22-'C-Döviz'!Z267/1000 | O22: =-((M22/(M22-N22))-1)
C23: İnci GS Yuasa | D23: ='C-Döviz'!AJ205/1000 | E23: =('C-Döviz'!AJ205-'C-Döviz'!Z205)/1000 | F23: 0 | G23: ='C-Döviz'!AJ294/1000 | H23: =('C-Döviz'!AA294-'C-Döviz'!Z294)/1000 | I23: =((G23/(G23-H23))-1) | J23: ='C-Döviz'!AJ307/1000 | K23: =('C-Döviz'!AA307-'C-Döviz'!Z307)/1000 | L23: =((J23/(J23-K23))-1) | M23: ='C-Döviz'!AA268/1000 | N23: =M23-'C-Döviz'!Z268/1000 | O23: =-(M23/(M23-N23))-1
C24: Yusen İnci Loj. | D24: ='C-Döviz'!AJ206/1000 | E24: =('C-Döviz'!AJ206-'C-Döviz'!Z206)/1000 | F24: =-((D24/(D24-E24))-1) | G24: ='C-Döviz'!AJ295/1000 | H24: =('C-Döviz'!AA295-'C-Döviz'!Z295)/1000 | I24: =((G24/(G24-H24))-1) | J24: ='C-Döviz'!AJ308/1000 | K24: =('C-Döviz'!AA308-'C-Döviz'!Z308)/1000 | L24: =(J24/(J24-K24))-1 | M24: ='C-Döviz'!AA269/1000 | N24: =M24-'C-Döviz'!Z269/1000 | O24: =(M24/(M24-N24))-1
C25: Jantaş | D25: ='C-Döviz'!AJ207/1000 | E25: =('C-Döviz'!AJ207-'C-Döviz'!Z207)/1000 | F25: =-((D25/(D25-E25))-1) | G25: ='C-Döviz'!AJ296/1000 | H25: =('C-Döviz'!AA296-'C-Döviz'!Z296)/1000 | I25: =((G25/(G25-H25))-1) | J25: ='C-Döviz'!AJ309/1000 | K25: =('C-Döviz'!AA309-'C-Döviz'!Z309)/1000 | L25: =((J25/(J25-K25))-1) | M25: ='C-Döviz'!AA270/1000 | N25: =M25-'C-Döviz'!Z270/1000 | O25: =(M25/(M25-N25))-1
C26: Çelik | D26: ='C-Döviz'!AJ208/1000 | E26: =('C-Döviz'!AJ208-'C-Döviz'!Z208)/1000 | F26: =-((D26/(D26-E26))-1) | G26: ='C-Döviz'!AJ297/1000 | H26: =('C-Döviz'!AA297-'C-Döviz'!Z297)/1000 | I26: =((G26/(G26-H26))-1) | J26: ='C-Döviz'!AJ310/1000 | K26: =('C-Döviz'!AA310-'C-Döviz'!Z310)/1000 | L26: =(J26/(J26-K26))-1 | M26: ='C-Döviz'!AA271/1000 | N26: =M26-'C-Döviz'!Z271/1000 | O26: =(M26/(M26-N26))-1
C27: Alüminyum | D27: ='C-Döviz'!AJ209/1000 | E27: =('C-Döviz'!AJ209-'C-Döviz'!Z209)/1000 | F27: =((D27/(D27-E27))-1) | G27: ='C-Döviz'!AJ298/1000 | H27: =('C-Döviz'!AA298-'C-Döviz'!Z298)/1000 | I27: =((G27/(G27-H27))-1) | J27: ='C-Döviz'!AJ311/1000 | K27: =('C-Döviz'!AA311-'C-Döviz'!Z311)/1000 | L27: =((J27/(J27-K27))-1) | M27: ='C-Döviz'!AA272/1000 | N27: =M27-'C-Döviz'!Z272/1000 | O27: =(M27/(M27-N27))-1
D30: Faaliyet Giderleri Marjı | F30: Brüt Kar Marjı | H30: EBITDA Marjı | J30: Net Kar Marjı | L30: Operasyonel Nakit Marjı | N30: Serbest Nakit Marjı
D31: Gerçekleşme | E31: Bütçe - Gerçekleşme Fark | F31: Gerçekleşme | G31: Bütçe - Gerçekleşme Fark | H31: Gerçekleşme | I31: Bütçe - Gerçekleşme Fark | J31: Gerçekleşme | K31: Bütçe - Gerçekleşme Fark | L31: Gerçekleşme | M31: Bütçe - Gerçekleşme Fark | N31: Gerçekleşme | O31: Bütçe - Gerçekleşme Fark
C33: İnci Holding | D33: ='C-Döviz'!AJ102 | E33: =-('C-Döviz'!AA102-'C-Döviz'!Z102) | F33: ='C-Döviz'!AJ79 | G33: ='C-Döviz'!AA79-'C-Döviz'!Z79 | H33: ='C-Döviz'!AJ150 | I33: ='C-Döviz'!AA150-'C-Döviz'!Z150 | J33: ='C-Döviz'!AJ226 | K33: ='C-Döviz'!AA226-'C-Döviz'!Z226 | L33: ='C-Döviz'!AJ291/'C-Döviz'!AJ9 | M33: =L33-('C-Döviz'!Z291/'C-Döviz'!Z9) | N33: ='C-Döviz'!AJ304/'C-Döviz'!AJ9 | O33: =N33-('C-Döviz'!Z304/'C-Döviz'!Z9)
C34: ISM | D34: ='C-Döviz'!AJ103 | E34: =-('C-Döviz'!AA103-'C-Döviz'!Z103) | F34: ='C-Döviz'!AJ80 | G34: ='C-Döviz'!AA80-'C-Döviz'!Z80 | H34: ='C-Döviz'!AJ151 | I34: ='C-Döviz'!AA151-'C-Döviz'!Z151 | J34: ='C-Döviz'!AJ227 | K34: ='C-Döviz'!AA227-'C-Döviz'!Z227 | L34: ='C-Döviz'!AJ292/'C-Döviz'!AJ10 | M34: =L34-('C-Döviz'!Z292/'C-Döviz'!Z10) | N34: ='C-Döviz'!AJ305/'C-Döviz'!AJ10 | O34: =N34-('C-Döviz'!Z305/'C-Döviz'!Z10)
C35: İncitaş | D35: ='C-Döviz'!AJ104 | E35: =-('C-Döviz'!AA104-'C-Döviz'!Z104) | F35: ='C-Döviz'!AJ81 | G35: ='C-Döviz'!AA81-'C-Döviz'!Z81 | H35: ='C-Döviz'!AJ152 | I35: ='C-Döviz'!AA152-'C-Döviz'!Z152 | J35: ='C-Döviz'!AJ228 | K35: ='C-Döviz'!AA228-'C-Döviz'!Z228 | L35: ='C-Döviz'!AJ293/'C-Döviz'!AJ11 | M35: =L35-('C-Döviz'!Z293/'C-Döviz'!Z11) | N35: ='C-Döviz'!AJ306/'C-Döviz'!AJ11 | O35: =N35-('C-Döviz'!Z306/'C-Döviz'!Z11)
C36: İnci GS Yuasa | D36: ='C-Döviz'!AJ105 | E36: =-('C-Döviz'!AA105-'C-Döviz'!Z105) | F36: ='C-Döviz'!AJ82 | G36: ='C-Döviz'!AA82-'C-Döviz'!Z82 | H36: ='C-Döviz'!AJ153 | I36: ='C-Döviz'!AA153-'C-Döviz'!Z153 | J36: ='C-Döviz'!AJ229 | K36: ='C-Döviz'!AA229-'C-Döviz'!Z229 | L36: ='C-Döviz'!AJ294/'C-Döviz'!AJ12 | M36: =L36-('C-Döviz'!Z294/'C-Döviz'!Z12) | N36: ='C-Döviz'!AJ307/'C-Döviz'!AJ12 | O36: =N36-('C-Döviz'!Z307/'C-Döviz'!Z12)
C37: Yusen İnci Loj. | D37: ='C-Döviz'!AJ106 | E37: =-('C-Döviz'!AA106-'C-Döviz'!Z106) | F37: ='C-Döviz'!AJ83 | G37: ='C-Döviz'!AA83-'C-Döviz'!Z83 | H37: ='C-Döviz'!AJ154 | I37: ='C-Döviz'!AA154-'C-Döviz'!Z154 | J37: ='C-Döviz'!AJ230 | K37: ='C-Döviz'!AA230-'C-Döviz'!Z230 | L37: ='C-Döviz'!AJ295/'C-Döviz'!AJ13 | M37: =L37-('C-Döviz'!Z295/'C-Döviz'!Z13) | N37: ='C-Döviz'!AJ308/'C-Döviz'!AJ13 | O37: =N37-('C-Döviz'!Z308/'C-Döviz'!Z13)
C38: Jantaş | D38: ='C-Döviz'!AJ107 | E38: =-('C-Döviz'!AA107-'C-Döviz'!Z107) | F38: ='C-Döviz'!AJ84 | G38: ='C-Döviz'!AA84-'C-Döviz'!Z84 | H38: ='C-Döviz'!AJ155 | I38: ='C-Döviz'!AA155-'C-Döviz'!Z155 | J38: ='C-Döviz'!AJ231 | K38: ='C-Döviz'!AA231-'C-Döviz'!Z231 | L38: ='C-Döviz'!AJ296/'C-Döviz'!AJ14 | M38: =L38-('C-Döviz'!Z296/'C-Döviz'!Z14) | N38: ='C-Döviz'!AJ309/'C-Döviz'!AJ14 | O38: =N38-('C-Döviz'!Z309/'C-Döviz'!Z14)
C39: Çelik | D39: ='C-Döviz'!AJ108 | E39: =-('C-Döviz'!AA108-'C-Döviz'!Z108) | F39: ='C-Döviz'!AJ85 | G39: ='C-Döviz'!AA85-'C-Döviz'!Z85 | H39: ='C-Döviz'!AJ156 | I39: ='C-Döviz'!AA156-'C-Döviz'!Z156 | J39: ='C-Döviz'!AJ232 | K39: ='C-Döviz'!AA232-'C-Döviz'!Z232 | L39: ='C-Döviz'!AJ297/'C-Döviz'!AJ15 | M39: =L39-('C-Döviz'!Z297/'C-Döviz'!Z15) | N39: ='C-Döviz'!AJ310/'C-Döviz'!AJ15 | O39: =N39-('C-Döviz'!Z310/'C-Döviz'!Z15)
C40: Alüminyum | D40: ='C-Döviz'!AJ109 | E40: =-('C-Döviz'!AA109-'C-Döviz'!Z109) | F40: ='C-Döviz'!AJ86 | G40: ='C-Döviz'!AA86-'C-Döviz'!Z86 | H40: ='C-Döviz'!AJ157 | I40: ='C-Döviz'!AA157-'C-Döviz'!Z157 | J40: ='C-Döviz'!AJ233 | K40: ='C-Döviz'!AA233-'C-Döviz'!Z233 | L40: ='C-Döviz'!AJ298/'C-Döviz'!AJ16 | M40: =L40-('C-Döviz'!Z298/'C-Döviz'!Z16) | N40: ='C-Döviz'!AJ311/'C-Döviz'!AJ16 | O40: =N40-('C-Döviz'!Z311/'C-Döviz'!Z16)
D64: Ciro | G64: EBITDA | K64: Net Kar
D65: Gerçekleşme | E65: % | G65: Gerçekleşme | I65: % | K65: Gerçekleşme | M65: %
C66: Ciro | D66: 55 | G66: 55 | K66: 55
C67: Adet | D67: 12 | E67: =D67/$D$66 | G67: 12 | H67: =G67/$D$66 | K67: 12 | M67: =K67/$K$66
C68: Fiyat | D68: 9 | E68: =D68/$D$66 | G68: 9 | H68: =G68/$D$66 | K68: 9 | M68: =K68/$K$66
C69: Miks | D69: 8 | E69: =D69/$D$66 | G69: 8 | H69: =G69/$D$66 | K69: 8 | M69: =K69/$K$66
C70: Ham Madde | D70: 5 | E70: =D70/$D$66 | G70: 5 | H70: =G70/$D$66 | K70: 5 | M70: =K70/$K$66
...

Sheet Finansal Raporlama Tahmin
C3: KÜMÜLATİF | D3: Ciro | I3: Brüt Kar | N3: EBITDA | S3: Net Kar
C4: bin Avro
D5: Temmuz Tahmin | E5: Ağustos Tahmin | F5: Eylül Tahmin | G5: Bütçe - Tahmin Fark | H5: % Değişim | I5: Temmuz Tahmin | J5: Ağustos Tahmin | K5: Eylül Tahmin | L5: Bütçe - Tahmin Fark | M5: % Değişim | N5: Temmuz Tahmin | O5: Ağustos Tahmin | P5: Eylül Tahmin | Q5: Bütçe - Tahmin Fark | R5: % Değişim | S5: Temmuz Tahmin | T5: Ağustos Tahmin | U5: Eylül Tahmin | V5: Bütçe - Tahmin Fark | W5: % Değişim
C6: Toplam | D6: =SUM(D7:D14) | E6: =SUM(E7:E14) | F6: =SUM(F7:F14) | G6: =SUM(G7:G14) | H6: =(F6/(F6-G6))-1 | I6: =SUM(I7:I14) | J6: =SUM(J7:J14) | K6: =SUM(K7:K14) | L6: =SUM(L7:L14) | M6: =(K6/(K6-L6))-1 | N6: =SUM(N7:N14) | O6: =SUM(O7:O14) | P6: =SUM(P7:P14) | Q6: =SUM(Q7:Q14) | R6: =(P6/(P6-Q6))-1 | S6: =SUM(S7:S14) | T6: =SUM(T7:T14) | U6: =SUM(U7:U14) | V6: =SUM(V7:V14) | W6: =(U6/(U6-V6))-1
C7: İnci Holding | D7: ='Tahmin Data'!O4/1000 | E7: ='Tahmin Data'!Q4/1000 | F7: ='Tahmin Data'!S4/1000 | G7: =F7-'C-Döviz'!AI9/1000 | H7: =(F7/(F7-G7))-1 | I7: ='Tahmin Data'!O20/1000 | J7: ='Tahmin Data'!Q20/1000 | K7: ='Tahmin Data'!S20/1000 | L7: =K7-'C-Döviz'!AI36/1000 | M7: =(K7/(K7-L7))-1 | N7: ='Tahmin Data'!M60/1000 | O7: ='Tahmin Data'!Q60/1000 | P7: ='Tahmin Data'!S60/1000 | Q7: =P7-'C-Döviz'!AI139/1000 | R7: =(P7/(P7-Q7))-1 | S7: ='Tahmin Data'!O100/1000 | T7: ='Tahmin Data'!Q100/1000 | U7: ='Tahmin Data'!S100/1000 | V7: =U7-'C-Döviz'!AI215/1000 | W7: =(U7/(U7-V7))-1
C8: ISM | D8: ='Tahmin Data'!O6/1000 | E8: ='Tahmin Data'!Q6/1000 | F8: ='Tahmin Data'!S6/1000 | G8: =F8-'C-Döviz'!AI10/1000 | H8: =(F8/(F8-G8))-1 | I8: ='Tahmin Data'!O22/1000 | J8: ='Tahmin Data'!Q22/1000 | K8: ='Tahmin Data'!S22/1000 | L8: =K8-'C-Döviz'!AI37/1000 | M8: =(K8/(K8-L8))-1 | N8: ='Tahmin Data'!O62/1000 | O8: ='Tahmin Data'!Q62/1000 | P8: ='Tahmin Data'!S62/1000 | Q8: =P8-'C-Döviz'!AI140/1000 | R8: =(P8/(P8-Q8))-1 | S8: ='Tahmin Data'!O102/1000 | T8: ='Tahmin Data'!Q102/1000 | U8: ='Tahmin Data'!S102/1000 | V8: =U8-'C-Döviz'!AI216/1000 | W8: =(U8/(U8-V8))-1
C9: İncitaş | D9: ='Tahmin Data'!O5/1000 | E9: ='Tahmin Data'!Q5/1000 | F9: ='Tahmin Data'!S5/1000 | G9: =F9-'C-Döviz'!AI11/1000 | H9: =(F9/(F9-G9))-1 | I9: ='Tahmin Data'!O21/1000 | J9: ='Tahmin Data'!Q21/1000 | K9: ='Tahmin Data'!S21/1000 | L9: =K9-'C-Döviz'!AI38/1000 | M9: =(K9/(K9-L9))-1 | N9: ='Tahmin Data'!O61/1000 | O9: ='Tahmin Data'!Q61/1000 | P9: ='Tahmin Data'!S61/1000 | Q9: =P9-'C-Döviz'!AI141/1000 | R9: =(P9/(P9-Q9))-1 | S9: ='Tahmin Data'!O101/1000 | T9: ='Tahmin Data'!Q101/1000 | U9: ='Tahmin Data'!S101/1000 | V9: =U9-'C-Döviz'!AI217/1000 | W9: =(U9/(U9-V9))-1
C10: İnci GS Yuasa | D10: ='Tahmin Data'!O3/1000 | E10: ='Tahmin Data'!Q3/1000 | F10: ='Tahmin Data'!S3/1000 | G10: =F10-'C-Döviz'!AI12/1000 | H10: =(F10/(F10-G10))-1 | I10: ='Tahmin Data'!O19/1000 | J10: ='Tahmin Data'!Q19/1000 | K10: ='Tahmin Data'!S19/1000 | L10: =K10-'C-Döviz'!AI39/1000 | M10: =(K10/(K10-L10))-1 | N10: ='Tahmin Data'!O59/1000 | O10: ='Tahmin Data'!Q59/1000 | P10: ='Tahmin Data'!S59/1000 | Q10: =P10-'C-Döviz'!AI142/1000 | R10: =(P10/(P10-Q10))-1 | S10: ='Tahmin Data'!O99/1000 | T10: ='Tahmin Data'!Q99/1000 | U10: ='Tahmin Data'!S99/1000 | V10: =U10-'C-Döviz'!AI218/1000 | W10: =(U10/(U10-V10))-1
C11: Yusen İnci Loj. | D11: ='Tahmin Data'!O10/1000 | E11: ='Tahmin Data'!Q10/1000 | F11: ='Tahmin Data'!S10/1000 | G11: =F11-'C-Döviz'!AI13/1000 | H11: =(F11/(F11-G11))-1 | I11: ='Tahmin Data'!O26/1000 | J11: ='Tahmin Data'!Q26/1000 | K11: ='Tahmin Data'!S26/1000 | L11: =K11-'C-Döviz'!AI40/1000 | M11: =(K11/(K11-L11))-1 | N11: ='Tahmin Data'!O66/1000 | O11: ='Tahmin Data'!Q66/1000 | P11: ='Tahmin Data'!S66/1000 | Q11: =P11-'C-Döviz'!AI143/1000 | R11: =(P11/(P11-Q11))-1 | S11: ='Tahmin Data'!O106/1000 | T11: ='Tahmin Data'!Q106/1000 | U11: ='Tahmin Data'!S106/1000 | V11: =U11-'C-Döviz'!AI219/1000 | W11: =(U11/(U11-V11))-1
C12: Jantaş | D12: ='Tahmin Data'!O9/1000 | E12: ='Tahmin Data'!Q9/1000 | F12: ='Tahmin Data'!S9/1000 | G12: =F12-'C-Döviz'!AI14/1000 | H12: =(F12/(F12-G12))-1 | I12: ='Tahmin Data'!O25/1000 | J12: ='Tahmin Data'!Q25/1000 | K12: ='Tahmin Data'!S25/1000 | L12: =K12-'C-Döviz'!AI41/1000 | M12: =(K12/(K12-L12))-1 | N12: ='Tahmin Data'!O65/1000 | O12: ='Tahmin Data'!Q65/1000 | P12: ='Tahmin Data'!S65/1000 | Q12: =P12-'C-Döviz'!AI144/1000 | R12: =(P12/(P12-Q12))-1 | S12: ='Tahmin Data'!O105/1000 | T12: ='Tahmin Data'!Q105/1000 | U12: ='Tahmin Data'!S105/1000 | V12: =U12-'C-Döviz'!AI220/1000 | W12: =(U12/(U12-V12))-1
C13: Çelik | D13: ='Tahmin Data'!O8/1000 | E13: ='Tahmin Data'!Q8/1000 | F13: ='Tahmin Data'!S8/1000 | G13: =F13-'C-Döviz'!AI15/1000 | H13: =(F13/(F13-G13))-1 | I13: ='Tahmin Data'!O24/1000 | J13: ='Tahmin Data'!Q24/1000 | K13: ='Tahmin Data'!S24/1000 | L13: =K13-'C-Döviz'!AI42/1000 | M13: =(K13/(K13-L13))-1 | N13: ='Tahmin Data'!O64/1000 | O13: ='Tahmin Data'!Q64/1000 | P13: ='Tahmin Data'!S64/1000 | Q13: =P13-'C-Döviz'!AI145/1000 | R13: =(P13/(P13-Q13))-1 | S13: ='Tahmin Data'!O104/1000 | T13: ='Tahmin Data'!Q104/1000 | U13: ='Tahmin Data'!S104/1000 | V13: =U13-'C-Döviz'!AI221/1000 | W13: =(U13/(U13-V13))-1
C14: Alüminyum | D14: ='Tahmin Data'!O7/1000 | E14: ='Tahmin Data'!Q7/1000 | F14: ='Tahmin Data'!S7/1000 | G14: =F14-'C-Döviz'!AI16/1000 | H14: =(F14/(F14-G14))-1 | I14: ='Tahmin Data'!O23/1000 | J14: ='Tahmin Data'!Q23/1000 | K14: ='Tahmin Data'!S23/1000 | L14: =K14-'C-Döviz'!AI43/1000 | M14: =(K14/(K14-L14))-1 | N14: ='Tahmin Data'!O63/1000 | O14: ='Tahmin Data'!Q63/1000 | P14: ='Tahmin Data'!S63/1000 | Q14: =P14-'C-Döviz'!AI146/1000 | R14: =(P14/(P14-Q14))-1 | S14: ='Tahmin Data'!O103/1000 | T14: ='Tahmin Data'!Q103/1000 | U14: ='Tahmin Data'!S103/1000 | V14: =U14-'C-Döviz'!AI222/1000 | W14: =(U14/(U14-V14))-1
D16: Vergi | I16: Operasyonel Nakit | N16: Serbest Nakit
C17: bin Avro
D18: Temmuz Tahmin | E18: Ağustos Tahmin | F18: Eylül Tahmin | G18: Bütçe - Tahmin Fark | H18: % Değişim | I18: Temmuz Tahmin | J18: Ağustos Tahmin | K18: Eylül Tahmin | L18: Bütçe - Tahmin Fark | M18: % Değişim | N18: Temmuz Tahmin | O18: Ağustos Tahmin | P18: Eylül Tahmin | Q18: Bütçe - Tahmin Fark | R18: % Değişim
C19: Toplam | D19: =SUM(D20:D27) | E19: =SUM(E20:E27) | F19: =SUM(F20:F27) | G19: =SUM(G20:G27) | H19: =(F19/(F19-G19))-1 | I19: =SUM(I20:I27) | J19: =SUM(J20:J27) | K19: =SUM(K20:K27) | L19: =SUM(L20:L27) | M19: =(K19/(K19-L19))-1 | N19: =SUM(N20:N27) | O19: =SUM(O20:O27) | P19: =SUM(P20:P27) | Q19: =SUM(Q20:Q27) | R19: =(P19/(P19-Q19))-1
C20: İnci Holding | D20: ='Tahmin Data'!O92/1000 | E20: ='Tahmin Data'!Q92/1000 | F20: ='Tahmin Data'!S92/1000 | G20: =F20-('C-Döviz'!AI202/-1000) | H20: =(F20/(F20-G20))-1 | I20: ='Tahmin Data'!O140/1000 | J20: ='Tahmin Data'!Q140/1000 | K20: ='Tahmin Data'!S140/1000 | L20: =K20-('C-Döviz'!AI291/1000) | M20: =(K20/(K20-L20))-1 | N20: ='Tahmin Data'!O148/1000 | O20: ='Tahmin Data'!Q148/1000 | P20: ='Tahmin Data'!S148/1000 | Q20: =P20-('C-Döviz'!AI304/1000) | R20: =(P20/(P20-Q20))-1
C21: ISM | D21: ='Tahmin Data'!O94/1000 | E21: ='Tahmin Data'!Q94/1000 | F21: ='Tahmin Data'!S94/1000 | G21: =F21-('C-Döviz'!AI203/-1000) | H21: =(F21/(F21-G21))-1 | I21: ='Tahmin Data'!O142/1000 | J21: ='Tahmin Data'!Q142/1000 | K21: ='Tahmin Data'!S142/1000 | L21: =K21-('C-Döviz'!AI292/1000) | M21: =(K21/(K21-L21))-1 | N21: ='Tahmin Data'!O150/1000 | O21: ='Tahmin Data'!Q150/1000 | P21: ='Tahmin Data'!S150/1000 | Q21: =P21-('C-Döviz'!AI305/1000) | R21: =(P21/(P21-Q21))-1
C22: İncitaş | D22: ='Tahmin Data'!O93/1000 | E22: ='Tahmin Data'!Q93/1000 | F22: ='Tahmin Data'!S93/1000 | G22: =F22-('C-Döviz'!AI204/-1000) | H22: =(F22/(F22-G22))-1 | I22: ='Tahmin Data'!O141/1000 | J22: ='Tahmin Data'!Q141/1000 | K22: ='Tahmin Data'!S141/1000 | L22: =K22-('C-Döviz'!AI293/1000) | M22: =-(K22/(K22-L22)) | N22: ='Tahmin Data'!O149/1000 | O22: ='Tahmin Data'!Q149/1000 | P22: ='Tahmin Data'!S149/1000 | Q22: =P22-('C-Döviz'!AI306/1000) | R22: =-(P22/(P22-Q22))
C23: İnci GS Yuasa | D23: ='Tahmin Data'!O91/1000 | E23: ='Tahmin Data'!Q91/1000 | F23: ='Tahmin Data'!S91/1000 | G23: =F23-('C-Döviz'!AI205/-1000) | H23: 0 | I23: ='Tahmin Data'!O139/1000 | J23: ='Tahmin Data'!Q139/1000 | K23: ='Tahmin Data'!S139/1000 | L23: =K23-('C-Döviz'!AI294/1000) | M23: =(K23/(K23-L23))-1 | N23: ='Tahmin Data'!O147/1000 | O23: ='Tahmin Data'!Q147/1000 | P23: ='Tahmin Data'!S147/1000 | Q23: =P23-('C-Döviz'!AI307/1000) | R23: =-(P23/(P23-Q23))
C24: Yusen İnci Loj. | D24: ='Tahmin Data'!O98/1000 | E24: ='Tahmin Data'!Q98/1000 | F24: ='Tahmin Data'!S98/1000 | G24: =F24-('C-Döviz'!AI206/-1000) | H24: =(F24/(F24-G24))-1 | I24: ='Tahmin Data'!O146/1000 | J24: ='Tahmin Data'!Q146/1000 | K24: ='Tahmin Data'!S146/1000 | L24: =K24-('C-Döviz'!AI295/1000) | M24: =(K24/(K24-L24))-1 | N24: ='Tahmin Data'!O154/1000 | O24: ='Tahmin Data'!Q154/1000 | P24: ='Tahmin Data'!S154/1000 | Q24: =P24-('C-Döviz'!AI308/1000) | R24: =(P24/(P24-Q24))-1
C25: Jantaş | D25: ='Tahmin Data'!O97/1000 | E25: ='Tahmin Data'!Q97/1000 | F25: ='Tahmin Data'!S97/1000 | G25: =F25-('C-Döviz'!AI207/-1000) | H25: =(F25/(F25-G25))-1 | I25: ='Tahmin Data'!O145/1000 | J25: ='Tahmin Data'!Q145/1000 | K25: ='Tahmin Data'!S145/1000 | L25: =K25-('C-Döviz'!AI296/1000) | M25: =(K25/(K25-L25))-1 | N25: ='Tahmin Data'!O153/1000 | O25: ='Tahmin Data'!Q153/1000 | P25: ='Tahmin Data'!S153/1000 | Q25: =P25-('C-Döviz'!AI309/1000) | R25: =(P25/(P25-Q25))-1
C26: Çelik | D26: ='Tahmin Data'!O96/1000 | E26: ='Tahmin Data'!Q96/1000 | F26: ='Tahmin Data'!S96/1000 | G26: =F26-('C-Döviz'!AI208/-1000) | H26: =(F26/(F26-G26))-1 | I26: ='Tahmin Data'!O144/1000 | J26: ='Tahmin Data'!Q144/1000 | K26: ='Tahmin Data'!S144/1000 | L26: =K26-('C-Döviz'!AI297/1000) | M26: =(K26/(K26-L26))-1 | N26: ='Tahmin Data'!O152/1000 | O26: ='Tahmin Data'!Q152/1000 | P26: ='Tahmin Data'!S152/1000 | Q26: =P26-('C-Döviz'!AI310/1000) | R26: =(P26/(P26-Q26))-1
C27: Alüminyum | D27: ='Tahmin Data'!O95/1000 | E27: ='Tahmin Data'!Q95/1000 | F27: ='Tahmin Data'!S95/1000 | G27: =F27-('C-Döviz'!AI209/-1000) | H27: =(F27/(F27-G27))-1 | I27: ='Tahmin Data'!O143/1000 | J27: ='Tahmin Data'!Q143/1000 | K27: ='Tahmin Data'!S143/1000 | L27: =K27-('C-Döviz'!AI298/1000) | M27: =(K27/(K27-L27))-1 | N27: ='Tahmin Data'!O151/1000 | O27: ='Tahmin Data'!Q151/1000 | P27: ='Tahmin Data'!S151/1000 | Q27: =P27-('C-Döviz'!AI311/1000) | R27: =(P27/(P27-Q27))-1
D30: Faaliyet Giderleri Marjı | H30: Brüt Kar Marjı | L30: EBITDA Marjı
C31: bin Avro
D32: Temmuz Tahmin | E32: Ağustos Tahmin | F32: Eylül Tahmin | G32: Bütçe - Tahmin Fark | H32: Temmuz Tahmin | I32: Ağustos Tahmin | J32: Eylül Tahmin | K32: Bütçe - Tahmin Fark | L32: Temmuz Tahmin | M32: Ağustos Tahmin | N32: Eylül Tahmin | O32: Bütçe - Tahmin Fark
C34: İnci Holding | D34: ='Tahmin Data'!O28/1000/D7*-1 | E34: ='Tahmin Data'!Q28/1000/E7*-1 | F34: ='Tahmin Data'!S28/1000/F7*-1 | G34: =-(F34-'C-Döviz'!AI102) | H34: =I7/D7 | I34: =J7/E7 | J34: =K7/F7 | K34: =J34-'C-Döviz'!AI79 | L34: =N7/D7 | M34: =O7/E7 | N34: =P7/F7 | O34: =N34-'C-Döviz'!AI150
C35: ISM | D35: ='Tahmin Data'!O30/1000/D8*-1 | E35: ='Tahmin Data'!Q30/1000/E8*-1 | F35: ='Tahmin Data'!S30/1000/F8*-1 | G35: =-(F35-'C-Döviz'!AI103) | H35: =I8/D8 | I35: =J8/E8 | J35: =K8/F8 | K35: =J35-'C-Döviz'!AI80 | L35: =N8/D8 | M35: =O8/E8 | N35: =P8/F8 | O35: =N35-'C-Döviz'!AI151
C36: İncitaş | D36: ='Tahmin Data'!O29/1000/D9*-1 | E36: ='Tahmin Data'!Q29/1000/E9*-1 | F36: ='Tahmin Data'!S29/1000/F9*-1 | G36: =-(F36-'C-Döviz'!AI104) | H36: =I9/D9 | I36: =J9/E9 | J36: =K9/F9 | K36: =J36-'C-Döviz'!AI81 | L36: =N9/D9 | M36: =O9/E9 | N36: =P9/F9 | O36: =N36-'C-Döviz'!AI152
C37: İnci GS Yuasa | D37: ='Tahmin Data'!O27/1000/D10*-1 | E37: ='Tahmin Data'!Q27/1000/E10*-1 | F37: ='Tahmin Data'!S27/1000/F10*-1 | G37: =-(F37-'C-Döviz'!AI105) | H37: =I10/D10 | I37: =J10/E10 | J37: =K10/F10 | K37: =J37-'C-Döviz'!AI82 | L37: =N10/D10 | M37: =O10/E10 | N37: =P10/F10 | O37: =N37-'C-Döviz'!AI153
C38: Yusen İnci Loj. | D38: ='Tahmin Data'!O34/1000/D11*-1 | E38: ='Tahmin Data'!Q34/1000/E11*-1 | F38: ='Tahmin Data'!S34/1000/F11*-1 | G38: =-(F38-'C-Döviz'!AI106) | H38: =I11/D11 | I38: =J11/E11 | J38: =K11/F11 | K38: =J38-'C-Döviz'!AI83 | L38: =N11/D11 | M38: =O11/E11 | N38: =P11/F11 | O38: =N38-'C-Döviz'!AI154
C39: Jantaş | D39: ='Tahmin Data'!O33/1000/D12*-1 | E39: ='Tahmin Data'!Q33/1000/E12*-1 | F39: ='Tahmin Data'!S33/1000/F12*-1 | G39: =-(F39-'C-Döviz'!AI107) | H39: =I12/D12 | I39: =J12/E12 | J39: =K12/F12 | K39: =J39-'C-Döviz'!AI84 | L39: =N12/D12 | M39: =O12/E12 | N39: =P12/F12 | O39: =N39-'C-Döviz'!AI155
C40: Çelik | D40: ='Tahmin Data'!O32/1000/D13*-1 | E40: ='Tahmin Data'!Q32/1000/E13*-1 | F40: ='Tahmin Data'!S32/1000/F13*-1 | G40: =-(F40-'C-Döviz'!AI108) | H40: =I13/D13 | I40: =J13/E13 | J40: =K13/F13 | K40: =J40-'C-Döviz'!AI85 | L40: =N13/D13 | M40: =O13/E13 | N40: =P13/F13 | O40: =N40-'C-Döviz'!AI156
C41: Alüminyum | D41: ='Tahmin Data'!O31/1000/D14*-1 | E41: ='Tahmin Data'!Q31/1000/E14*-1 | F41: ='Tahmin Data'!S31/1000/F14*-1 | G41: =-(F41-'C-Döviz'!AI109) | H41: =I14/D14 | I41: =J14/E14 | J41: =K14/F14 | K41: =J41-'C-Döviz'!AI86 | L41: =N14/D14 | M41: =O14/E14 | N41: =P14/F14 | O41: =N41-'C-Döviz'!AI157
D43: Net Kar Marjı | H43: Operasyonel Nakit Marjı | L43: Serbest Nakit Marjı
C44: bin Avro
D45: Temmuz Tahmin | E45: Ağustos Tahmin | F45: Eylül Tahmin | G45: Bütçe - Tahmin Fark | H45: Temmuz Tahmin | I45: Ağustos Tahmin | J45: Eylül Tahmin | K45: Bütçe - Tahmin Fark | L45: Temmuz Tahmin | M45: Ağustos Tahmin | N45: Eylül Tahmin | O45: Bütçe - Tahmin Fark
C47: İnci Holding | D47: =S7/D7 | E47: =T7/E7 | F47: =U7/F7 | G47: =F47-'C-Döviz'!AI226 | H47: =I20/D7 | I47: =J20/E7 | J47: =K20/F7 | K47: =J47-('C-Döviz'!AI291/'C-Döviz'!AI9) | L47: =N20/D7 | M47: =O20/E7 | N47: =P20/F7 | O47: =N47-'C-Döviz'!AI304/'C-Döviz'!AI9
C48: ISM | D48: =S8/D8 | E48: =T8/E8 | F48: =U8/F8 | G48: =F48-'C-Döviz'!AI227 | H48: =I21/D8 | I48: =J21/E8 | J48: =K21/F8 | K48: =J48-('C-Döviz'!AI292/'C-Döviz'!AI10) | L48: =N21/D8 | M48: =O21/E8 | N48: =P21/F8 | O48: =N48-'C-Döviz'!AI305/'C-Döviz'!AI10
...

Sheet A -Döviz
A1: ='A-TRY'!A1 | B1: OCAK | E1: ŞUBAT | H1: MART | K1: NİSAN | N1: MAYIS | Q1: HAZİRAN | T1: TEMMUZ | W1: AĞUSTOS | Z1: EYLÜL | AC1: EKİM | AF1: KASIM | AI1: ARALIK
B2: Budget | C2: Actual | E2: Budget | F2: Actual | H2: Budget | I2: Actual | K2: Budget | L2: Actual | N2: Budget | O2: Actual | Q2: Budget | R2: Actual | T2: Budget | U2: Actual | W2: Budget | X2: Actual | Z2: Budget | AA2: Actual | AC2: Budget | AD2: Actual | AF2: Budget | AG2: Actual | AI2: Budget | AJ2: Actual | AL2: Difference | AM2: Variance % | AO2: Budget | AP2: Actual
A3: Eur Kapanış | B3: ='Bütçe aylık-TL'!$B$2 | C3: ='gerç aylık-tl'!$B$2 | E3: ='Bütçe aylık-TL'!$C$2 | F3: ='gerç aylık-tl'!$C$2 | H3: ='Bütçe aylık-TL'!$D$2 | I3: ='gerç aylık-tl'!$D$2 | K3: ='Bütçe aylık-TL'!$E$2 | L3: ='gerç aylık-tl'!$E$2 | N3: ='Bütçe aylık-TL'!$F$2 | O3: ='gerç aylık-tl'!$F$2 | Q3: ='Bütçe aylık-TL'!$G$2 | R3: ='gerç aylık-tl'!$G$2 | T3: ='Bütçe aylık-TL'!$H$2 | U3: ='gerç aylık-tl'!$H$2 | W3: ='Bütçe aylık-TL'!$I$2 | X3: ='gerç aylık-tl'!$I$2 | Z3: ='Bütçe aylık-TL'!$J$2 | AA3: ='gerç aylık-tl'!$J$2 | AC3: ='Bütçe aylık-TL'!$K$2 | AD3: ='gerç aylık-tl'!$K$2 | AF3: ='Bütçe aylık-TL'!$L$2 | AG3: ='gerç aylık-tl'!$L$2 | AI3: ='Bütçe aylık-TL'!$M$2 | AJ3: ='gerç aylık-tl'!$M$2 | AL3: =AP3-AO3 | AM3: =AP3/AO3-1 | AO3: =IF($A$1=$B$1,B3,IF($A$1=$E$1,E3,IF($A$1=$H$1,H3,IF($A$1=$K$1,K3,IF($A$1=$N$1,N3,IF($A$1=$Q$1,Q3,IF($A$1=$T$1,T3,IF($A$1=$W$1,W3,IF($A$1=$Z$1,Z3,IF($A$1=$AC$1,AC3,IF($A$1=$AF$1,AF3,IF($A$1=$AI$1,AI3)))))))))))) | AP3: =IF($A$1=$B$1,C3,IF($A$1=$E$1,F3,IF($A$1=$H$1,I3,IF($A$1=$K$1,L3,IF($A$1=$N$1,O3,IF($A$1=$Q$1,R3,IF($A$1=$T$1,U3,IF($A$1=$W$1,X3,IF($A$1=$Z$1,AA3,IF($A$1=$AC$1,AD3,IF($A$1=$AF$1,AG3,IF($A$1=$AI$1,AJ3)))))))))))) | AR3: =250000000/L3
A4: Eur Ortalama | B4: ='Bütçe aylık-TL'!$B$3 | C4: ='gerç aylık-tl'!$B$3 | E4: ='Bütçe aylık-TL'!$C$3 | F4: ='gerç aylık-tl'!$C$3 | H4: ='Bütçe aylık-TL'!$D$3 | I4: ='gerç aylık-tl'!$D$3 | K4: ='Bütçe aylık-TL'!$E$3 | L4: ='gerç aylık-tl'!$E$3 | N4: ='Bütçe aylık-TL'!$F$3 | O4: ='gerç aylık-tl'!$F$3 | Q4: ='Bütçe aylık-TL'!$G$3 | R4: ='gerç aylık-tl'!$G$3 | T4: ='Bütçe aylık-TL'!$H$3 | U4: ='gerç aylık-tl'!$H$3 | W4: ='Bütçe aylık-TL'!$I$3 | X4: ='gerç aylık-tl'!$I$3 | Z4: ='Bütçe aylık-TL'!$J$3 | AA4: ='gerç aylık-tl'!$J$3 | AC4: ='Bütçe aylık-TL'!$K$3 | AD4: ='gerç aylık-tl'!$K$3 | AF4: ='Bütçe aylık-TL'!$L$3 | AG4: ='gerç aylık-tl'!$L$3 | AI4: ='Bütçe aylık-TL'!$M$3 | AJ4: ='gerç aylık-tl'!$M$3 | AL4: =AP4-AO4 | AM4: =AP4/AO4-1 | AO4: =IF($A$1=$B$1,B4,IF($A$1=$E$1,E4,IF($A$1=$H$1,H4,IF($A$1=$K$1,K4,IF($A$1=$N$1,N4,IF($A$1=$Q$1,Q4,IF($A$1=$T$1,T4,IF($A$1=$W$1,W4,IF($A$1=$Z$1,Z4,IF($A$1=$AC$1,AC4,IF($A$1=$AF$1,AF4,IF($A$1=$AI$1,AI4)))))))))))) | AP4: =IF($A$1=$B$1,C4,IF($A$1=$E$1,F4,IF($A$1=$H$1,I4,IF($A$1=$K$1,L4,IF($A$1=$N$1,O4,IF($A$1=$Q$1,R4,IF($A$1=$T$1,U4,IF($A$1=$W$1,X4,IF($A$1=$Z$1,AA4,IF($A$1=$AC$1,AD4,IF($A$1=$AF$1,AG4,IF($A$1=$AI$1,AJ4))))))))))))
A6: Net Sales | B6: ='Bütçe aylık-Eur'!$B$4 | C6: ='gerç aylık-eur'!$B$4 | E6: ='Bütçe aylık-Eur'!$C$4 | F6: ='gerç aylık-eur'!$C$4 | H6: ='Bütçe aylık-Eur'!$D$4 | I6: ='gerç aylık-eur'!$D$4 | K6: ='Bütçe aylık-Eur'!$E$4 | L6: ='gerç aylık-eur'!$E$4 | N6: ='Bütçe aylık-Eur'!$F$4 | O6: ='gerç aylık-eur'!$F$4 | Q6: ='Bütçe aylık-Eur'!$G$4 | R6: ='gerç aylık-eur'!$G$4 | T6: ='Bütçe aylık-Eur'!$H$4 | U6: ='gerç aylık-eur'!$H$4 | W6: ='Bütçe aylık-Eur'!$I$4 | X6: ='gerç aylık-eur'!$I$4 | Z6: ='Bütçe aylık-Eur'!$J$4 | AA6: ='gerç aylık-eur'!$J$4 | AC6: ='Bütçe aylık-Eur'!$K$4 | AD6: ='gerç aylık-eur'!$K$4 | AF6: ='Bütçe aylık-Eur'!$L$4 | AG6: ='gerç aylık-eur'!$L$4 | AI6: ='Bütçe aylık-Eur'!$M$4 | AJ6: ='gerç aylık-eur'!$M$4 | AL6: =AP6-AO6 | AM6: =AP6/AO6-1 | AO6: =IF($A$1=$B$1,B6,IF($A$1=$E$1,E6,IF($A$1=$H$1,H6,IF($A$1=$K$1,K6,IF($A$1=$N$1,N6,IF($A$1=$Q$1,Q6,IF($A$1=$T$1,T6,IF($A$1=$W$1,W6,IF($A$1=$Z$1,Z6,IF($A$1=$AC$1,AC6,IF($A$1=$AF$1,AF6,IF($A$1=$AI$1,AI6)))))))))))) | AP6: =IF($A$1=$B$1,C6,IF($A$1=$E$1,F6,IF($A$1=$H$1,I6,IF($A$1=$K$1,L6,IF($A$1=$N$1,O6,IF($A$1=$Q$1,R6,IF($A$1=$T$1,U6,IF($A$1=$W$1,X6,IF($A$1=$Z$1,AA6,IF($A$1=$AC$1,AD6,IF($A$1=$AF$1,AG6,IF($A$1=$AI$1,AJ6))))))))))))
C7: =B6-C6 | F7: =E6-F6 | I7: =H6-I6 | L7: =K6-L6 | O7: =N6-O6
A8: SALES BY CHANNELS(100% Satışlar)
A9: İnci Holding | B9: ='Bütçe aylık-Eur'!$B$5 | C9: ='gerç aylık-eur'!$B$5 | E9: ='Bütçe aylık-Eur'!$C$5 | F9: ='gerç aylık-eur'!$C$5 | H9: ='Bütçe aylık-Eur'!$D$5 | I9: ='gerç aylık-eur'!$D$5 | K9: ='Bütçe aylık-Eur'!$E$5 | L9: ='gerç aylık-eur'!$E$5 | N9: ='Bütçe aylık-Eur'!$F$5 | O9: ='gerç aylık-eur'!$F$5 | P9: =O9/N9 | Q9: ='Bütçe aylık-Eur'!$G$5 | R9: ='gerç aylık-eur'!$G$5 | T9: ='Bütçe aylık-Eur'!$H$5 | U9: ='gerç aylık-eur'!$H$5 | W9: ='Bütçe aylık-Eur'!$I$5 | X9: ='gerç aylık-eur'!$I$5 | Z9: ='Bütçe aylık-Eur'!$J$5 | AA9: ='gerç aylık-eur'!$J$5 | AC9: ='Bütçe aylık-Eur'!$K$5 | AD9: ='gerç aylık-eur'!$K$5 | AF9: ='Bütçe aylık-Eur'!$L$5 | AG9: ='gerç aylık-eur'!$L$5 | AI9: ='Bütçe aylık-Eur'!$M$5 | AJ9: ='gerç aylık-eur'!$M$5 | AL9: =AP9-AO9 | AM9: =AP9/AO9-1 | AO9: =IF($A$1=$B$1,B9,IF($A$1=$E$1,E9,IF($A$1=$H$1,H9,IF($A$1=$K$1,K9,IF($A$1=$N$1,N9,IF($A$1=$Q$1,Q9,IF($A$1=$T$1,T9,IF($A$1=$W$1,W9,IF($A$1=$Z$1,Z9,IF($A$1=$AC$1,AC9,IF($A$1=$AF$1,AF9,IF($A$1=$AI$1,AI9)))))))))))) | AP9: =IF($A$1=$B$1,C9,IF($A$1=$E$1,F9,IF($A$1=$H$1,I9,IF($A$1=$K$1,L9,IF($A$1=$N$1,O9,IF($A$1=$Q$1,R9,IF($A$1=$T$1,U9,IF($A$1=$W$1,X9,IF($A$1=$Z$1,AA9,IF($A$1=$AC$1,AD9,IF($A$1=$AF$1,AG9,IF($A$1=$AI$1,AJ9))))))))))))
A10: ISM | B10: ='Bütçe aylık-Eur'!$B$6 | C10: ='gerç aylık-eur'!$B$6 | E10: ='Bütçe aylık-Eur'!$C$6 | F10: ='gerç aylık-eur'!$C$6 | H10: ='Bütçe aylık-Eur'!$D$6 | I10: ='gerç aylık-eur'!$D$6 | K10: ='Bütçe aylık-Eur'!$E$6 | L10: ='gerç aylık-eur'!$E$6 | N10: ='Bütçe aylık-Eur'!$F$6 | O10: ='gerç aylık-eur'!$F$6 | P10: =O10/N10 | Q10: ='Bütçe aylık-Eur'!$G$6 | R10: ='gerç aylık-eur'!$G$6 | T10: ='Bütçe aylık-Eur'!$H$6 | U10: ='gerç aylık-eur'!$H$6 | W10: ='Bütçe aylık-Eur'!$I$6 | X10: ='gerç aylık-eur'!$I$6 | Z10: ='Bütçe aylık-Eur'!$J$6 | AA10: ='gerç aylık-eur'!$J$6 | AC10: ='Bütçe aylık-Eur'!$K$6 | AD10: ='gerç aylık-eur'!$K$6 | AF10: ='Bütçe aylık-Eur'!$L$6 | AG10: ='gerç aylık-eur'!$L$6 | AI10: ='Bütçe aylık-Eur'!$M$6 | AJ10: ='gerç aylık-eur'!$M$6 | AL10: =AP10-AO10 | AM10: =AP10/AO10-1 | AO10: =IF($A$1=$B$1,B10,IF($A$1=$E$1,E10,IF($A$1=$H$1,H10,IF($A$1=$K$1,K10,IF($A$1=$N$1,N10,IF($A$1=$Q$1,Q10,IF($A$1=$T$1,T10,IF($A$1=$W$1,W10,IF($A$1=$Z$1,Z10,IF($A$1=$AC$1,AC10,IF($A$1=$AF$1,AF10,IF($A$1=$AI$1,AI10)))))))))))) | AP10: =IF($A$1=$B$1,C10,IF($A$1=$E$1,F10,IF($A$1=$H$1,I10,IF($A$1=$K$1,L10,IF($A$1=$N$1,O10,IF($A$1=$Q$1,R10,IF($A$1=$T$1,U10,IF($A$1=$W$1,X10,IF($A$1=$Z$1,AA10,IF($A$1=$AC$1,AD10,IF($A$1=$AF$1,AG10,IF($A$1=$AI$1,AJ10))))))))))))
A11: İncitaş | B11: ='Bütçe aylık-Eur'!$B$7 | C11: ='gerç aylık-eur'!$B$7 | E11: ='Bütçe aylık-Eur'!$C$7 | F11: ='gerç aylık-eur'!$C$7 | H11: ='Bütçe aylık-Eur'!$D$7 | I11: ='gerç aylık-eur'!$D$7 | K11: ='Bütçe aylık-Eur'!$E$7 | L11: ='gerç aylık-eur'!$E$7 | N11: ='Bütçe aylık-Eur'!$F$7 | O11: ='gerç aylık-eur'!$F$7 | P11: =O11/N11 | Q11: ='Bütçe aylık-Eur'!$G$7 | R11: ='gerç aylık-eur'!$G$7 | T11: ='Bütçe aylık-Eur'!$H$7 | U11: ='gerç aylık-eur'!$H$7 | W11: ='Bütçe aylık-Eur'!$I$7 | X11: ='gerç aylık-eur'!$I$7 | Z11: ='Bütçe aylık-Eur'!$J$7 | AA11: ='gerç aylık-eur'!$J$7 | AC11: ='Bütçe aylık-Eur'!$K$7 | AD11: ='gerç aylık-eur'!$K$7 | AF11: ='Bütçe aylık-Eur'!$L$7 | AG11: ='gerç aylık-eur'!$L$7 | AI11: ='Bütçe aylık-Eur'!$M$7 | AJ11: ='gerç aylık-eur'!$M$7 | AL11: =AP11-AO11 | AM11: =AP11/AO11-1 | AO11: =IF($A$1=$B$1,B11,IF($A$1=$E$1,E11,IF($A$1=$H$1,H11,IF($A$1=$K$1,K11,IF($A$1=$N$1,N11,IF($A$1=$Q$1,Q11,IF($A$1=$T$1,T11,IF($A$1=$W$1,W11,IF($A$1=$Z$1,Z11,IF($A$1=$AC$1,AC11,IF($A$1=$AF$1,AF11,IF($A$1=$AI$1,AI11)))))))))))) | AP11: =IF($A$1=$B$1,C11,IF($A$1=$E$1,F11,IF($A$1=$H$1,I11,IF($A$1=$K$1,L11,IF($A$1=$N$1,O11,IF($A$1=$Q$1,R11,IF($A$1=$T$1,U11,IF($A$1=$W$1,X11,IF($A$1=$Z$1,AA11,IF($A$1=$AC$1,AD11,IF($A$1=$AF$1,AG11,IF($A$1=$AI$1,AJ11))))))))))))
A12: İnci GS Yuasa | B12: ='Bütçe aylık-Eur'!$B$8 | C12: ='gerç aylık-eur'!$B$8 | E12: ='Bütçe aylık-Eur'!$C$8 | F12: ='gerç aylık-eur'!$C$8 | H12: ='Bütçe aylık-Eur'!$D$8 | I12: ='gerç aylık-eur'!$D$8 | K12: ='Bütçe aylık-Eur'!$E$8 | L12: ='gerç aylık-eur'!$E$8 | N12: ='Bütçe aylık-Eur'!$F$8 | O12: ='gerç aylık-eur'!$F$8 | P12: =O12/N12 | Q12: ='Bütçe aylık-Eur'!$G$8 | R12: ='gerç aylık-eur'!$G$8 | T12: ='Bütçe aylık-Eur'!$H$8 | U12: ='gerç aylık-eur'!$H$8 | W12: ='Bütçe aylık-Eur'!$I$8 | X12: ='gerç aylık-eur'!$I$8 | Z12: ='Bütçe aylık-Eur'!$J$8 | AA12: ='gerç aylık-eur'!$J$8 | AC12: ='Bütçe aylık-Eur'!$K$8 | AD12: ='gerç aylık-eur'!$K$8 | AF12: ='Bütçe aylık-Eur'!$L$8 | AG12: ='gerç aylık-eur'!$L$8 | AI12: ='Bütçe aylık-Eur'!$M$8 | AJ12: ='gerç aylık-eur'!$M$8 | AL12: =AP12-AO12 | AM12: =AP12/AO12-1 | AN12: =AL12*0.4 | AO12: =IF($A$1=$B$1,B12,IF($A$1=$E$1,E12,IF($A$1=$H$1,H12,IF($A$1=$K$1,K12,IF($A$1=$N$1,N12,IF($A$1=$Q$1,Q12,IF($A$1=$T$1,T12,IF($A$1=$W$1,W12,IF($A$1=$Z$1,Z12,IF($A$1=$AC$1,AC12,IF($A$1=$AF$1,AF12,IF($A$1=$AI$1,AI12)))))))))))) | AP12: =IF($A$1=$B$1,C12,IF($A$1=$E$1,F12,IF($A$1=$H$1,I12,IF($A$1=$K$1,L12,IF($A$1=$N$1,O12,IF($A$1=$Q$1,R12,IF($A$1=$T$1,U12,IF($A$1=$W$1,X12,IF($A$1=$Z$1,AA12,IF($A$1=$AC$1,AD12,IF($A$1=$AF$1,AG12,IF($A$1=$AI$1,AJ12))))))))))))
A13: Yusen İnci Loj. | B13: ='Bütçe aylık-Eur'!$B$9 | C13: ='gerç aylık-eur'!$B$9 | E13: ='Bütçe aylık-Eur'!$C$9 | F13: ='gerç aylık-eur'!$C$9 | H13: ='Bütçe aylık-Eur'!$D$9 | I13: ='gerç aylık-eur'!$D$9 | K13: ='Bütçe aylık-Eur'!$E$9 | L13: ='gerç aylık-eur'!$E$9 | N13: ='Bütçe aylık-Eur'!$F$9 | O13: ='gerç aylık-eur'!$F$9 | P13: =O13/N13 | Q13: ='Bütçe aylık-Eur'!$G$9 | R13: ='gerç aylık-eur'!$G$9 | T13: ='Bütçe aylık-Eur'!$H$9 | U13: ='gerç aylık-eur'!$H$9 | W13: ='Bütçe aylık-Eur'!$I$9 | X13: ='gerç aylık-eur'!$I$9 | Z13: ='Bütçe aylık-Eur'!$J$9 | AA13: ='gerç aylık-eur'!$J$9 | AC13: ='Bütçe aylık-Eur'!$K$9 | AD13: ='gerç aylık-eur'!$K$9 | AF13: ='Bütçe aylık-Eur'!$L$9 | AG13: ='gerç aylık-eur'!$L$9 | AI13: ='Bütçe aylık-Eur'!$M$9 | AJ13: ='gerç aylık-eur'!$M$9 | AL13: =AP13-AO13 | AM13: =AP13/AO13-1 | AN13: =AL13*0.4 | AO13: =IF($A$1=$B$1,B13,IF($A$1=$E$1,E13,IF($A$1=$H$1,H13,IF($A$1=$K$1,K13,IF($A$1=$N$1,N13,IF($A$1=$Q$1,Q13,IF($A$1=$T$1,T13,IF($A$1=$W$1,W13,IF($A$1=$Z$1,Z13,IF($A$1=$AC$1,AC13,IF($A$1=$AF$1,AF13,IF($A$1=$AI$1,AI13)))))))))))) | AP13: =IF($A$1=$B$1,C13,IF($A$1=$E$1,F13,IF($A$1=$H$1,I13,IF($A$1=$K$1,L13,IF($A$1=$N$1,O13,IF($A$1=$Q$1,R13,IF($A$1=$T$1,U13,IF($A$1=$W$1,X13,IF($A$1=$Z$1,AA13,IF($A$1=$AC$1,AD13,IF($A$1=$AF$1,AG13,IF($A$1=$AI$1,AJ13)))))))))))) | AR13: 43.12 | AS13: =B13/AR13
A14: Jantaş | B14: ='Bütçe aylık-Eur'!$B$10 | C14: ='gerç aylık-eur'!$B$10 | E14: ='Bütçe aylık-Eur'!$C$10 | F14: ='gerç aylık-eur'!$C$10 | H14: ='Bütçe aylık-Eur'!$D$10 | I14: ='gerç aylık-eur'!$D$10 | K14: ='Bütçe aylık-Eur'!$E$10 | L14: ='gerç aylık-eur'!$E$10 | N14: ='Bütçe aylık-Eur'!$F$10 | O14: ='gerç aylık-eur'!$F$10 | P14: =O14/N14 | Q14: ='Bütçe aylık-Eur'!$G$10 | R14: ='gerç aylık-eur'!$G$10 | T14: ='Bütçe aylık-Eur'!$H$10 | U14: ='gerç aylık-eur'!$H$10 | W14: ='Bütçe aylık-Eur'!$I$10 | X14: ='gerç aylık-eur'!$I$10 | Z14: ='Bütçe aylık-Eur'!$J$10 | AA14: ='gerç aylık-eur'!$J$10 | AC14: ='Bütçe aylık-Eur'!$K$10 | AD14: ='gerç aylık-eur'!$K$10 | AF14: ='Bütçe aylık-Eur'!$L$10 | AG14: ='gerç aylık-eur'!$L$10 | AI14: ='Bütçe aylık-Eur'!$M$10 | AJ14: ='gerç aylık-eur'!$M$10 | AL14: =AP14-AO14 | AM14: =AP14/AO14-1 | AN14: =AL14*0.4 | AO14: =IF($A$1=$B$1,B14,IF($A$1=$E$1,E14,IF($A$1=$H$1,H14,IF($A$1=$K$1,K14,IF($A$1=$N$1,N14,IF($A$1=$Q$1,Q14,IF($A$1=$T$1,T14,IF($A$1=$W$1,W14,IF($A$1=$Z$1,Z14,IF($A$1=$AC$1,AC14,IF($A$1=$AF$1,AF14,IF($A$1=$AI$1,AI14)))))))))))) | AP14: =IF($A$1=$B$1,C14,IF($A$1=$E$1,F14,IF($A$1=$H$1,I14,IF($A$1=$K$1,L14,IF($A$1=$N$1,O14,IF($A$1=$Q$1,R14,IF($A$1=$T$1,U14,IF($A$1=$W$1,X14,IF($A$1=$Z$1,AA14,IF($A$1=$AC$1,AD14,IF($A$1=$AF$1,AG14,IF($A$1=$AI$1,AJ14))))))))))))
A15: Çelik | B15: ='Bütçe aylık-Eur'!$B$11 | C15: ='gerç aylık-eur'!$B$11 | E15: ='Bütçe aylık-Eur'!$C$11 | F15: ='gerç aylık-eur'!$C$11 | H15: ='Bütçe aylık-Eur'!$D$11 | I15: ='gerç aylık-eur'!$D$11 | K15: ='Bütçe aylık-Eur'!$E$11 | L15: ='gerç aylık-eur'!$E$11 | N15: ='Bütçe aylık-Eur'!$F$11 | O15: ='gerç aylık-eur'!$F$11 | P15: =O15/N15 | Q15: ='Bütçe aylık-Eur'!$G$11 | R15: ='gerç aylık-eur'!$G$11 | T15: ='Bütçe aylık-Eur'!$H$11 | U15: ='gerç aylık-eur'!$H$11 | W15: ='Bütçe aylık-Eur'!$I$11 | X15: ='gerç aylık-eur'!$I$11 | Z15: ='Bütçe aylık-Eur'!$J$11 | AA15: ='gerç aylık-eur'!$J$11 | AC15: ='Bütçe aylık-Eur'!$K$11 | AD15: ='gerç aylık-eur'!$K$11 | AF15: ='Bütçe aylık-Eur'!$L$11 | AG15: ='gerç aylık-eur'!$L$11 | AI15: ='Bütçe aylık-Eur'!$M$11 | AJ15: ='gerç aylık-eur'!$M$11 | AL15: =AP15-AO15 | AM15: =AP15/AO15-1 | AN15: =AL15*0.4 | AO15: =IF($A$1=$B$1,B15,IF($A$1=$E$1,E15,IF($A$1=$H$1,H15,IF($A$1=$K$1,K15,IF($A$1=$N$1,N15,IF($A$1=$Q$1,Q15,IF($A$1=$T$1,T15,IF($A$1=$W$1,W15,IF($A$1=$Z$1,Z15,IF($A$1=$AC$1,AC15,IF($A$1=$AF$1,AF15,IF($A$1=$AI$1,AI15)))))))))))) | AP15: =IF($A$1=$B$1,C15,IF($A$1=$E$1,F15,IF($A$1=$H$1,I15,IF($A$1=$K$1,L15,IF($A$1=$N$1,O15,IF($A$1=$Q$1,R15,IF($A$1=$T$1,U15,IF($A$1=$W$1,X15,IF($A$1=$Z$1,AA15,IF($A$1=$AC$1,AD15,IF($A$1=$AF$1,AG15,IF($A$1=$AI$1,AJ15))))))))))))
A16: Alüminyum | B16: ='Bütçe aylık-Eur'!$B$12 | C16: ='gerç aylık-eur'!$B$12 | E16: ='Bütçe aylık-Eur'!$C$12 | F16: ='gerç aylık-eur'!$C$12 | H16: ='Bütçe aylık-Eur'!$D$12 | I16: ='gerç aylık-eur'!$D$12 | K16: ='Bütçe aylık-Eur'!$E$12 | L16: ='gerç aylık-eur'!$E$12 | N16: ='Bütçe aylık-Eur'!$F$12 | O16: ='gerç aylık-eur'!$F$12 | P16: =O16/N16 | Q16: ='Bütçe aylık-Eur'!$G$12 | R16: ='gerç aylık-eur'!$G$12 | T16: ='Bütçe aylık-Eur'!$H$12 | U16: ='gerç aylık-eur'!$H$12 | W16: ='Bütçe aylık-Eur'!$I$12 | X16: ='gerç aylık-eur'!$I$12 | Z16: ='Bütçe aylık-Eur'!$J$12 | AA16: ='gerç aylık-eur'!$J$12 | AC16: ='Bütçe aylık-Eur'!$K$12 | AD16: ='gerç aylık-eur'!$K$12 | AF16: ='Bütçe aylık-Eur'!$L$12 | AG16: ='gerç aylık-eur'!$L$12 | AI16: ='Bütçe aylık-Eur'!$M$12 | AJ16: ='gerç aylık-eur'!$M$12 | AL16: =AP16-AO16 | AM16: =AP16/AO16-1 | AN16: =AL16*0.4 | AO16: =IF($A$1=$B$1,B16,IF($A$1=$E$1,E16,IF($A$1=$H$1,H16,IF($A$1=$K$1,K16,IF($A$1=$N$1,N16,IF($A$1=$Q$1,Q16,IF($A$1=$T$1,T16,IF($A$1=$W$1,W16,IF($A$1=$Z$1,Z16,IF($A$1=$AC$1,AC16,IF($A$1=$AF$1,AF16,IF($A$1=$AI$1,AI16)))))))))))) | AP16: =IF($A$1=$B$1,C16,IF($A$1=$E$1,F16,IF($A$1=$H$1,I16,IF($A$1=$K$1,L16,IF($A$1=$N$1,O16,IF($A$1=$Q$1,R16,IF($A$1=$T$1,U16,IF($A$1=$W$1,X16,IF($A$1=$Z$1,AA16,IF($A$1=$AC$1,AD16,IF($A$1=$AF$1,AG16,IF($A$1=$AI$1,AJ16))))))))))))
AO17: =IF($A$1=$B$1,B17,IF($A$1=$E$1,E17,IF($A$1=$H$1,H17,IF($A$1=$K$1,K17,IF($A$1=$N$1,N17,IF($A$1=$Q$1,Q17,IF($A$1=$T$1,T17,IF($A$1=$W$1,W17,IF($A$1=$Z$1,Z17,IF($A$1=$AC$1,AC17,IF($A$1=$AF$1,AF17,IF($A$1=$AI$1,AI17)))))))))))) | AP17: =IF($A$1=$B$1,C17,IF($A$1=$E$1,F17,IF($A$1=$H$1,I17,IF($A$1=$K$1,L17,IF($A$1=$N$1,O17,IF($A$1=$Q$1,R17,IF($A$1=$T$1,U17,IF($A$1=$W$1,X17,IF($A$1=$Z$1,AA17,IF($A$1=$AC$1,AD17,IF($A$1=$AF$1,AG17,IF($A$1=$AI$1,AJ17))))))))))))
AO18: =IF($A$1=$B$1,B18,IF($A$1=$E$1,E18,IF($A$1=$H$1,H18,IF($A$1=$K$1,K18,IF($A$1=$N$1,N18,IF($A$1=$Q$1,Q18,IF($A$1=$T$1,T18,IF($A$1=$W$1,W18,IF($A$1=$Z$1,Z18,IF($A$1=$AC$1,AC18,IF($A$1=$AF$1,AF18,IF($A$1=$AI$1,AI18)))))))))))) | AP18: =IF($A$1=$B$1,C18,IF($A$1=$E$1,F18,IF($A$1=$H$1,I18,IF($A$1=$K$1,L18,IF($A$1=$N$1,O18,IF($A$1=$Q$1,R18,IF($A$1=$T$1,U18,IF($A$1=$W$1,X18,IF($A$1=$Z$1,AA18,IF($A$1=$AC$1,AD18,IF($A$1=$AF$1,AG18,IF($A$1=$AI$1,AJ18))))))))))))
A19: SHARE OF SALES (%)
A20: İnci Holding | B20: =B9/B6 | C20: =C9/C6 | E20: =E9/E6 | F20: =F9/F6 | H20: =H9/H6 | I20: =I9/I6 | K20: =K9/K6 | L20: =L9/L6 | N20: =N9/N6 | O20: =O9/O6 | Q20: =Q9/Q6 | R20: =R9/R6 | T20: =T9/T6 | U20: =U9/U6 | W20: =W9/W6 | X20: =X9/X6 | Z20: =Z9/Z6 | AA20: =AA9/AA6 | AC20: =AC9/AC6 | AD20: =AD9/AD6 | AF20: =AF9/AF6 | AG20: =AG9/AG6 | AI20: =AI9/AI6 | AJ20: =AJ9/AJ6 | AL20: =AP20-AO20 | AO20: =IF($A$1=$B$1,B20,IF($A$1=$E$1,E20,IF($A$1=$H$1,H20,IF($A$1=$K$1,K20,IF($A$1=$N$1,N20,IF($A$1=$Q$1,Q20,IF($A$1=$T$1,T20,IF($A$1=$W$1,W20,IF($A$1=$Z$1,Z20,IF($A$1=$AC$1,AC20,IF($A$1=$AF$1,AF20,IF($A$1=$AI$1,AI20)))))))))))) | AP20: =IF($A$1=$B$1,C20,IF($A$1=$E$1,F20,IF($A$1=$H$1,I20,IF($A$1=$K$1,L20,IF($A$1=$N$1,O20,IF($A$1=$Q$1,R20,IF($A$1=$T$1,U20,IF($A$1=$W$1,X20,IF($A$1=$Z$1,AA20,IF($A$1=$AC$1,AD20,IF($A$1=$AF$1,AG20,IF($A$1=$AI$1,AJ20))))))))))))
A21: ISM | B21: =B10/B6 | C21: =C10/C6 | E21: =E10/E6 | F21: =F10/F6 | H21: =H10/H6 | I21: =I10/I6 | K21: =K10/K6 | L21: =L10/L6 | N21: =N10/N6 | O21: =O10/O6 | Q21: =Q10/Q6 | R21: =R10/R6 | T21: =T10/T6 | U21: =U10/U6 | W21: =W10/W6 | X21: =X10/X6 | Z21: =Z10/Z6 | AA21: =AA10/AA6 | AC21: =AC10/AC6 | AD21: =AD10/AD6 | AF21: =AF10/AF6 | AG21: =AG10/AG6 | AI21: =AI10/AI6 | AJ21: =AJ10/AJ6 | AL21: =AP21-AO21 | AO21: =IF($A$1=$B$1,B21,IF($A$1=$E$1,E21,IF($A$1=$H$1,H21,IF($A$1=$K$1,K21,IF($A$1=$N$1,N21,IF($A$1=$Q$1,Q21,IF($A$1=$T$1,T21,IF($A$1=$W$1,W21,IF($A$1=$Z$1,Z21,IF($A$1=$AC$1,AC21,IF($A$1=$AF$1,AF21,IF($A$1=$AI$1,AI21)))))))))))) | AP21: =IF($A$1=$B$1,C21,IF($A$1=$E$1,F21,IF($A$1=$H$1,I21,IF($A$1=$K$1,L21,IF($A$1=$N$1,O21,IF($A$1=$Q$1,R21,IF($A$1=$T$1,U21,IF($A$1=$W$1,X21,IF($A$1=$Z$1,AA21,IF($A$1=$AC$1,AD21,IF($A$1=$AF$1,AG21,IF($A$1=$AI$1,AJ21))))))))))))
A22: İncitaş | B22: =B11/B6 | C22: =C11/C6 | E22: =E11/E6 | F22: =F11/F6 | H22: =H11/H6 | I22: =I11/I6 | K22: =K11/K6 | L22: =L11/L6 | N22: =N11/N6 | O22: =O11/O6 | Q22: =Q11/Q6 | R22: =R11/R6 | T22: =T11/T6 | U22: =U11/U6 | W22: =W11/W6 | X22: =X11/X6 | Z22: =Z11/Z6 | AA22: =AA11/AA6 | AC22: =AC11/AC6 | AD22: =AD11/AD6 | AF22: =AF11/AF6 | AG22: =AG11/AG6 | AI22: =AI11/AI6 | AJ22: =AJ11/AJ6 | AL22: =AP22-AO22 | AO22: =IF($A$1=$B$1,B22,IF($A$1=$E$1,E22,IF($A$1=$H$1,H22,IF($A$1=$K$1,K22,IF($A$1=$N$1,N22,IF($A$1=$Q$1,Q22,IF($A$1=$T$1,T22,IF($A$1=$W$1,W22,IF($A$1=$Z$1,Z22,IF($A$1=$AC$1,AC22,IF($A$1=$AF$1,AF22,IF($A$1=$AI$1,AI22)))))))))))) | AP22: =IF($A$1=$B$1,C22,IF($A$1=$E$1,F22,IF($A$1=$H$1,I22,IF($A$1=$K$1,L22,IF($A$1=$N$1,O22,IF($A$1=$Q$1,R22,IF($A$1=$T$1,U22,IF($A$1=$W$1,X22,IF($A$1=$Z$1,AA22,IF($A$1=$AC$1,AD22,IF($A$1=$AF$1,AG22,IF($A$1=$AI$1,AJ22))))))))))))
A23: İnci GS Yuasa | B23: =B12*0.5/B6 | C23: =C12*0.5/C6 | E23: =E12*0.5/E6 | F23: =F12*0.5/F6 | H23: =H12*0.5/H6 | I23: =I12*0.5/I6 | K23: =K12*0.5/K6 | L23: =L12*0.5/L6 | N23: =N12*0.5/N6 | O23: =O12*0.5/O6 | Q23: =Q12*0.5/Q6 | R23: =R12*0.5/R6 | T23: =T12*0.5/T6 | U23: =U12*0.5/U6 | W23: =W12*0.5/W6 | X23: =X12*0.5/X6 | Z23: =Z12*0.5/Z6 | AA23: =AA12*0.5/AA6 | AC23: =AC12*0.5/AC6 | AD23: =AD12*0.5/AD6 | AF23: =AF12*0.5/AF6 | AG23: =AG12*0.5/AG6 | AI23: =AI12*0.5/AI6 | AJ23: =AJ12*0.5/AJ6 | AL23: =AP23-AO23 | AO23: =IF($A$1=$B$1,B23,IF($A$1=$E$1,E23,IF($A$1=$H$1,H23,IF($A$1=$K$1,K23,IF($A$1=$N$1,N23,IF($A$1=$Q$1,Q23,IF($A$1=$T$1,T23,IF($A$1=$W$1,W23,IF($A$1=$Z$1,Z23,IF($A$1=$AC$1,AC23,IF($A$1=$AF$1,AF23,IF($A$1=$AI$1,AI23)))))))))))) | AP23: =IF($A$1=$B$1,C23,IF($A$1=$E$1,F23,IF($A$1=$H$1,I23,IF($A$1=$K$1,L23,IF($A$1=$N$1,O23,IF($A$1=$Q$1,R23,IF($A$1=$T$1,U23,IF($A$1=$W$1,X23,IF($A$1=$Z$1,AA23,IF($A$1=$AC$1,AD23,IF($A$1=$AF$1,AG23,IF($A$1=$AI$1,AJ23))))))))))))
